Workbook

Sheet 回答一覧
A1: No | B1: 案件番号 | C1: 案件名 | D1: 回答種別 | E1: 電力会社 | F1: 回答日 | G1: 申込日 | H1: 申込者 | I1: 設置場所 | J1: 放電kW | K1: 充電kW | L1: 電圧 | M1: 変電所 | N1: 配電線/送電線 | O1: 負担金(円) | P1: 税区分 | Q1: 負担金(税込・万円) | R1: 負担金帯 | S1: 負担金の原文 | T1: 保証金(円) | U1: 工期(月) | V1: 工期帯 | W1: 工期の原文 | X1: 運開見込み | Y1: 主な対策工事 | Z1: 上位系統増強 | AA1: 連系条件 | AB1: 有効期限 | AC1: 読取信頼度 | AD1: 未読理由 | AE1: 備考 | AF1: 集計対象 | AG1: 律速・可否メモ | AH1: 自動チェック | AI1: 7月メモ差異 | AJ1: 検証ステータス | AK1: 検証者 | AL1: 検証コメント | AM1: 原本リンク | AN1: ファイル名 | AO1: パス
A2: 1 | B2: 0794 | C2: 0794_三重県名張市瀬古口（PX） | D2: 接続検討回答 | E2: 中部 | F2: 2025-08-18 | G2: 2025-05-28 | H2: 株式会社パワーエックス（受付番号AAD315770609） | I2: 三重県名張市瀬古口１１－４他２筆（発電者名称：瀬古口変電所隣接地蓄電） | J2: 1949 | K2: 1999 | L2: 高圧（高圧版回答書） | M2: 瀬古口変電所 | N2: 瀬古口変電所F35（65ﾈ283～西に約100mより分岐し構内柱と接続） | O2: 3418300 | P2: 税込 | Q2: =IF(O2="","",IF(P2="税抜",O2*1.1,O2)/10000) -> 341.83 | R2: =IF(Q2="","不明",IF(Q2<=500,"〜500万",IF(Q2<=1000,"500〜1,000万",IF(Q2<=3000,"1,000〜3,000万","3,000万〜")))) -> 〜500万 | S2: 工事費負担金総額3,418.3千円（消費税相当額310.8千円を含む）。税抜3,107.6千円＝架空線工事2,955.6千円＋計量設備工事152.0千円。概算工事費も同額。 | T2: 170000 | U2: 6 | V2: =IF(U2="","不明",IF(U2<=6,"〜6ヶ月",IF(U2<=12,"7〜12ヶ月",IF(U2<=24,"13〜24ヶ月","25ヶ月〜")))) -> 〜6ヶ月 | W2: 工事費負担金の入金後 6ヶ月程度（契約手続き期間は含まず） | X2: アクセス設備の運用開始希望日 2027年1月1日（連系可否：可） | Y2: 電柱新設4本、高圧線新設408m、高圧引込線60m（60㎟OCW 送電容量240A）、計量器/VCT・通信端末 | Z2: 上位系統増強工事なし（記載なし） | AA2: ノンファーム型接続適用（出力制御量に影響：西部変電所500/275kV変圧器、中勢変電所275/77kV変圧器、77kV中勢青山線）。基幹系は再給電方式（一定の順序）。PCS力率一定制御（放電/充電とも力率100%）、出力変化速度0→100%で5秒以上・1ステップ10%以下、PCS手動復帰設定、単独運転検出機能設定変更。中勢変電所作業停止時等の抑制。N-1電制本格適用。 | AB2: 接続検討の回答日から1年を経過した場合は契約申込不可 | AC2: high | AE2: 系統連系保証金170千円（消費税等相当額15.4千円を含む）。最大自家消費電力1,999kWをcapacity_kw_chargeに記載。後続の契約申込回答(KK4763)あり（別レコード）。 | AF2: － | AH2: =IF(AD2<>"","未読",IF(AND(D2<>"接続検討回答",D2<>"再接続検討",D2<>"契約申込回答"),"",TRIM(IF(O2="","負担金なし ","")&IF(U2="","工期なし ","")&IF(AND(O2<>"",OR(P2="",P2="不明")),"税区分不明 ","")&IF(AC2="low","信頼度low","")))) | AJ2: 未確認 | AM2: 開く | AN2: 接続検討回答書.pdf | AO2: 11_接続回答/接続検討回答書.pdf
A3: 2 | B3: 0794 | C3: 0794_三重県名張市瀬古口（PX） | D3: 契約申込回答 | E3: 中部 | F3: 2026-04-24 | H3: 株式会社パワーエックス（受付番号KK4763） | I3: 三重県名張市瀬古口11-4 他2筆（発電者名称：株式会社パワーエックス 瀬古口変電所隣接地蓄電所） | J3: 1949 | K3: 1999 | L3: 高圧 | M3: 瀬古口変電所（基幹系変電所：中勢275/77変電所） | N3: 瀬古口変電所F35（65ﾈ28ｱより分岐し構内柱と接続） | O3: 3418334 | P3: 税込 | Q3: =IF(O3="","",IF(P3="税抜",O3*1.1,O3)/10000) -> 341.8334 | R3: =IF(Q3="","不明",IF(Q3<=500,"〜500万",IF(Q3<=1000,"500〜1,000万",IF(Q3<=3000,"1,000〜3,000万","3,000万〜")))) -> 〜500万 | S3: 工事費負担金3,418,334円（消費税等相当額310,757円を含む）。税抜3,107,577円＝架空線工事2,955,582円＋計量設備工事151,995円。既に支払った系統連系保証金を差し引いた額を請求。 | U3: 10 | V3: =IF(U3="","不明",IF(U3<=6,"〜6ヶ月",IF(U3<=12,"7〜12ヶ月",IF(U3<=24,"13〜24ヶ月","25ヶ月〜")))) -> 7〜12ヶ月 | W3: 工事費負担金の入金後 10ヶ月程度（契約手続き期間は含まず。別紙「所要工期について」：架空線・計器・上位系統の工程10カ月） | X3: アクセス設備の運用開始希望日 2026年8月1日（連系可否：可） | Y3: 電柱4本、高圧線1548m、高圧引込線60m（OC-W60mm2 送電容量240A）、計量器・VCT等 | Z3: 上位系統増強工事なし（工程表に上位系統欄あるが工事費計上なし） | AA3: ノンファーム型接続適用（西部変電所500/275kV変圧器、中勢変電所275/77kV変圧器、77kV中勢青山線）。再給電方式。PCS力率一定制御（力率1.00）、PCS手動復帰設定、単独運転検出機能設定変更、保安通信用電話設備要確認。中勢変電所作業停止時等の抑制。N-1電制本格適用。発電側課金：配電用変電所 瀬古口変電所。 | AC3: high | AE3: 接続検討回答（2025-08-18、工期6ヶ月・高圧線408m）からの本回答（連系承諾）。負担金額はほぼ同額だが工期は10ヶ月程度、高圧線数量1548mに変更。14_接続検討要否確認フォルダに追加の要否確認依頼書(2026-05)あり（回答なし）。 | AF3: ○ | AH3: =IF(AD3<>"","未読",IF(AND(D3<>"接続検討回答",D3<>"再接続検討",D3<>"契約申込回答"),"",TRIM(IF(O3="","負担金なし ","")&IF(U3="","工期なし ","")&IF(AND(O3<>"",OR(P3="",P3="不明")),"税区分不明 ","")&IF(AC3="low","信頼度low","")))) | AJ3: 未確認 | AM3: 開く | AN3: 02 契約申込回答書（KK4763）.pdf | AO3: 13_本回答/02 契約申込回答書（KK4763）.pdf
A4: 3 | B4: 0876 | C4: 0876_埼玉県本庄市児玉町入浅見字東日延766（アスソラ） | D4: 接続検討回答 | E4: 東京 | F4: 2025-06-18 | G4: 2025-03-24 | H4: 株式会社パワーエックス（本庄児玉蓄電所） | I4: 埼玉県本庄市児玉町入浅見字東日延766番 | J4: 1998 | K4: 1999 | L4: 6.6kV | M4: 共和変電所（1B, 基幹:新岡部変電所） | N4: 6kV横手線 | O4: 5817700 | P4: 税込 | Q4: =IF(O4="","",IF(P4="税抜",O4*1.1,O4)/10000) -> 581.77 | R4: =IF(Q4="","不明",IF(Q4<=500,"〜500万",IF(Q4<=1000,"500〜1,000万",IF(Q4<=3000,"1,000〜3,000万","3,000万〜")))) -> 500〜1,000万 | S4: 工事費負担金の総額581.77万円(消費税等相当額52.89万円含む)、税抜528.88万円（架空線501.00/通信3.65/計量24.23）。概算工事費総額612.44万円(税込) | T4: 290000 | U4: 5 | V4: =IF(U4="","不明",IF(U4<=6,"〜6ヶ月",IF(U4<=12,"7〜12ヶ月",IF(U4<=24,"13〜24ヶ月","25ヶ月〜")))) -> 〜6ヶ月 | W4: 工事費負担金の入金後 5ヶ月程度（受給契約申込後からは13ヶ月程度） | X4: 希望2026年3月1日 | Y4: 架空引込線アルミ120×3条×5m、開閉器新設2台・撤去2台、変圧器新設1台、VCT・計量器・電力用保安通信設備 | Z4: なし（バンク逆潮流対策は完了済み、上位系統対策0円） | AA4: ノンファーム型接続(新岡部500/154変圧器)、再給電方式、運転力率 遅れ90%一定、N-1電制本格適用、先行事業者の設備対策工事前提 | AB4: 接続検討の回答日から1年を経過した場合は契約申込不可 | AC4: high | AE4: 系統連系保証金290千円(税込)。その後2026-02-02付「系統状況変化による再接続検討のお願い」で空き容量消失、発調申込取下げ→再接続検討(JK25GHZ042932)へ。同一ファイルのコピー(1lqVArpJi7bOcqsjyvYu8iIr6lnAAi9MM)あり | AF4: － | AH4: =IF(AD4<>"","未読",IF(AND(D4<>"接続検討回答",D4<>"再接続検討",D4<>"契約申込回答"),"",TRIM(IF(O4="","負担金なし ","")&IF(U4="","工期なし ","")&IF(AND(O4<>"",OR(P4="",P4="不明")),"税区分不明 ","")&IF(AC4="low","信頼度low","")))) | AJ4: 未確認 | AM4: 開く | AN4: 接続検討の回答について【JK24GHZ024878】.pdf | AO4: 01_接続検討/接続検討の回答について【JK24GHZ024878】.pdf
A5: 4 | B5: 0876 | C5: 0876_埼玉県本庄市児玉町入浅見字東日延766（アスソラ） | D5: その他 | E5: 東京 | F5: 2026-02-02 | H5: 株式会社パワーエックス（本庄児玉蓄電所） | I5: 埼玉県本庄市児玉町入浅見字東日延766番 | P5: 不明 | Q5: =IF(O5="","",IF(P5="税抜",O5*1.1,O5)/10000) | R5: =IF(Q5="","不明",IF(Q5<=500,"〜500万",IF(Q5<=1000,"500〜1,000万",IF(Q5<=3000,"1,000〜3,000万","3,000万〜")))) -> 不明 | T5: 290000 | V5: =IF(U5="","不明",IF(U5<=6,"〜6ヶ月",IF(U5<=12,"7〜12ヶ月",IF(U5<=24,"13〜24ヶ月","25ヶ月〜")))) -> 不明 | AB5: 再接続検討は接続検討回答日から1年以内・同内容なら調査料不要 | AC5: high | AE5: 発調申込受付前の系統確認で空き容量がなくなり再接続検討が必要との通知。発調申込取下げ・保証金返還の案内。保証金額は同フォルダ保証金請求書(2026-01-06, 290,000円税込=263,637+消費税26,363)より | AF5: － | AH5: =IF(AD5<>"","未読",IF(AND(D5<>"接続検討回答",D5<>"再接続検討",D5<>"契約申込回答"),"",TRIM(IF(O5="","負担金なし ","")&IF(U5="","工期なし ","")&IF(AND(O5<>"",OR(P5="",P5="不明")),"税区分不明 ","")&IF(AC5="low","信頼度low","")))) | AJ5: 未確認 | AM5: 開く | AN5: 系統状況変化によるご案内について(JK24GHZ024878).pdf | AO5: 02_本申請/系統状況変化によるご案内について(JK24GHZ024878).pdf
A6: 5 | B6: 0876 | C6: 0876_埼玉県本庄市児玉町入浅見字東日延766（アスソラ） | D6: 再接続検討 | E6: 東京 | F6: 2026-05-07 | G6: 2026-02-13 | H6: 株式会社パワーエックス（本庄児玉蓄電所） | I6: 埼玉県本庄市児玉町入浅見字東日延766番 | J6: 1998 | K6: 1999 | L6: 6.6kV | M6: 共和変電所（3B, 基幹:新岡部変電所） | N6: 6kV阿那志線 | O6: 26239500 | P6: 税込 | Q6: =IF(O6="","",IF(P6="税抜",O6*1.1,O6)/10000) -> 2623.95 | R6: =IF(Q6="","不明",IF(Q6<=500,"〜500万",IF(Q6<=1000,"500〜1,000万",IF(Q6<=3000,"1,000〜3,000万","3,000万〜")))) -> 1,000〜3,000万 | S6: 工事費負担金の総額2,623.95万円(消費税等相当額238.54万円含む)、税抜2,385.41万円（架空線978.35/地中線1,379.70/通信3.13/計量24.23）。概算工事費総額4,557.41万円(税込) | T6: 2623000 | U6: 18 | V6: =IF(U6="","不明",IF(U6<=6,"〜6ヶ月",IF(U6<=12,"7〜12ヶ月",IF(U6<=24,"13〜24ヶ月","25ヶ月〜")))) -> 13〜24ヶ月 | W6: 工事費負担金の入金後 18ヶ月程度（受給契約申込後からは40ヶ月程度）。先行事業者の系統対策工事完了後に本件工事を実施 | X6: 希望2026年3月1日（記載のまま） | Y6: 電柱新設15本/建替10本、高圧線新設1,087m、引込線10m、開閉器新設2台、変圧器新設3台/撤去4台、管路26m・高圧ケーブル142m(CVT325/500)、ミニクラ新設一式、VCT・計量器・保安通信 | Z6: なし（上位系統対策0円、バンク逆潮流対策完了済み） | AA6: ノンファーム型接続(新岡部500/154変圧器)、再給電方式、運転力率 遅れ90%一定、早期連系追加対策(充電制限)は現時点不要、N-1電制本格適用、先行事業者工事前提 | AB6: 接続検討の回答日から1年を経過した場合は契約申込不可 | AC6: high | AE6: 系統状況変化（他事業者申込で空き容量消失）による再接続検討の回答。系統連系保証金2,623千円(税込)。初回(JK24GHZ024878)より負担金・工期とも増加 | AF6: ○ | AH6: =IF(AD6<>"","未読",IF(AND(D6<>"接続検討回答",D6<>"再接続検討",D6<>"契約申込回答"),"",TRIM(IF(O6="","負担金なし ","")&IF(U6="","工期なし ","")&IF(AND(O6<>"",OR(P6="",P6="不明")),"税区分不明 ","")&IF(AC6="low","信頼度low","")))) | AJ6: 未確認 | AM6: 開く | AN6: 接続検討の回答について【JK25GHZ042932】.pdf | AO6: 03_再接続検討/接続検討の回答について【JK25GHZ042932】/接続検討の回答について【JK25GHZ042932】.pdf
A7: 6 | B7: 0916 | C7: 0916_島根県浜田市宇野町1819-1他3筆（エクスパワー） | D7: 接続検討回答 | E7: 中国 | F7: 2025-10-21 | G7: 2025-07-22 | H7: 株式会社パワーエックス（PX浜田市宇野町1819-1蓄電所, 受付番号G松江320） | I7: 島根県浜田市宇野町1819番1他4筆 | J7: 1994 | K7: 1999 | L7: 6.6kV | M7: 下府変電所（配電用）／基幹:西島根変電所 | N7: 6kV国分線 上府(支)78H7号柱より分岐（国分線一部を生湯線へ、生湯線一部を長沢線へ系統変更） | O7: 32000000 | P7: 税込 | Q7: =IF(O7="","",IF(P7="税抜",O7*1.1,O7)/10000) -> 3200 | R7: =IF(Q7="","不明",IF(Q7<=500,"〜500万",IF(Q7<=1000,"500〜1,000万",IF(Q7<=3000,"1,000〜3,000万","3,000万〜")))) -> 3,000万〜 | S7: 工事費負担金の総額32.0百万円(消費税等相当額2.9百万円含む)、税抜29.1百万円（架空線20.7/バンク逆潮流対策7.0/計量0.3/NTT電柱建替0.5/上位系増強0.6）。概算工事費総額104.0百万円(税込) | U7: 31 | V7: =IF(U7="","不明",IF(U7<=6,"〜6ヶ月",IF(U7<=12,"7〜12ヶ月",IF(U7<=24,"13〜24ヶ月","25ヶ月〜")))) -> 25ヶ月〜 | W7: 工事費負担金の入金後 31箇月程度（契約手続期間含まず）。運用開始希望日2026年3月1日には連系不可、連系時期の調整が必要 | X7: 希望2026年3月1日は不可（入金後31箇月程度） | Y7: 高圧線新設・増架・張替(HAL-OC200mm2)、引込線ACSR-OC58、電柱新設7本/建替37本、開閉器、下府変電所1号変圧器バンク逆潮流対策(EVT・OVGR, 2026年4月完了予定)、計量設備 | Z7: あり: 金城変電所110/66kV連系変圧器 順潮流対策用N-1電制装置(過負荷保護装置)設置工事（共用按分4.88%で特定負担0.6百万円）。本対策完了前の連系可 | AA7: ノンファーム型接続(西島根変220/110kV連系変圧器・110kV金城連絡線)、再給電方式、早期連系追加対策(充電制限:金城変110/66kV)、力率 放電93%遅れ/充電93%進み一定、充電変化速度調整、手動復帰、N-1電制本格適用 | AB7: 接続検討の回答日から1年を経過した場合は契約申込不可 | AC7: high | AE7: 検討対象年度2028年度。別紙1適合検討書・別紙2潮流グラフあり | AF7: － | AG7: 運開希望日に間に合わず | AH7: =IF(AD7<>"","未読",IF(AND(D7<>"接続検討回答",D7<>"再接続検討",D7<>"契約申込回答"),"",TRIM(IF(O7="","負担金なし ","")&IF(U7="","工期なし ","")&IF(AND(O7<>"",OR(P7="",P7="不明")),"税区分不明 ","")&IF(AC7="low","信頼度low","")))) | AJ7: 未確認 | AM7: 開く | AN7: 【秘】接続検討回答書 （G松江320）.pdf | AO7: 【秘】接続検討回答書 （G松江320）.pdf
A8: 7 | B8: 0916 | C8: 0916_島根県浜田市宇野町1819-1他3筆（エクスパワー） | D8: 契約申込回答 | E8: 中国 | F8: 2026-07-07 | G8: 2026-01-16 | H8: 株式会社パワーエックス（PX浜田市宇野町1819-1蓄電所） | I8: 島根県浜田市宇野町1819番1他4筆 | J8: 1994 | K8: 1999 | L8: 6.6kV | M8: 下府変電所（配電用） | N8: 6kV国分線 | O8: 32506910 | P8: 税込 | Q8: =IF(O8="","",IF(P8="税抜",O8*1.1,O8)/10000) -> 3250.691 | R8: =IF(Q8="","不明",IF(Q8<=500,"〜500万",IF(Q8<=1000,"500〜1,000万",IF(Q8<=3000,"1,000〜3,000万","3,000万〜")))) -> 3,000万〜 | S8: 工事費負担金の総額32,506,910円(消費税等相当額2,955,173円含む)、税抜29,551,737円（架空線20,764,400/バンク逆潮流対策6,979,000/計量337,318/NTT柱建替500,000/上位系増強971,019）。接続検討時32.0百万円から変更 | V8: =IF(U8="","不明",IF(U8<=6,"〜6ヶ月",IF(U8<=12,"7〜12ヶ月",IF(U8<=24,"13〜24ヶ月","25ヶ月〜")))) -> 不明 | W8: 別紙に連系予定（運用開始）2029年3月1日（工期月数の記載はOCRで判読できず） | X8: 2029年3月1日（系統連系予定日／竣工予定日） | Y8: 接続検討時と同様の配電線工事(HAL-OC200mm2新設・増架・張替、電柱新設7/建替37)、バンク逆潮流対策(EVT・OVGR、2026年4月完了)、計量設備 | Z8: 上位系統増強工事: 西島根変電所220/110kV連系変圧器N-1電制装置、110kV金城連絡線N-1電制装置、金城変電所110/66kV連系変圧器N-1電制装置設置工事（共用按分2.55%/4.07%） | AA8: ノンファーム型接続・再給電方式、充電制限（接続検討時に準ず） | AC8: medium | AE8: 2025年12月2日付契約申込(2026年1月16日受付)の承諾。系統容量確定。スキャンPDFのDrive OCRで読取のため一部判読不能（工期等） | AF8: ○ | AH8: =IF(AD8<>"","未読",IF(AND(D8<>"接続検討回答",D8<>"再接続検討",D8<>"契約申込回答"),"",TRIM(IF(O8="","負担金なし ","")&IF(U8="","工期なし ","")&IF(AND(O8<>"",OR(P8="",P8="不明")),"税区分不明 ","")&IF(AC8="low","信頼度low","")))) -> 工期なし | AJ8: 未確認 | AM8: 開く | AN8: 916（エクスパワー）_発電設備等に関する契約申込みお回答について（承諾）_中国電力NW_20260707.pdf | AO8: 916（エクスパワー）_発電設備等に関する契約申込みお回答について（承諾）_中国電力NW_20260707.pdf
A9: 8 | B9: 0916 | C9: 0916_島根県浜田市宇野町1819-1他3筆（エクスパワー） | D9: その他 | E9: 中国 | F9: 2026-07-07 | H9: 株式会社パワーエックス（PX浜田市宇野町1819-1蓄電所） | I9: 島根県浜田市宇野町1819番1他4筆 | J9: 1994 | K9: 1999 | L9: 6.6kV | M9: 下府変電所（配電用） | N9: 6kV国分線 | O9: 32506910 | P9: 税込 | Q9: =IF(O9="","",IF(P9="税抜",O9*1.1,O9)/10000) -> 3250.691 | R9: =IF(Q9="","不明",IF(Q9<=500,"〜500万",IF(Q9<=1000,"500〜1,000万",IF(Q9<=3000,"1,000〜3,000万","3,000万〜")))) -> 3,000万〜 | S9: 請求額 32,506,910円(税込, うち消費税等2,955,173円)。お支払済み保証金1,600,000円を差引き今回ご請求額30,906,910円、支払期限2026年8月10日 | T9: 1600000 | V9: =IF(U9="","不明",IF(U9<=6,"〜6ヶ月",IF(U9<=12,"7〜12ヶ月",IF(U9<=24,"13〜24ヶ月","25ヶ月〜")))) -> 不明 | W9: 竣工予定日 2029年3月1日 | X9: 竣工予定日2029年3月1日 | AA9: 工事はご負担額を申し受けた後に着手 | AC9: high | AE9: 工事費負担金請求書（スキャン画像を目視読取） | AF9: － | AH9: =IF(AD9<>"","未読",IF(AND(D9<>"接続検討回答",D9<>"再接続検討",D9<>"契約申込回答"),"",TRIM(IF(O9="","負担金なし ","")&IF(U9="","工期なし ","")&IF(AND(O9<>"",OR(P9="",P9="不明")),"税区分不明 ","")&IF(AC9="low","信頼度low","")))) | AJ9: 未確認 | AM9: 開く | AN9: 916（エクスパワー）_工事費のご請求について_20260707.pdf | AO9: 916（エクスパワー）_工事費のご請求について_20260707.pdf
A10: 9 | B10: 0916 | C10: 0916_島根県浜田市宇野町1819-1他3筆（エクスパワー） | D10: その他 | E10: 中国 | F10: 2026-07-07 | G10: 2026-01-16 | H10: 株式会社パワーエックス（PX浜田市宇野町1819-1蓄電所） | I10: 島根県浜田市宇野町1819番1他4筆 | J10: 1994 | K10: 1999 | L10: 6.6kV | M10: 下府変電所（配電用） | N10: 6kV国分線 | P10: 不明 | Q10: =IF(O10="","",IF(P10="税抜",O10*1.1,O10)/10000) | R10: =IF(Q10="","不明",IF(Q10<=500,"〜500万",IF(Q10<=1000,"500〜1,000万",IF(Q10<=3000,"1,000〜3,000万","3,000万〜")))) -> 不明 | V10: =IF(U10="","不明",IF(U10<=6,"〜6ヶ月",IF(U10<=12,"7〜12ヶ月",IF(U10<=24,"13〜24ヶ月","25ヶ月〜")))) -> 不明 | X10: 系統連系予定日 2029年3月1日 | AA10: PCS力率 放電94%遅れ/充電90%進み一定（2026.6.15追記）、出力変化速度設定、オンライン制御準備までオフライン(手動)出力制御、PCS2,600kW→1,999kW出力制限、蓄電池7,404kWh | AC10: medium | AE10: 系統連系承諾日2026-07-07、定格出力1,999kW、連系電圧高圧6kV。負担金記載なし（OCR読取） | AF10: － | AH10: =IF(AD10<>"","未読",IF(AND(D10<>"接続検討回答",D10<>"再接続検討",D10<>"契約申込回答"),"",TRIM(IF(O10="","負担金なし ","")&IF(U10="","工期なし ","")&IF(AND(O10<>"",OR(P10="",P10="不明")),"税区分不明 ","")&IF(AC10="low","信頼度low","")))) | AJ10: 未確認 | AM10: 開く | AN10: 916（エクスパワー）_系統連系およびアンシラリーサービス契約承諾書_20260707.pdf | AO10: 916（エクスパワー）_系統連系およびアンシラリーサービス契約承諾書_20260707.pdf
A11: 10 | B11: 0919 | C11: 0919_山口県周防大島町久賀2086-4（エクスパワー） | D11: 接続検討回答 | E11: 中国 | H11: （PX周防大島町久賀2086-4蓄電所, お問合せ番号G周南184(柳井)） | I11: 山口県大島郡周防大島町久賀2086-4 | P11: 不明 | Q11: =IF(O11="","",IF(P11="税抜",O11*1.1,O11)/10000) | R11: =IF(Q11="","不明",IF(Q11<=500,"〜500万",IF(Q11<=1000,"500〜1,000万",IF(Q11<=3000,"1,000〜3,000万","3,000万〜")))) -> 不明 | V11: =IF(U11="","不明",IF(U11<=6,"〜6ヶ月",IF(U11<=12,"7〜12ヶ月",IF(U11<=24,"13〜24ヶ月","25ヶ月〜")))) -> 不明 | AB11: 本接続検討結果の有効期間は発行日から1年（2025-10-09送付メールより） | AC11: low | AD11: スキャン画像PDF（約7MB）: read_file_contentでは本文テキスト化されず（グラフ断片のみ）、download_file_contentはMCPセッション切断で2回失敗 | AE11: 回答送付メール(2025-10-09, 中国電力NW, 1jUHmHFjZyvXbIa9p3mhiiwEaOb-XFCU6)より: 原本はパスワード付ZIP「【秘】接続検討回答書（高圧）（G周南184）.zip」。連系申込時にPCS出力制限証明書提出要、保証金=接続検討回答時の工事費負担金概算×5%。読めた断片は西島根/徳山系統の2024年度潮流グラフのみ。接続検討申込(2025-06-06)、発調申込書類(2025-11-14修正)あり | AF11: － | AH11: =IF(AD11<>"","未読",IF(AND(D11<>"接続検討回答",D11<>"再接続検討",D11<>"契約申込回答"),"",TRIM(IF(O11="","負担金なし ","")&IF(U11="","工期なし ","")&IF(AND(O11<>"",OR(P11="",P11="不明")),"税区分不明 ","")&IF(AC11="low","信頼度low","")))) -> 未読 | AJ11: 未確認 | AM11: 開く | AN11: 接続検討回答_#0919_山口県大島郡周防大島町久賀2086-4.pdf | AO11: 251010_接続検討回答/接続検討回答_#0919_山口県大島郡周防大島町久賀2086-4.pdf
A12: 11 | B12: 1092 | C12: 1092_三重県伊勢市特高 | D12: 接続検討回答 | E12: 中部 | F12: 2026-06-16 | G12: 2026-03-16 | H12: 株式会社パワーエックス（三重伊勢蓄電所） | I12: 三重県伊勢市矢持町（番地未定） | J12: 49880 | K12: 50000 | L12: 77kV | M12: 南勢変電所（275/77kV）系統／度会橋変電所 | N12: 77kV度会橋連絡線 No.26鉄塔より架空2回線(A160)で連系 | O12: 922900000 | P12: 税込 | Q12: =IF(O12="","",IF(P12="税抜",O12*1.1,O12)/10000) -> 92290 | R12: =IF(Q12="","不明",IF(Q12<=500,"〜500万",IF(Q12<=1000,"500〜1,000万",IF(Q12<=3000,"1,000〜3,000万","3,000万〜")))) -> 3,000万〜 | S12: 工事費負担金の総額922.9百万円(消費税相当額83.9百万円含む)、税抜839.0百万円（架空線643.6/変電169.0/通信18.7/計量7.8）。概算工事費総額2,355.4百万円(税込) | U12: 57 | V12: =IF(U12="","不明",IF(U12<=6,"〜6ヶ月",IF(U12<=12,"7〜12ヶ月",IF(U12<=24,"13〜24ヶ月","25ヶ月〜")))) -> 25ヶ月〜 | W12: 工事費負担金の入金後 57カ月程度（契約手続き期間・停電作業制約は含まず）。運用開始希望日2028年4月5日に間に合わないため連系時期の変更が必要 | X12: 希望2028年4月5日に間に合わず（入金後57カ月程度） | Y12: 鉄塔1基建替・アクセス線A160×2回線0.03km新設、南勢変電所 遮断器・断路器・開閉器取替(短絡容量超過)、N-1充電停止装置新設(南勢変275/77kV変圧器・77kV南勢度会橋線・77kV度会橋連絡線)、度会橋変PCM対向試験・補償リアクトル保護装置改造、押淵変電所断路器取替、他社(A社)受電用CT取替、VCT/計量器・保安通信・給電情報伝送装置新設 | Z12: 上位2電圧(500/275kV)は再給電方式。南勢変電所275/77kV変圧器関連のN-1充電停止装置新設等（増強ではなく電制装置） | AA12: ノンファーム型接続適用(主な設備:77kV度会橋連絡線)、N-1電制(本格適用)、早期連系追加対策(充電制限)前提・充電制限12時間/日目安、PCM保護継電装置設置、励磁突入電流対策(電圧変動対策 不適)、保護装置 不適(Tr%Z増加等)、運転力率は別途指定 | AB12: 接続検討の回答日から1年を経過した場合は契約申込不可 | AC12: high | AE12: 最大受電電力49,880kW・最大自家消費電力50,000kW。検討対象年度2032年度。専用線オンライン化工事は別途回答（同フォルダ） | AF12: ○ | AG12: 運開希望日に間に合わず | AH12: =IF(AD12<>"","未読",IF(AND(D12<>"接続検討回答",D12<>"再接続検討",D12<>"契約申込回答"),"",TRIM(IF(O12="","負担金なし ","")&IF(U12="","工期なし ","")&IF(AND(O12<>"",OR(P12="",P12="不明")),"税区分不明 ","")&IF(AC12="low","信頼度low","")))) | AJ12: 未確認 | AM12: 開く | AN12: 接続検討回答書【株式会社パワーエックスさま（三重伊勢蓄電所）】.pdf | AO12: 接続検討回答書/接続検討回答書【株式会社パワーエックスさま（三重伊勢蓄電所）】.pdf
A13: 12 | B13: 1092 | C13: 1092_三重県伊勢市特高 | D13: その他 | E13: 中部 | F13: 2026-06-16 | G13: 2026-03-16 | H13: 株式会社パワーエックス（三重伊勢蓄電所） | I13: 三重県伊勢市矢持町（番地未定） | O13: 152020000 | P13: 税込 | Q13: =IF(O13="","",IF(P13="税抜",O13*1.1,O13)/10000) -> 15202 | R13: =IF(Q13="","不明",IF(Q13<=500,"〜500万",IF(Q13<=1000,"500〜1,000万",IF(Q13<=3000,"1,000〜3,000万","3,000万〜")))) -> 3,000万〜 | S13: 工事補償金の総額152.02百万円(消費税等相当額13.82百万円含む)。税抜138.2百万円（給電0.0/通信138.2）、概算工事費141.8百万円(税抜,給電は未定) | V13: =IF(U13="","不明",IF(U13<=6,"〜6ヶ月",IF(U13<=12,"7〜12ヶ月",IF(U13<=24,"13〜24ヶ月","25ヶ月〜")))) -> 不明 | W13: 『未定』 通常は工事補償金の入金後41ヶ月程度(給電1ヶ月,通信41ヶ月)だが制御システム改修時期が未確定のため未定 | Y13: 通信線路の2ルート化(光ケーブル施設)、専用線オンライン用CDT装置設置、給電制御システムデータメンテ | AA13: 2ルート目の事業者鉄塔～連系変電所区間OPGWは事業者設置 | AC13: high | AE13: 接続検討回答に付随する専用線オンライン化工事の見積回答（工事補償金）。添付:通信工事検討結果(1UvesZxdLFKjdMsJE0C3L1TyUpYJpJXGO)は前提条件のみで金額なし | AF13: － | AH13: =IF(AD13<>"","未読",IF(AND(D13<>"接続検討回答",D13<>"再接続検討",D13<>"契約申込回答"),"",TRIM(IF(O13="","負担金なし ","")&IF(U13="","工期なし ","")&IF(AND(O13<>"",OR(P13="",P13="不明")),"税区分不明 ","")&IF(AC13="low","信頼度low","")))) | AJ13: 未確認 | AM13: 開く | AN13: 専用線オンライン化工事 御見積の回答について（三重伊勢蓄電所）.pdf | AO13: 接続検討回答書/専用線オンライン化工事 御見積の回答について（三重伊勢蓄電所）.pdf
A14: 13 | B14: 1113 | C14: 1113_茨城県行方市浜1985-1,1985-3,1986-3（合同会社高塚） | D14: 接続検討回答 | E14: 東京 | P14: 不明 | Q14: =IF(O14="","",IF(P14="税抜",O14*1.1,O14)/10000) | R14: =IF(Q14="","不明",IF(Q14<=500,"〜500万",IF(Q14<=1000,"500〜1,000万",IF(Q14<=3000,"1,000〜3,000万","3,000万〜")))) -> 不明 | V14: =IF(U14="","不明",IF(U14<=6,"〜6ヶ月",IF(U14<=12,"7〜12ヶ月",IF(U14<=24,"13〜24ヶ月","25ヶ月〜")))) -> 不明 | AC14: low | AD14: スキャン画像PDF（約7MB）: read_file_contentでは本文テキスト化されず（グラフ断片のみ）、download_file_contentはMCPセッション切断で2回失敗 | AE14: 埋込みファイル名「接続検討の回答について【JK25GHZ040495】.pdf」（東京電力PG様式）。同フォルダに東電PGのノンファーム型接続同意書・売電先確定のお願い・ローカル系統混雑同意書・出力制御PCS仕様確認依頼書（回答同封物）あり。申込書は「茨城県行方市浜蓄電所」(2025-12-15)。数値は未取得 | AF14: － | AH14: =IF(AD14<>"","未読",IF(AND(D14<>"接続検討回答",D14<>"再接続検討",D14<>"契約申込回答"),"",TRIM(IF(O14="","負担金なし ","")&IF(U14="","工期なし ","")&IF(AND(O14<>"",OR(P14="",P14="不明")),"税区分不明 ","")&IF(AC14="low","信頼度low","")))) -> 未読 | AJ14: 未確認 | AM14: 開く | AN14: 接続検討回答.pdf | AO14: 04_回答/接続検討回答.pdf
A15: 14 | B15: 1123 | C15: 00_取り下げ、進行不可/1123_北海道道厚岸郡浜中町姉別南三線(エクスパワー）) | D15: 接続検討回答 | E15: 北海道 | F15: 2025-04-18 | G15: 2025-01-20 | H15: 株式会社エクスパワー | I15: 北海道厚岸郡浜中町姉別南三線179、他 | J15: 20395 | K15: 20450 | L15: 66kV | M15: 厚床変電所系統（工事検討結果の系統図より、要確認） | N15: 66kV根室2号線 No.361付近より1回線T分岐（66kV連系線ACSR/AC95sq 0.34km） | O15: 63500000 | P15: 税込 | Q15: =IF(O15="","",IF(P15="税抜",O15*1.1,O15)/10000) -> 6350 | R15: =IF(Q15="","不明",IF(Q15<=500,"〜500万",IF(Q15<=1000,"500〜1,000万",IF(Q15<=3000,"1,000〜3,000万","3,000万〜")))) -> 3,000万〜 | S15: 工事費負担金総額63.5百万円（消費税等5.8百万円含む）。税抜57.7百万円＝架空線33.7＋通信10.3＋計量13.7＋給電0.0。概算工事費84.9百万円(税込)。一般負担上限超過0 | U15: 26 | V15: =IF(U15="","不明",IF(U15<=6,"〜6ヶ月",IF(U15<=12,"7〜12ヶ月",IF(U15<=24,"13〜24ヶ月","25ヶ月〜")))) -> 25ヶ月〜 | W15: 工事費負担金の入金後26ヶ月程度（契約申込受付2025年5月下旬・入金2025年12月下旬を仮定）。今回申込のアクセス線運転開始希望日には連系不可 | X15: 工程表上: アクセス設備の運用開始可能日 2027年3月上旬（希望日2027年3月1日）※本文では希望日連系不可・ノンファームシステム開発期間は含まず | Y15: 66kV根室2号線No.361支持物建替、66kV連系線新設0.34km、通信回線構成・光ケーブル0.4km、中給・釧路系統制御所システム改修、計量器・VCT。申込者側: 電圧変動対策(STATCOM等 容量性/誘導性 各16MVar程度)、連系用変圧器%Z 64%以上(100MVAベース) | Z15: なし（基幹系北新得変275/187kVはノンファーム混雑管理で対応） | AA15: ノンファーム型接続（北新得変電所275/187kV連絡用変圧器）、再給電方式(一定の順序)、ローカル系統混雑管理、N-1電制本格適用、充放電抑制、PCS単独運転検出ロック、力率別途協議 | AB15: 接続検討回答日から1年を経過すると契約申込不可 | AC15: high | AE15: 受付番号 託2024_1167（約款改訂に係る更新版）。00_取り下げ、進行不可フォルダ配下。同フォルダに01回答について/02注意事項/04工事検討結果/05計量設備接続構造図/06電圧変動対策/07保安通信回線資料、03.発調申請書類に同一回答書の重複コピー(id=1sMDU7cV4t_qkmuBQLG5nGQqHwwzOswpH)あり | AF15: ○ | AG15: 運開希望日に間に合わず | AH15: =IF(AD15<>"","未読",IF(AND(D15<>"接続検討回答",D15<>"再接続検討",D15<>"契約申込回答"),"",TRIM(IF(O15="","負担金なし ","")&IF(U15="","工期なし ","")&IF(AND(O15<>"",OR(P15="",P15="不明")),"税区分不明 ","")&IF(AC15="low","信頼度low","")))) | AJ15: 未確認 | AM15: 開く | AN15: 03_接続検討回答書（約款改訂に係る更新）_【託2024_1167】_1.pdf | AO15: 1123_北海道道厚岸郡浜中町姉別南三線(エクスパワー）)/01_接続検討回答/03_接続検討回答書（約款改訂に係る更新）_【託2024_1167】_1.pdf
A16: 15 | B16: 1129 | C16: 1129_崇徳学園入野グラウンド(大柿産業) | D16: 事前相談回答 | E16: 中国 | F16: 2026-02-17 | G16: 2026-01-28 | H16: 株式会社イノスタ | I16: 広島県東広島市河内町入野字東山2138番38,2138番37 | J16: 100000 | L16: 110kV | N16: 想定連系点まで直線距離約5.2km | P16: 不明 | Q16: =IF(O16="","",IF(P16="税抜",O16*1.1,O16)/10000) | R16: =IF(Q16="","不明",IF(Q16<=500,"〜500万",IF(Q16<=1000,"500〜1,000万",IF(Q16<=3000,"1,000〜3,000万","3,000万〜")))) -> 不明 | S16: 事前相談のため記載なし | V16: =IF(U16="","不明",IF(U16<=6,"〜6ヶ月",IF(U16<=12,"7〜12ヶ月",IF(U16<=24,"13〜24ヶ月","25ヶ月〜")))) -> 不明 | W16: 記載なし（接続検討で検討） | Z16: 平常時における混雑発生［あり］、主な混雑設備：110kV椋梨川線 | AA16: ノンファーム型接続適用電源。熱容量起因の連系制限欄は取消線（対象外）。FRT要件充足要。逆潮流側のみの検討（順潮流は接続検討で実施）。 | AC16: high | AE16: 特別高圧様式CK3。PDFはテキスト層なし（Print To PDF）のため画像レンダリングして目視で読取。事前相談は100,000kW/110kVだが、その後の接続検討申込は高圧規模で別スキーム。 | AF16: － | AH16: =IF(AD16<>"","未読",IF(AND(D16<>"接続検討回答",D16<>"再接続検討",D16<>"契約申込回答"),"",TRIM(IF(O16="","負担金なし ","")&IF(U16="","工期なし ","")&IF(AND(O16<>"",OR(P16="",P16="不明")),"税区分不明 ","")&IF(AC16="low","信頼度low","")))) | AI16: 比較不可(片方に値なし)（メモ:東広島654(1129崇徳)） | AJ16: 未確認 | AM16: 開く | AN16: 【秘】事前相談に対する回答書（広島２６１４）.pdf | AO16: 01.事前相談/【秘】事前相談に対する回答書（広島２６１４）.pdf
A17: 16 | B17: 1129 | C17: 1129_崇徳学園入野グラウンド(大柿産業) | D17: 接続検討回答 | E17: 中国 | F17: 2026-06-29 | G17: 2026-04-03 | H17: 株式会社パワーエックス | I17: 広島県東広島市河内町入野字東山12138番37（（仮称）PX東広島市河内蓄電所） | J17: 1994 | K17: 1999 | L17: 6.6kV（高圧） | M17: 高屋変電所（配電用）／基幹変電所：広島変電所 | N17: 6kV 是国線 大仙支20号柱より分岐（竹原変電所6kV新庄線は空き容量なしのため不可） | O17: 103700000 | P17: 税込 | Q17: =IF(O17="","",IF(P17="税抜",O17*1.1,O17)/10000) -> 10370 | R17: =IF(Q17="","不明",IF(Q17<=500,"〜500万",IF(Q17<=1000,"500〜1,000万",IF(Q17<=3000,"1,000〜3,000万","3,000万〜")))) -> 3,000万〜 | S17: 工事費負担金総額103.7百万円（消費税等9.5百万円含む）。税抜94.2百万円の内訳：架空線41.9／地中線44.8／計量0.3／上位系対策0.6／伐採6.6。概算工事費総額159.2百万円（税込、税抜144.7）。一般負担上限超過なし。 | U17: 92 | V17: =IF(U17="","不明",IF(U17<=6,"〜6ヶ月",IF(U17<=12,"7〜12ヶ月",IF(U17<=24,"13〜24ヶ月","25ヶ月〜")))) -> 25ヶ月〜 | W17: 工事費負担金の入金後92箇月程度（契約手続期間は含まず） | X17: 運用開始希望日2027-10-01には連系不可、連系時期の調整が必要（入金後92箇月） | Y17: 6kV架空線：高圧線新設168m・張替7,511m（RW-AL-OC200㎜2、455A）、電柱新設4本・建替59本、開閉器新設3・取替4、TVR取替1台、計測機能付開閉器1台、引込線30m／地中線：管路330m（Φ125×2条）・CVT325㎟ 195m／伐採23径間／計量器2台（受電用・供給用）ほか。工事亘長 架空約7.8km・地中約0.2km | Z17: 220kV広島西幹線対策（N-1充電停止装置設置他：先行事業者特定負担46.1百万円×共用比率1.3%＝0.6百万円）、220kV広島系SSC取替（一般負担3.0百万円）。先行事業者分として実施中で、本文では本対策完了前の連系が可能とする | AA17: ノンファーム型接続（再給電方式・一定の順序、制御量に影響する主設備：220kV広島西幹線、オンライン出力制御機器を自社負担で導入）。早期連系追加対策（充電制限）適用：110kV広島西条線の熱容量を順潮流で超過するため、スケジュール運転機能・区分計量器が必要（暫定措置、不同意なら増強工事＋再検討）。力率：放電時 進み93%／充電時 遅れ93%一定。出力変化速度の設定、停止後は手動復帰、作業停止時の充放電抑制、N-1電制本格適用。発電側課金割引区分A-3。検討年度2034年度。サイバーセキュリティ要件 | AB17: 有効期限の明記なし（系統状況の変化等で有効でなくなる場合ありとの記載のみ） | AC17: high | AE17: PDFはパスワード付きだったが、同じ回答書フォルダにあるファイル名の値（中国電力NWの通知パスワードと推定）で開けた。別紙2（概略工程表）：92箇月工程、6kV架空約7.8km・地中約0.2km。注意事項欄には『上位系統の空き容量不足のため対策工事を実施中で、連系は上位系統対策完了後』とあり、本文7頁の『本対策完了前の連系が可能』と食い違うため確認が必要。別紙4（110kV広島西条線の季節別想定潮流）はグラフのみで数値はテキストで取れない。 | AF17: ○ | AG17: 運開希望日に間に合わず | AH17: =IF(AD17<>"","未読",IF(AND(D17<>"接続検討回答",D17<>"再接続検討",D17<>"契約申込回答"),"",TRIM(IF(O17="","負担金なし ","")&IF(U17="","工期なし ","")&IF(AND(O17<>"",OR(P17="",P17="不明")),"税区分不明 ","")&IF(AC17="low","信頼度low","")))) | AI17: 比較不可(片方に値なし)（メモ:東広島654(1129崇徳)） | AJ17: 未確認 | AM17: 開く | AN17: 【秘】接続検討回答書(G東広島654).pdf | AO17: 04.接続検討回答書/【秘】接続検討回答書(G東広島654).pdf
A18: 17 | B18: 1135 | C18: 1135_北海道夕張郡由仁町川端1178番、1180番（葵アセットマネジメント株式会社） | D18: 事前相談回答 | E18: 北海道 | F18: 2026-02-27 | G18: 2026-01-28 | H18: 株式会社イノスタ | I18: 北海道夕張郡由仁町川端1178番、1180番 | J18: 25000 | L18: 66kV | N18: 66kV 川端線 NO.78 付近（想定連系点、設置場所から直線距離約2km） | P18: 不明 | Q18: =IF(O18="","",IF(P18="税抜",O18*1.1,O18)/10000) | R18: =IF(Q18="","不明",IF(Q18<=500,"〜500万",IF(Q18<=1000,"500〜1,000万",IF(Q18<=3000,"1,000〜3,000万","3,000万〜")))) -> 不明 | S18: 事前相談のため工事費負担金の記載なし | V18: =IF(U18="","不明",IF(U18<=6,"〜6ヶ月",IF(U18<=12,"7〜12ヶ月",IF(U18<=24,"13〜24ヶ月","25ヶ月〜")))) -> 不明 | W18: 記載なし（工事内容・工期は接続検討で検討） | Z18: 主な混雑設備：北江別変電所 187/66kV 連変 | AA18: ノンファーム型接続適用電源。平常時混雑発生［なし］・［あり］及び熱容量起因連系制限［なし］・［あり］の選択はテキスト抽出で判別不可（連系制限ありの場合の最大受電電力欄は「－kW」）。北海道エリアは需給調整面の出力制御可能性あり。 | AC18: high | AE18: 事前相談回答（特別高圧様式CK3、受付託2025_1317、申込者はイノスタ名義、希望受電電圧66kV・25,000kW）。その後PX名義で高圧接続検討（託2026_0059、（仮称）PX北海道夕張蓄電所、高圧4台）を申込んだが2026-06-09付で取下げ、接続検討料220,000円(税込)返金のお知らせ(2026-06-11)あり。接続検討回答書はフォルダ内に無し。 | AF18: － | AH18: =IF(AD18<>"","未読",IF(AND(D18<>"接続検討回答",D18<>"再接続検討",D18<>"契約申込回答"),"",TRIM(IF(O18="","負担金なし ","")&IF(U18="","工期なし ","")&IF(AND(O18<>"",OR(P18="",P18="不明")),"税区分不明 ","")&IF(AC18="low","信頼度low","")))) | AI18: 比較不可(片方に値なし)（メモ:北海道由仁町(案件1135)） | AJ18: 未確認 | AM18: 開く | AN18: 【非公開情報等】【託2025_1317】事前相談回答書_株式会社イノスタ.pdf | AO18: 03_接続検討申請/01.事前相談/【非公開情報等】【託2025_1317】事前相談回答書_株式会社イノスタ.pdf
A19: 18 | B19: 1136 | C19: 1136_兵庫県高砂市中筋3丁目780番（藤栄建設） | D19: 接続検討回答 | E19: 関西 | F19: 2026-04-28 | G19: 2026-02-10 | H19: 株式会社パワーエックス（兵庫高砂蓄電所, 受付番号2025-82-04346） | I19: 兵庫県高砂市中筋三丁目780番,781番 | J19: 1994 | K19: 100 | L19: 6.6kV | M19: 曽根変電所 | N19: 天川配電線（アルミ120sq, 阿弥陀43E2付近から高圧引込） | O19: 32500000 | P19: 税込 | Q19: =IF(O19="","",IF(P19="税抜",O19*1.1,O19)/10000) -> 3250 | R19: =IF(Q19="","不明",IF(Q19<=500,"〜500万",IF(Q19<=1000,"500〜1,000万",IF(Q19<=3000,"1,000〜3,000万","3,000万〜")))) -> 3,000万〜 | S19: 工事費負担金の総額32.5百万円(消費税等相当額含む, 額は空欄)、税抜29.5（架空線29.3/計量0.2）。概算工事費総額32.7百万円(税抜29.7)。※内訳表の単位表記は「千円」だが数値は百万円単位相当 | U19: 24 | V19: =IF(U19="","不明",IF(U19<=6,"〜6ヶ月",IF(U19<=12,"7〜12ヶ月",IF(U19<=24,"13〜24ヶ月","25ヶ月〜")))) -> 13〜24ヶ月 | W19: 工事費負担金の入金後 24ケ月程度（契約手続き期間含まず）。運用開始希望日2027年2月1日には連系不可、連系時期の調整が必要 | X19: 希望2027年2月1日は不可（入金後24ケ月程度） | Y19: 電柱建替15本、高圧線新設831m・張替182m(アルミ120sq)、変圧器位置替14台、開閉器新設/位置替、電圧調整器新設3台(3500kVA)、引込線20m、計量設備(VCT・計量器2台・通信端局) | Z19: なし（上位系増強工事 -） | AA19: ノンファーム型接続適用（北摂変電所500/275kV変圧器混雑）・再給電方式。早期連系追加対策(充電制限)は現時点不要。揚水・蓄電池特別措置適用前提で算定。OCR・DGR保護協調は連系申込時に検討 | AB19: 接続検討の回答日から1年を経過した場合は契約申込不可 | AC19: high | AE19: 最大自家消費電力100kWとして検討。検討対象年度2026年度。同一内容のコピーが複数(1LxdEg…, 1ecLWJ…, 1BMTiR…, 圧縮版1bMaqG…/1vyKSS…)。発調申込(2026-05-18提出)フォルダあり、充電制限同意書(関西,2026-05-15)も存在 | AF19: ○ | AG19: 運開希望日に間に合わず | AH19: =IF(AD19<>"","未読",IF(AND(D19<>"接続検討回答",D19<>"再接続検討",D19<>"契約申込回答"),"",TRIM(IF(O19="","負担金なし ","")&IF(U19="","工期なし ","")&IF(AND(O19<>"",OR(P19="",P19="不明")),"税区分不明 ","")&IF(AC19="low","信頼度low","")))) | AJ19: 未確認 | AM19: 開く | AN19: 接続検討申込みに対する回答について.pdf | AO19: 03_イノスタ作成成果物/接続検討申込みに対する回答について.pdf
A20: 19 | B20: 1147 | C20: 1147_愛知県岡崎市板田町東流石（中部産業） | D20: 接続検討回答 | E20: 中部 | F20: 2026-06-03 | G20: 2026-03-09 | H20: 株式会社パワーエックス（PX愛知県岡崎市蓄電所, 受付番号AAD610461758） | I20: 愛知県岡崎市板田町字東流石27-1 他26筆 | J20: 1994 | K20: 1999 | L20: 6.6kV | M20: 大平変電所 | N20: 大平変電所F36 01ｷ401より分岐（OC-W60mm2） | O20: 7946700 | P20: 税込 | Q20: =IF(O20="","",IF(P20="税抜",O20*1.1,O20)/10000) -> 794.67 | R20: =IF(Q20="","不明",IF(Q20<=500,"〜500万",IF(Q20<=1000,"500〜1,000万",IF(Q20<=3000,"1,000〜3,000万","3,000万〜")))) -> 500〜1,000万 | S20: 工事費負担金の総額7,946.7千円(消費税相当額722.4千円含む)、税抜7,224.3千円（架空線86.7/バンク逆潮流対策6,979.0/計量158.6）。概算工事費総額38,769.8千円(税込) | T20: 397000 | U20: 6 | V20: =IF(U20="","不明",IF(U20<=6,"〜6ヶ月",IF(U20<=12,"7〜12ヶ月",IF(U20<=24,"13〜24ヶ月","25ヶ月〜")))) -> 〜6ヶ月 | W20: 工事費負担金の入金後 6ヶ月程度（契約手続き期間含まず）。別紙: 2028年度下期頃予定のバンク逆潮流対策工事後に連系可能となるため、上記工期かバンク逆潮流対策工事のどちらか遅い時期 | X20: 入金後6ヶ月 または 2028年度下期頃（バンク逆潮流対策工事後）の遅い方 | Y20: 架空線(高圧引込線20m等)、配変バンク逆潮流対策、計量設備(計量器2台・VCT) | Z20: 上位系統の現場調査・設計/工事施工が工程表に記載（バンク逆潮流対策 2028年度下期頃） | AA20: ノンファーム型接続(275kV東部額田線・新三河変電所)、再給電方式、早期連系追加対策(充電制限)前提、PCS力率一定 充電95%進み/放電99%遅れ、手動復帰、構内変圧器タップ6600、N-1電制本格適用(新三河変電所) | AB20: 接続検討の回答日から1年を経過した場合は契約申込不可 | AC20: high | AE20: 系統連系保証金397千円(税込,消費税36千円含む)を記載。希望運用開始2027年2月1日。同一ファイルのコピー2件(1OeU4m…,1zQE5s…)とZIP版(1CHhco…, 未展開)あり。別紙「所要工期について」(1dUW8K…)参照 | AF20: ○ | AG20: 工期と別にバンク/上位系対策待ち | AH20: =IF(AD20<>"","未読",IF(AND(D20<>"接続検討回答",D20<>"再接続検討",D20<>"契約申込回答"),"",TRIM(IF(O20="","負担金なし ","")&IF(U20="","工期なし ","")&IF(AND(O20<>"",OR(P20="",P20="不明")),"税区分不明 ","")&IF(AC20="low","信頼度low","")))) | AJ20: 未確認 | AM20: 開く | AN20: 接続検討回答書（株式会社パワーエックス PX愛知県岡崎市蓄電所）.pdf | AO20: 04.接続検討回答書/接続検討回答書 株式会社パワーエックス PX愛知県岡崎市蓄電所/接続検討回答書（株式会社パワーエックス PX愛知県岡崎市蓄電所）.pdf
A21: 20 | B21: 1147 | C21: 1147_愛知県岡崎市板田町東流石（中部産業） | D21: その他 | E21: 中部 | F21: 2026-06-16 | G21: 2026-06-11 | H21: 株式会社パワーエックス | P21: 不明 | Q21: =IF(O21="","",IF(P21="税抜",O21*1.1,O21)/10000) | R21: =IF(Q21="","不明",IF(Q21<=500,"〜500万",IF(Q21<=1000,"500〜1,000万",IF(Q21<=3000,"1,000〜3,000万","3,000万〜")))) -> 不明 | V21: =IF(U21="","不明",IF(U21<=6,"〜6ヶ月",IF(U21<=12,"7〜12ヶ月",IF(U21<=24,"13〜24ヶ月","25ヶ月〜")))) -> 不明 | AC21: high | AE21: 接続検討要否確認結果: 「接続検討申込みは省略することができます」（受付番号AAD610461758, 契約申込前の要否確認） | AF21: － | AH21: =IF(AD21<>"","未読",IF(AND(D21<>"接続検討回答",D21<>"再接続検討",D21<>"契約申込回答"),"",TRIM(IF(O21="","負担金なし ","")&IF(U21="","工期なし ","")&IF(AND(O21<>"",OR(P21="",P21="不明")),"税区分不明 ","")&IF(AC21="low","信頼度low","")))) | AJ21: 未確認 | AM21: 開く | AN21: 接続検討の要否確認依頼に対する結果について（株式会社パワーエックス様）.pdf | AO21: 07.接続検討要否確認結果※イノスタ対応/接続検討の要否確認依頼に対する結果について（株式会社パワーエックス様）.pdf
A22: 21 | B22: 1168 | C22: 1168_兵庫県高砂市伊保四丁目５１６番 | D22: 接続検討回答 | E22: 関西 | F22: 2026-06-24 | G22: 2026-04-10 | H22: 株式会社パワーエックス | I22: 兵庫県高砂市伊保四丁目516番（（仮称）PX兵庫高砂伊保四丁目蓄電所） | J22: 1994 | L22: 6.6kV（高圧） | M22: 曽根変電所 | N22: 石殿配電線（上沼田35S5付近から高圧引込） | O22: 3800000 | P22: 税込 | Q22: =IF(O22="","",IF(P22="税抜",O22*1.1,O22)/10000) -> 380 | R22: =IF(Q22="","不明",IF(Q22<=500,"〜500万",IF(Q22<=1000,"500〜1,000万",IF(Q22<=3000,"1,000〜3,000万","3,000万〜")))) -> 〜500万 | S22: 工事費負担金の総額3.8百万円（消費税等相当額 欄空白）／内訳(税抜)架空線3.3・計量0.2等 計3.5百万円。概算工事費総額4.1百万円（税抜3.7）。特措適用前提 | U22: 12 | V22: =IF(U22="","不明",IF(U22<=6,"〜6ヶ月",IF(U22<=12,"7〜12ヶ月",IF(U22<=24,"13〜24ヶ月","25ヶ月〜")))) -> 7〜12ヶ月 | W22: 工事費負担金の入金後 12ケ月程度（契約手続期間は含まず）。運用開始希望日2027/2/1には連系不可 | X22: 運用開始希望日2027年2月1日は不可（入金後12ヶ月程度） | Y22: 電柱新設1本/建替2本、高圧線新設118m・張替302m(アルミ120sq)、低圧線張替38m、引込線20m、開閉器新設、計量装置 | Z22: なし（上位系増強工事 -） | AA22: ノンファーム型接続（主な混雑設備:北摂変電所500/275kV変圧器）、再給電方式、N-1電制本格適用、力率一定制御0.9、早期連系追加対策(充電制限)は不要、特措(蓄電池特別措置)適用前提 | AB22: 接続検討の回答日から1年を経過すると契約申込不可 | AC22: high | AE22: 受付番号2025-82-05087。最大自家消費電力は95kWと記載（充電側kW不明確のためcapacity_kw_chargeはnull）。消費税額欄が空白のため税込/税抜表記は総額欄の書式による。 | AF22: ○ | AG22: 運開希望日に間に合わず | AH22: =IF(AD22<>"","未読",IF(AND(D22<>"接続検討回答",D22<>"再接続検討",D22<>"契約申込回答"),"",TRIM(IF(O22="","負担金なし ","")&IF(U22="","工期なし ","")&IF(AND(O22<>"",OR(P22="",P22="不明")),"税区分不明 ","")&IF(AC22="low","信頼度low","")))) | AJ22: 未確認 | AM22: 開く | AN22: 接続検討申込に対する回答_兵庫高砂伊保四丁目蓄電所.pdf | AO22: 接続検討申込に対する回答_兵庫高砂伊保四丁目蓄電所.pdf
A23: 22 | B23: 1169 | C23: 確認要_1169_島根県邑智郡梁瀬（石見簗瀬駅）（JR西日本） | D23: 接続検討回答 | E23: 中国 | F23: 2026-06-29 | G23: 2026-03-31 | H23: 西日本旅客鉄道株式会社 | I23: 島根県邑智郡美郷町築瀬202-7（（仮称）島根県邑智郡美郷町蓄電所） | J23: 1994 | K23: 1999 | L23: 6.6kV（高圧） | M23: 明塚変電所（配電用）/潮変電所No.2変圧器増設/基幹:作木変電所 | N23: 6kV赤来線 吾郷幹30号柱より分岐（22/6kV柱上変圧器2.5MVA新設・他発電設備の系統変更後） | O23: 322500000 | P23: 税込 | Q23: =IF(O23="","",IF(P23="税抜",O23*1.1,O23)/10000) -> 32250 | R23: =IF(Q23="","不明",IF(Q23<=500,"〜500万",IF(Q23<=1000,"500〜1,000万",IF(Q23<=3000,"1,000〜3,000万","3,000万〜")))) -> 3,000万〜 | S23: 工事費負担金の総額322.5百万円（消費税等相当額29.3百万円を含む）／税抜293.2百万円＝架空線21.5+計量0.3+その他(上位系)62.2+一般負担上限額超過分209.2。概算工事費総額481.9百万円（税込） | U23: 54 | V23: =IF(U23="","不明",IF(U23<=6,"〜6ヶ月",IF(U23<=12,"7〜12ヶ月",IF(U23<=24,"13〜24ヶ月","25ヶ月〜")))) -> 25ヶ月〜 | W23: 工事費負担金の入金後 54ヶ月程度（契約手続期間は含まず）。運用開始希望日2027/10/1には連系不可、連系時期の調整が必要 | X23: 運用開始希望日2027年10月1日は不可（入金後54ヶ月程度） | Y23: 高圧線新設1344m・張替632m、電柱新設42本/建替10本、引込線11m、SVR(3,000kVA)新設、22/6kV柱上変圧器2.5MVA新設+22kV架空線、潮変電所No.2変圧器増設(20MVA)・1次CB設置 | Z23: あり：潮変電所No.2変圧器増設(20MVA)、220kV広島西幹線/作木支線N-1充電停止装置通信設備(共用負担0.6+0.5百万円)、広島系SSC取替。一般負担上限(4.1万円/kW×1,994kW=81.8百万円)超過分209.2百万円を特定負担 | AA23: ノンファーム型接続（出力制御に影響:220kV作木支線/110kV潮熊見線）、再給電方式、N-1電制本格適用、力率 放電93%遅れ/充電90%進み一定、出力変化速度規定、充電停止あり。早期連系追加対策(充電制限)は不要 | AB23: 接続検討の回答日から1年を経過すると契約申込不可 | AC23: high | AE23: 同フォルダに【秘】書類確認結果（G松江691）.pdf（回答書ではない）あり。ZIP/emlは申込書送付関係 | AF23: ○ | AG23: 運開希望日に間に合わず | AH23: =IF(AD23<>"","未読",IF(AND(D23<>"接続検討回答",D23<>"再接続検討",D23<>"契約申込回答"),"",TRIM(IF(O23="","負担金なし ","")&IF(U23="","工期なし ","")&IF(AND(O23<>"",OR(P23="",P23="不明")),"税区分不明 ","")&IF(AC23="low","信頼度low","")))) | AJ23: 未確認 | AM23: 開く | AN23: 【秘】接続検討回答書（G松江691） | AO23: 【秘】接続検討回答書（G松江691）
A24: 23 | B24: 1185 | C24: 1185_静岡県掛川市淡陽18番1（ティーライフ） | D24: 接続検討回答 | E24: 中部 | F24: 2026-08-21 | G24: 2026-05-25 | H24: 株式会社パワーエックス（受付番号AAD240735819） | I24: 静岡県掛川市淡陽18番1（（仮称）PX静岡県掛川市蓄電所） | J24: 1994 | K24: 1999 | L24: 高圧 | M24: 安養寺変電所 | N24: 安養寺変電所F27（02ｳ851より分岐し構内柱と接続） | O24: 3260700 | P24: 税込 | Q24: =IF(O24="","",IF(P24="税抜",O24*1.1,O24)/10000) -> 326.07 | R24: =IF(Q24="","不明",IF(Q24<=500,"〜500万",IF(Q24<=1000,"500〜1,000万",IF(Q24<=3000,"1,000〜3,000万","3,000万〜")))) -> 〜500万 | S24: 工事費負担金の総額3,260.7千円（消費税相当額296.4千円を含む）。税抜2,964.3千円＝架空線工事2,805.7千円＋計量設備工事158.6千円。概算工事費も同額。 | U24: 12 | V24: =IF(U24="","不明",IF(U24<=6,"〜6ヶ月",IF(U24<=12,"7〜12ヶ月",IF(U24<=24,"13〜24ヶ月","25ヶ月〜")))) -> 7〜12ヶ月 | W24: 工事費負担金の入金後 12ヶ月程度 | X24: アクセス設備の運用開始希望日 2027年2月1日（連系可否：可） | Y24: 電柱新設1本・建替1本、高圧線新設20m・張替408m（OCW-60㎟へ太線化）、高圧引込線30m、開閉器取替、計量器1台・VCT1台 | Z24: 上位系統増強なし（駿遠変電所275/77kV変圧器の順潮流超過は充電制限で対応） | AA24: ノンファーム型接続適用（500kV西部幹線、500kV三岐幹線）、再給電方式。早期連系追加対策（充電制限）適用（駿遠変電所275/77kV変圧器の熱容量超過、スケジュール運転機能要、区分計量器要）。力率：放電97%（遅れ）・充電90%（進み）で不適→対策要。変圧器励磁突入電流による瞬時電圧変動対策要。出力変化速度5秒以上・ステップ10%以下・ランプ20%/秒以下。N-1電制本格適用。 | AB24: 接続検討の回答日から1年を経過した場合は契約申込不可 | AC24: high | AE24: 最大自家消費電力1,999kWをcapacity_kw_chargeに記載。充電制限に同意しない場合は増強工事・再接続検討の可能性。保証金額の記載なし。 | AF24: ○ | AH24: =IF(AD24<>"","未読",IF(AND(D24<>"接続検討回答",D24<>"再接続検討",D24<>"契約申込回答"),"",TRIM(IF(O24="","負担金なし ","")&IF(U24="","工期なし ","")&IF(AND(O24<>"",OR(P24="",P24="不明")),"税区分不明 ","")&IF(AC24="low","信頼度low","")))) | AJ24: 未確認 | AM24: 開く | AN24: 接続検討申込みに対する回答について.pdf | AO24: 1185_接続検討回答書一式 (PX静岡県掛川)/接続検討申込みに対する回答について.pdf
A25: 24 | B25: 1186 | C25: 確認要_1186_島根県邑智郡石原（沢谷駅）（JR西日本） | D25: 接続検討回答 | E25: 中国 | F25: 2026-06-29 | G25: 2026-03-31 | H25: 西日本旅客鉄道株式会社 | I25: 島根県邑智郡美郷町石原111-9（（仮称）JR島根県邑智郡石原蓄電所） | J25: 1994 | K25: 1999 | L25: 6.6kV（高圧） | M25: 潮変電所（配電用、No.2変圧器増設）/基幹:作木変電所 | N25: 6kV新設配電線 潮来島線144M3号柱より分岐（22/6kV柱上変圧器2.5MVA新設） | O25: 307000000 | P25: 税込 | Q25: =IF(O25="","",IF(P25="税抜",O25*1.1,O25)/10000) -> 30700 | R25: =IF(Q25="","不明",IF(Q25<=500,"〜500万",IF(Q25<=1000,"500〜1,000万",IF(Q25<=3000,"1,000〜3,000万","3,000万〜")))) -> 3,000万〜 | S25: 工事費負担金の総額307.0百万円（消費税等相当額27.9百万円を含む）／税抜279.1百万円＝架空線7.9+計量0.3+その他(上位系)84.2+一般負担上限額超過分186.7。概算工事費総額466.5百万円（税込） | U25: 54 | V25: =IF(U25="","不明",IF(U25<=6,"〜6ヶ月",IF(U25<=12,"7〜12ヶ月",IF(U25<=24,"13〜24ヶ月","25ヶ月〜")))) -> 25ヶ月〜 | W25: 工事費負担金の入金後 54ヶ月程度（契約手続期間は含まず）。運用開始希望日2027/10/1には連系不可、連系時期の調整が必要 | X25: 運用開始希望日2027年10月1日は不可（入金後54ヶ月程度） | Y25: 電柱新設3本、高圧線新設15m、引込線10m、SVR(3,000kVA)新設、22/6kV柱上変圧器2.5MVA新設(特定負担100%)+22kV架空線10m、潮変電所No.2変圧器増設(20MVA)・1次CB設置 | Z25: あり：潮変電所No.2変圧器増設(20MVA)、220kV広島西幹線/作木支線N-1充電停止装置通信設備(共用負担0.6+0.5百万円)、広島系SSC取替。一般負担上限81.8百万円超過分186.7百万円を特定負担 | AA25: ノンファーム型接続（220kV作木支線/110kV潮熊見線）、再給電方式、N-1電制本格適用、力率 放電93%遅れ/充電93%進み一定、出力変化速度規定、充電停止あり。早期連系追加対策(充電制限)は不要 | AB25: 接続検討の回答日から1年を経過すると契約申込不可 | AC25: high | AE25: 同フォルダに【秘】書類確認結果（G松江670）.pdf（回答書ではない）あり | AF25: ○ | AG25: 運開希望日に間に合わず | AH25: =IF(AD25<>"","未読",IF(AND(D25<>"接続検討回答",D25<>"再接続検討",D25<>"契約申込回答"),"",TRIM(IF(O25="","負担金なし ","")&IF(U25="","工期なし ","")&IF(AND(O25<>"",OR(P25="",P25="不明")),"税区分不明 ","")&IF(AC25="low","信頼度low","")))) | AJ25: 未確認 | AM25: 開く | AN25: 【秘】接続検討回答書（G松江670） | AO25: 【秘】接続検討回答書（G松江670）
A26: 25 | B26: 1227 | C26: 1227_島根県出雲市知井宮町1360-1（JR西日本） | D26: 接続検討回答 | E26: 中国 | F26: 2026-09-04 | G26: 2026-06-19 | H26: 株式会社パワーエックス | I26: 島根県出雲市多枝町久村137-18（蓄電所） | J26: 1994 | K26: 1999 | L26: 6.6kV | M26: 知井宮変電所（配電用／発電側課金区分）、基幹: 松江変電所。適合検討書上の供給線路は多伎変電所 新設線 | N26: 6kV新設線（久村(分)18M1号柱より分岐）、配電用変圧器3次巻線22kV引出し＋22/6kV柱上変圧器2.5MVA | O26: 97700000 | P26: 税込 | Q26: =IF(O26="","",IF(P26="税抜",O26*1.1,O26)/10000) -> 9770 | R26: =IF(Q26="","不明",IF(Q26<=500,"〜500万",IF(Q26<=1000,"500〜1,000万",IF(Q26<=3000,"1,000〜3,000万","3,000万〜")))) -> 3,000万〜 | S26: 工事費負担金総額97.7百万円（消費税等8.8百万円含む）。税抜88.9百万円＝架空線8.7＋計量0.3＋上位系増強(基幹/地域/22kV)79.9。概算工事費総額341.1百万円(税込)。共用設備分は他事業者動向で変動 | U26: 55 | V26: =IF(U26="","不明",IF(U26<=6,"〜6ヶ月",IF(U26<=12,"7〜12ヶ月",IF(U26<=24,"13〜24ヶ月","25ヶ月〜")))) -> 25ヶ月〜 | W26: 工事費負担金の入金後55ヶ月程度（アクセス設備運用開始希望日2027/6/1には連系不可、連系時期調整要） | X26: 入金後55ヶ月程度（希望日2027年6月1日は不可） | Y26: 6kV新設線・高圧線増架/新設(RW-AL-OC200mm2)、高圧引込線ACSR-OC58mm2、SVR(3,000kVA)1台、22kVスイッチギヤ新設、22/6kV柱上変圧器2.5MVA新設、計量 | Z26: あり: 松江変 N-1電制装置設置(基幹)、110kV松江知井宮線・知井宮変110/66kV N-1電制装置(地域)、22kV配電関係(柱上変圧器新設他)。上位系統増強工事計79.9百万円(税抜負担分) | AA26: ノンファーム型接続（北松江変500/220kV、66kV知井宮大田線）、再給電方式(一定の順序)、ローカル系統混雑管理、N-1電制本格適用、力率93%一定(放電遅れ/充電進み)、充電停止の可能性、出力変化速度規定、早期連系追加対策(充電制限)は不要 | AB26: 接続検討回答日から1年を経過すると契約申込不可 | AC26: high | AE26: ファイル名・フォルダは知井宮町1360-1だが、本文は受付番号G松江767・発電場所『島根県出雲市多枝町久村137-18蓄電所』（申込者パワーエックス）。別案件の回答書が誤格納の可能性あり要確認。ZIP(59MB)は未展開 ／【要確認】本文は受付G松江767・発電場所 多伎町久村137-18＝1279案件の回答書。1227フォルダへの誤格納の可能性 | AF26: ○ | AG26: 運開希望日に間に合わず | AH26: =IF(AD26<>"","未読",IF(AND(D26<>"接続検討回答",D26<>"再接続検討",D26<>"契約申込回答"),"",TRIM(IF(O26="","負担金なし ","")&IF(U26="","工期なし ","")&IF(AND(O26<>"",OR(P26="",P26="不明")),"税区分不明 ","")&IF(AC26="low","信頼度low","")))) | AJ26: 未確認 | AM26: 開く | AN26: 1227（JR西日本）_接続検討回答書_島根県出雲市知井宮町1360-1.pdf | AO26: 01.接続検討申込書/1227（JR西日本）_接続検討回答書_島根県出雲市知井宮町1360-1.pdf
A27: 26 | B27: 1228 | C27: 1228_広島県福山市神島町142-2（JR西日本） | D27: 接続検討回答 | E27: 中国 | J27: 25000 | K27: 25000 | L27: 110kV | N27: 110kV特高事業者線（No.26/27/28鉄塔改造・新設・除却） | Q27: =IF(O27="","",IF(P27="税抜",O27*1.1,O27)/10000) | R27: =IF(Q27="","不明",IF(Q27<=500,"〜500万",IF(Q27<=1000,"500〜1,000万",IF(Q27<=3000,"1,000〜3,000万","3,000万〜")))) -> 不明 | V27: =IF(U27="","不明",IF(U27<=6,"〜6ヶ月",IF(U27<=12,"7〜12ヶ月",IF(U27<=24,"13〜24ヶ月","25ヶ月〜")))) -> 不明 | AC27: low | AD27: スキャン画像PDF(13MB)。テキスト抽出は工事概要図ページの断片のみ（【秘】接続検討回答書（G福山422）、110kV、25,000kW等）。サイズ超過のためダウンロード/OCR未実施 | AE27: 受付番号G福山422（中国電力NW）と推定。工事費負担金・工期・回答日は読取不可。同フォルダにZIP2件(52MB/59MB、20MB超で未展開)。110kV/66kVパターン両方の申込書あり | AF27: － | AH27: =IF(AD27<>"","未読",IF(AND(D27<>"接続検討回答",D27<>"再接続検討",D27<>"契約申込回答"),"",TRIM(IF(O27="","負担金なし ","")&IF(U27="","工期なし ","")&IF(AND(O27<>"",OR(P27="",P27="不明")),"税区分不明 ","")&IF(AC27="low","信頼度low","")))) -> 未読 | AJ27: 未確認 | AM27: 開く | AN27: 1228（JR西日本）_接続検討回答書_広島県福山市神島町142-2.pdf | AO27: 接続検討申込書（修正版_20260604）/1228（JR西日本）_接続検討回答書_広島県福山市神島町142-2.pdf
A28: 27 | B28: 1239 | C28: 1239_つくばみらい10MW（自然電力→三田証券） | D28: 接続検討回答 | E28: 東京 | F28: 2024-01-10 | G28: 2023-12-11 | H28: フェニックスエナジー | I28: 茨城県つくばみらい市野堀611-1 | J28: 10050 | K28: 10420 | L28: 66kV | M28: 常総変電所（275/66kV、基幹用変電所） | N28: 66kV取手線系の既設送電線（66kV神生ソーラー線）No.3鉄塔より1回線分岐 | O28: 131000000 | P28: 税込 | Q28: =IF(O28="","",IF(P28="税抜",O28*1.1,O28)/10000) -> 13100 | R28: =IF(Q28="","不明",IF(Q28<=500,"〜500万",IF(Q28<=1000,"500〜1,000万",IF(Q28<=3000,"1,000〜3,000万","3,000万〜")))) -> 3,000万〜 | S28: 工事費負担金総額131.0百万円（消費税等11.9百万円含む）。税抜119.1百万円＝架空線111.7＋通信4.0＋計量3.4。概算工事費138.8百万円(税込) | T28: 6543000 | U28: 18 | V28: =IF(U28="","不明",IF(U28<=6,"〜6ヶ月",IF(U28<=12,"7〜12ヶ月",IF(U28<=24,"13〜24ヶ月","25ヶ月〜")))) -> 13〜24ヶ月 | W28: 工事費負担金の入金後1年6ヶ月程度（契約申込受付後・損害実費弁償契約締結後2年10ヶ月程度）。運用開始希望日2024/10/1には連系不可 | X28: 工程表上アクセス設備供給可能時期2026/12 | Y28: 66kVアクセス線新設ACSR/AC160mm2×1回線0.04km、既設No.3鉄塔建替1基、電線移線0.22km、通信(受電状態自動伝達装置・光/メタル0.2km・ノンファーム設備)、VCT・計量器新設 | Z28: なし（上位系増強工事の記載なし） | AA28: ノンファーム型接続（275kV東京北線・鹿島線）、再給電方式(一定の順序)、N-1電制本格適用、1回線連系に伴う抑制、充電抑制/停止の可能性 | AB28: 接続検討回答日から1年を経過すると契約申込不可 | AC28: high | AE28: 受付番号JK23GHZ014338。金額・工期は2023年2月15日付接続検討回答書の値を記載と明記（再回答）。系統連系保証金6,543千円(税込)。同フォルダに受理済み系統連系申込書・保証金請求書・損害実費弁償契約書・供給承諾書(2025/04/14)・TEPCO打合せ資料(2025/3/25)あり。つくば_案件紹介資料.zip(44MB)未展開 | AF28: ○ | AG28: 運開希望日に間に合わず | AH28: =IF(AD28<>"","未読",IF(AND(D28<>"接続検討回答",D28<>"再接続検討",D28<>"契約申込回答"),"",TRIM(IF(O28="","負担金なし ","")&IF(U28="","工期なし ","")&IF(AND(O28<>"",OR(P28="",P28="不明")),"税区分不明 ","")&IF(AC28="low","信頼度low","")))) | AJ28: 未確認 | AM28: 開く | AN28: 20240110_接続検討回答書_つくばみらい.pdf | AO28: Document for Utility_電力関連資料/20240110_接続検討回答書_つくばみらい.pdf
A29: 28 | B29: 1244 | C29: 1244_高砂市阿弥陀町北池190 | D29: 接続検討回答 | E29: 関西 | F29: 2026-09-15 | G29: 2026-06-19 | H29: 株式会社パワーエックス（受付番号2026-82-00685） | I29: 兵庫県高砂市阿弥陀町北池字向沖190（(仮称)PX兵庫高砂市蓄電所） | J29: 1994 | K29: 95 | L29: 高圧 | M29: 曽根変電所 | N29: 天川配電線 | O29: 22800000 | P29: 税込 | Q29: =IF(O29="","",IF(P29="税抜",O29*1.1,O29)/10000) -> 2280 | R29: =IF(Q29="","不明",IF(Q29<=500,"〜500万",IF(Q29<=1000,"500〜1,000万",IF(Q29<=3000,"1,000〜3,000万","3,000万〜")))) -> 1,000〜3,000万 | S29: 工事費負担金の総額22.8百万円（消費税等相当額 百万円を含む＝金額欄空欄）。税抜20.7百万円＝架空線工事20.5＋計量設備工事0.2。概算工事費総額23.0百万円（税抜20.9）。一般負担上限超過0.0。 | U29: 30 | V29: =IF(U29="","不明",IF(U29<=6,"〜6ヶ月",IF(U29<=12,"7〜12ヶ月",IF(U29<=24,"13〜24ヶ月","25ヶ月〜")))) -> 25ヶ月〜 | W29: 工事費負担金の入金後 30ヶ月程度（概略工程表上は契約手続き期間を含まず）。運用開始希望日には連系不可、連系時期の調整が必要 | X29: 運用開始希望日2027年6月1日は連系不可。連系可能は工事費負担金入金から30ヶ月後 | Y29: 電柱新設3本・建替21本、高圧線新設1207m（アルミ120sq）・張替346m（銅5.0mm→アルミ120sq）、変圧器位置替13台、手動開閉器新設1・位置替2、自動開閉器位置替3、電圧調整器(SVR)新設1台3500kVA、高圧引込線20m、計量器2台・VCT1台・通信端局2台 | Z29: 上位系増強工事なし | AA29: ノンファーム型接続適用（主な混雑設備：北摂変電所500/275kV変圧器、停止作業94日/年）。基幹系は再給電方式（一定の順序）。早期連系追加対策（充電制限）は希望されたが現時点で不要と判定。出力変化速度5秒以上、力率一定制御0.9（整定値表）、自動再連系不可。蓄電池特別措置適用前提で算定。N-1電制本格適用。OCR・DGR保護協調は契約申込時に実施。 | AB29: 接続検討の回答日から1年を経過した場合は契約申込不可 | AC29: high | AE29: 最大自家消費電力95kWをcapacity_kw_chargeに記載（原文「最大自家消費電力：95kW」）。消費税額欄が空欄のため税込額は総額表記どおり。同一内容のPDFが案件フォルダ直下にも「接続検討申込に対する回答」(id 11wMRjmY9vR_k2lPjFjtXH2YMcHdAn1fg, 同サイズ515012B)として重複保存。 | AF29: ○ | AG29: 運開希望日に間に合わず | AH29: =IF(AD29<>"","未読",IF(AND(D29<>"接続検討回答",D29<>"再接続検討",D29<>"契約申込回答"),"",TRIM(IF(O29="","負担金なし ","")&IF(U29="","工期なし ","")&IF(AND(O29<>"",OR(P29="",P29="不明")),"税区分不明 ","")&IF(AC29="low","信頼度low","")))) | AJ29: 未確認 | AM29: 開く | AN29: 1244（藤栄建設）_接続検討申込に対する回答_兵庫県高砂市阿弥陀町北池字向沖190番.pdf | AO29: 03.接続検討申込書一式/1244（藤栄建設）_接続検討申込に対する回答_兵庫県高砂市阿弥陀町北池字向沖190番.pdf
A30: 29 | B30: 1279 | C30: 1279_島根県出雲市多伎町久村137-18（須山木材） | D30: 接続検討回答 | E30: 中国 | Q30: =IF(O30="","",IF(P30="税抜",O30*1.1,O30)/10000) | R30: =IF(Q30="","不明",IF(Q30<=500,"〜500万",IF(Q30<=1000,"500〜1,000万",IF(Q30<=3000,"1,000〜3,000万","3,000万〜")))) -> 不明 | V30: =IF(U30="","不明",IF(U30<=6,"〜6ヶ月",IF(U30<=12,"7〜12ヶ月",IF(U30<=24,"13〜24ヶ月","25ヶ月〜")))) -> 不明 | AC30: low | AD30: パスワード付き（PDFがユーザーパスワードで暗号化）。中国電力NWのパスワードは案件ごとにランダムに発行される（G松江691の通知メールで確認）。G松江767の『受領およびパスワードのご連絡』メールやパスワードのメモは、案件フォルダ内（再帰的に）、Drive全体の検索、Gmailのいずれにも見つからなかった | AE30: ファイル名(G松江767=中国電力NW松江の受付番号と推定)以外読めず全項目null。同フォルダに接続検討申込書xlsx・PCS仕様確認依頼書・単線結線図(2.5MVA 6.6kV 60Hz昇圧変圧器)・機器仕様書あり。パスワード入手後に再抽出要。 中国電力NWの受付担当（ネットワークサービスセンター）が発行した通知メールを入手するか、PDFを再送してもらう必要がある。 ／1227フォルダに同じG松江767の読める回答書あり（97.7百万円税込・入金後55ヶ月） | AF30: － | AH30: =IF(AD30<>"","未読",IF(AND(D30<>"接続検討回答",D30<>"再接続検討",D30<>"契約申込回答"),"",TRIM(IF(O30="","負担金なし ","")&IF(U30="","工期なし ","")&IF(AND(O30<>"",OR(P30="",P30="不明")),"税区分不明 ","")&IF(AC30="low","信頼度low","")))) -> 未読 | AJ30: 未確認 | AM30: 開く | AN30: 【秘】接続検討回答書（G松江767）.pdf | AO30: 02.接続検討/【秘】接続検討回答書（G松江767）.pdf
A31: 30 | B31: 1315 | C31: 1315_長野県上水内郡信濃町案件（本久） | D31: 接続検討回答 | E31: 中部 | F31: 2026-09-25 | G31: 2026-06-29 | H31: 株式会社パワーエックス | I31: 長野県上水内郡信濃町大字大井字市道端2272番1（（仮称）信濃蓄電所） | J31: 1998 | K31: 1999 | L31: 高圧 | M31: 牟礼変電所 | O31: 207000000 | P31: 税込 | Q31: =IF(O31="","",IF(P31="税抜",O31*1.1,O31)/10000) -> 20700 | R31: =IF(Q31="","不明",IF(Q31<=500,"〜500万",IF(Q31<=1000,"500〜1,000万",IF(Q31<=3000,"1,000〜3,000万","3,000万〜")))) -> 3,000万〜 | S31: 連系否。工事費負担金概算は207百万円以上（消費税等相当額を含む）。配変増強のみで負担可能上限額を超過、配電線以下工事は未検討・未計上 | V31: =IF(U31="","不明",IF(U31<=6,"〜6ヶ月",IF(U31<=12,"7〜12ヶ月",IF(U31<=24,"13〜24ヶ月","25ヶ月〜")))) -> 不明 | X31: 連系否 | Y31: 牟礼変電所（配電用変電所）の増強が必要 | Z31: 配電用変電所増強（牟礼変電所 熱容量超過）。費用が負担可能上限額を超過 | AA31: 連系否（理由:配変増強で負担金上限を超過するため）。代替案・連系可能最大受電電力の提示なし | AC31: high | AE31: 連系否の回答。受付番号AAD510748080。同一内容のファイルが03_電力申請/1315_接続検討申込みに対する回答について_中部電力NW_長野県上水内郡信濃町大字大井字市道端2279番4.pdf (id 1TBV299-lhcB9nz3p0aiYcfA5guFIkZlV, 同サイズ261852B) にも重複保存 | AF31: ○ | AG31: 連系不可 | AH31: =IF(AD31<>"","未読",IF(AND(D31<>"接続検討回答",D31<>"再接続検討",D31<>"契約申込回答"),"",TRIM(IF(O31="","負担金なし ","")&IF(U31="","工期なし ","")&IF(AND(O31<>"",OR(P31="",P31="不明")),"税区分不明 ","")&IF(AC31="low","信頼度low","")))) -> 工期なし | AJ31: 未確認 | AM31: 開く | AN31: 接続検討申込みに対する回答について | AO31: 接続検討申込みに対する回答について
A32: 31 | B32: 1316 | C32: 1316_北海道虻田郡喜茂別町(ソーラークリエート) | D32: 接続検討回答 | E32: 北海道 | F32: 2025-09-24 | G32: 2025-06-24 | H32: Akaysha Energy Japan株式会社（受付番号 託2024_2340） | I32: 北海道虻田郡喜茂別町中里376-1,379-1（（仮称）AKJ西双葉蓄電所） | J32: 400000 | K32: 411100 | L32: 275kV | M32: 275kV道央西幹線（西野変電所～西双葉開閉所） | N32: 275kV道央西幹線 No.111付近より2回線T分岐（2回線常時）、連系用開閉器にて架空線と気中接続 | O32: 814500000 | P32: 税込 | Q32: =IF(O32="","",IF(P32="税抜",O32*1.1,O32)/10000) -> 81450 | R32: =IF(Q32="","不明",IF(Q32<=500,"〜500万",IF(Q32<=1000,"500〜1,000万",IF(Q32<=3000,"1,000〜3,000万","3,000万〜")))) -> 3,000万〜 | S32: 工事費負担金総額814.5百万円（消費税等相当額74.1百万円を含む）。税抜740.4百万円＝架空線448.0＋通信設備203.0＋計量設備89.4（変電・給電は0）。概算工事費総額1,929.0百万円（税175.4含む、税抜1,753.6）。一般負担分923.8百万円、上限超過0。 | U32: 36 | V32: =IF(U32="","不明",IF(U32<=6,"〜6ヶ月",IF(U32<=12,"7〜12ヶ月",IF(U32<=24,"13〜24ヶ月","25ヶ月〜")))) -> 25ヶ月〜 | W32: 工事費負担金の入金後 3年程度（契約申込2025年10月・入金2027年2月までと仮定。ノンファームシステム開発期間は含まず） | X32: アクセス設備の運用開始可能日：2030年3月上旬（希望日2027年9月30日は連系不可） | Y32: 鉄塔新設2基・道央西幹線No.111建替、275kV連系線新設0.3km（ACSR/AC410mm2複導体×2回線）、No.110～112間移線0.8km、電磁誘導対策、保護継電装置取替4式（西双葉開閉所・西野変電所）、給電システム改修2式、通信装置・光ケーブル0.4km、特別精密級計量器2台。申込者側：STATCOM等無効電力補償装置 容量性230MVar・誘導性230MVar程度（概算） | Z32: 上位系統増強なし（基幹系増強の記載なし。変電・給電・通信の一般負担分のみ） | AA32: ノンファーム型接続適用（出力制御量に影響を与える主な設備：なし）、基幹系再給電方式。電圧変動対策（STATCOM等）要、送電線保護は主後一体型2系列、系統安定化システム設置の可能性、出力変動幅±400MWに対する変化率制約の可能性、N-1電制本格適用、順潮流側は作業停止時・系統状況により充電停止の可能性。 | AB32: 接続検討の回答日から1年を経過した場合は契約申込不可 | AC32: high | AE32: 申込者はAkaysha Energy Japan（PX/ソーラークリエートではない）。案件フォルダ「電力関連」に表紙・(1)工事検討結果・(2)計量設備回答書・(3)計量設備接続構造図・(4)運用制約による電圧変動対策・注意事項と一式で保管。土地契約書も「西双葉」名義で本案件(喜茂別町)と同一地点と推定。最大自家消費電力411,100kWをcapacity_kw_chargeに記載。 | AF32: ○ | AG32: 運開希望日に間に合わず | AH32: =IF(AD32<>"","未読",IF(AND(D32<>"接続検討回答",D32<>"再接続検討",D32<>"契約申込回答"),"",TRIM(IF(O32="","負担金なし ","")&IF(U32="","工期なし ","")&IF(AND(O32<>"",OR(P32="",P32="不明")),"税区分不明 ","")&IF(AC32="low","信頼度low","")))) | AJ32: 未確認 | AM32: 開く | AN32: 接続検討回答書（AKJ西双葉蓄電所_Akaysha Energy Japan㈱）.pdf | AO32: 電力関連/接続検討回答書（AKJ西双葉蓄電所_Akaysha Energy Japan㈱）.pdf
A33: 32 | B33: 1326 | C33: 1326_大栄工業_伊賀市案件 | D33: その他 | E33: 中部 | H33: 株式会社大栄工業 | I33: 三重県伊賀市予野字向川540番1（伊賀市予野540-1(蓄電池)） | O33: 13337722 | P33: 税込 | Q33: =IF(O33="","",IF(P33="税抜",O33*1.1,O33)/10000) -> 1333.7722 | R33: =IF(Q33="","不明",IF(Q33<=500,"〜500万",IF(Q33<=1000,"500〜1,000万",IF(Q33<=3000,"1,000〜3,000万","3,000万〜")))) -> 1,000〜3,000万 | S33: 連系工事費負担金 金13,337,722円（内消費税等1,212,520円）。系統連系保証金589,000円(2025/11/17支払済)を差引いた支払工事費負担金12,748,722円 | T33: 589000 | V33: =IF(U33="","不明",IF(U33<=6,"〜6ヶ月",IF(U33<=12,"7〜12ヶ月",IF(U33<=24,"13〜24ヶ月","25ヶ月〜")))) -> 不明 | W33: 支払工事費負担金は請求日から1ヶ月以内に支払 | Y33: 架空線工事一式、計量設備工事一式 | AC33: medium | AE33: 回答書ではなく連系工事費負担金契約書（中部電力PG、甲:大栄工業）。契約日の記載はOCR上『2006年7月6日』だが別通知では2026年7月16日付契約とされる。申込日は契約書上2025年10月27日付。回答書本体は1326_三重県伊賀市予野字向川540番2フォルダにあり（同一案件）。他に名義変更通知書docx2件 | AF33: － | AH33: =IF(AD33<>"","未読",IF(AND(D33<>"接続検討回答",D33<>"再接続検討",D33<>"契約申込回答"),"",TRIM(IF(O33="","負担金なし ","")&IF(U33="","工期なし ","")&IF(AND(O33<>"",OR(P33="",P33="不明")),"税区分不明 ","")&IF(AC33="low","信頼度low","")))) | AJ33: 未確認 | AM33: 開く | AN33: 工事負担金契約書.pdf | AO33: 工事負担金契約書.pdf
A34: 33 | B34: 1326 | C34: 1326_三重県伊賀市予野字向川540番2 | D34: 接続検討回答 | E34: 中部 | N34: 77kV荒木上野線（潮流実績グラフのみ判読） | Q34: =IF(O34="","",IF(P34="税抜",O34*1.1,O34)/10000) | R34: =IF(Q34="","不明",IF(Q34<=500,"〜500万",IF(Q34<=1000,"500〜1,000万",IF(Q34<=3000,"1,000〜3,000万","3,000万〜")))) -> 不明 | V34: =IF(U34="","不明",IF(U34<=6,"〜6ヶ月",IF(U34<=12,"7〜12ヶ月",IF(U34<=24,"13〜24ヶ月","25ヶ月〜")))) -> 不明 | AC34: low | AD34: スキャン画像PDF(5.8MB)。テキスト抽出はグラフ断片のみで本文読取不可（サイズのためダウンロード/OCR未実施） | AE34: 接続検討回答書（中部電力PG）と推定。後続の契約申込回答書(KK5390)に主要条件あり | AF34: － | AH34: =IF(AD34<>"","未読",IF(AND(D34<>"接続検討回答",D34<>"再接続検討",D34<>"契約申込回答"),"",TRIM(IF(O34="","負担金なし ","")&IF(U34="","工期なし ","")&IF(AND(O34<>"",OR(P34="",P34="不明")),"税区分不明 ","")&IF(AC34="low","信頼度low","")))) -> 未読 | AJ34: 未確認 | AM34: 開く | AN34: 予野接続検討回答.pdf | AO34: 予野接続検討回答.pdf
A35: 34 | B35: 1326 | C35: 1326_三重県伊賀市予野字向川540番2 | D35: その他 | E35: 中部 | F35: 2026-03-25 | H35: 株式会社大栄工業 | I35: 伊賀市予野540-2蓄電池 | Q35: =IF(O35="","",IF(P35="税抜",O35*1.1,O35)/10000) | R35: =IF(Q35="","不明",IF(Q35<=500,"〜500万",IF(Q35<=1000,"500〜1,000万",IF(Q35<=3000,"1,000〜3,000万","3,000万〜")))) -> 不明 | V35: =IF(U35="","不明",IF(U35<=6,"〜6ヶ月",IF(U35<=12,"7〜12ヶ月",IF(U35<=24,"13〜24ヶ月","25ヶ月〜")))) -> 不明 | AC35: high | AE35: 接続検討の要否確認結果：接続検討申込は不要（地番540-2→540-1へ変更可能）。工事費・工期の記載なし | AF35: － | AH35: =IF(AD35<>"","未読",IF(AND(D35<>"接続検討回答",D35<>"再接続検討",D35<>"契約申込回答"),"",TRIM(IF(O35="","負担金なし ","")&IF(U35="","工期なし ","")&IF(AND(O35<>"",OR(P35="",P35="不明")),"税区分不明 ","")&IF(AC35="low","信頼度low","")))) | AJ35: 未確認 | AM35: 開く | AN35: 接続検討の要否確認依頼に対する結果について.pdf | AO35: 接続検討の要否確認依頼に対する結果について.pdf
A36: 35 | B36: 1326 | C36: 1326_三重県伊賀市予野字向川540番2 | D36: 契約申込回答 | E36: 中部 | F36: 2026-05-28 | G36: 2025-12-02 | H36: 株式会社大栄工業 | I36: 三重県伊賀市予野字向川540番2 | J36: 1997 | K36: 1999 | L36: 6.6kV | M36: 予野変電所（配電用）、基幹系: 中勢275/77変電所 | N36: 予野変電所F25 56ﾇ191より分岐 | O36: 13337722 | P36: 税込 | Q36: =IF(O36="","",IF(P36="税抜",O36*1.1,O36)/10000) -> 1333.7722 | R36: =IF(Q36="","不明",IF(Q36<=500,"〜500万",IF(Q36<=1000,"500〜1,000万",IF(Q36<=3000,"1,000〜3,000万","3,000万〜")))) -> 1,000〜3,000万 | S36: 工事費負担金13,337,722円（消費税等1,212,520円含む）=概算工事費。税抜12,125,203円＝架空線11,973,208＋計量151,995。支払済系統連系保証金を差引いて請求 | T36: 589000 | U36: 29 | V36: =IF(U36="","不明",IF(U36<=6,"〜6ヶ月",IF(U36<=12,"7〜12ヶ月",IF(U36<=24,"13〜24ヶ月","25ヶ月〜")))) -> 25ヶ月〜 | W36: 工事費負担金の入金後29ヶ月程度（運用開始希望日2026/4/1は所要工期超過のため調整要） | Y36: 高圧線張替316m（5mm→OC-W60mm2）、高圧引込線新設10m、電圧調整器取替1台、計量器・VCT | Z36: 別紙工程表に『上位系統』『先行件名』の記載あり（詳細不明） | AA36: ノンファーム型接続（西部変500/275kV、新鈴鹿変275/77kV、77kV新鈴鹿壬生野線・荒木壬生野線・荒木上野線・白樫分岐線）、再給電方式(一定の順序)、ローカル系統混雑管理、N-1電制本格適用、PCS力率一定0.98、手動復帰、早期連系追加対策(充電制限)留意事項あり | AB36: 連系工事費負担金契約の締結意思を2026年6月29日までに表示（01案内） | AC36: high | AE36: 受付番号KK5390。同内容PDF(02 契約申込回答書（KK5390）.pdf, id=1P3ezrP3TiQAGK5rjy2e_o7HaJ0aL3Zyk)あり、本文はdocx版から読取。申込受付日2025/12/2は01案内記載（工事負担金契約書では2025/10/27付申込）。保証金589,000円は工事負担金契約書記載。別紙03〜06（取り決め・検討結果説明書・工事概要図・所要工期）同梱。連系工事費負担金契約締結済み(13,337,722円)、2026/9/16付で発電者名を大栄工業→パワーエックスに変更 | AF36: ○ | AH36: =IF(AD36<>"","未読",IF(AND(D36<>"接続検討回答",D36<>"再接続検討",D36<>"契約申込回答"),"",TRIM(IF(O36="","負担金なし ","")&IF(U36="","工期なし ","")&IF(AND(O36<>"",OR(P36="",P36="不明")),"税区分不明 ","")&IF(AC36="low","信頼度low","")))) | AJ36: 未確認 | AM36: 開く | AN36: 02 契約申込回答書（KK5390）.docx | AO36: 02 契約申込回答書（KK5390）.docx
A37: 36 | B37: 1326 | C37: 1326_三重県伊賀市予野字向川540番2 | D37: その他 | E37: 中部 | F37: 2026-09-16 | H37: 株式会社パワーエックス | I37: 伊賀市予野540-1（蓄電池） | Q37: =IF(O37="","",IF(P37="税抜",O37*1.1,O37)/10000) | R37: =IF(Q37="","不明",IF(Q37<=500,"〜500万",IF(Q37<=1000,"500〜1,000万",IF(Q37<=3000,"1,000〜3,000万","3,000万〜")))) -> 不明 | V37: =IF(U37="","不明",IF(U37<=6,"〜6ヶ月",IF(U37<=12,"7〜12ヶ月",IF(U37<=24,"13〜24ヶ月","25ヶ月〜")))) -> 不明 | AC37: high | AE37: 2026/7/16付連系工事費負担金契約の発電者名を株式会社大栄工業→株式会社パワーエックスへ変更した旨の通知（名義変更通知書2026/9/8付に基づく） | AF37: － | AH37: =IF(AD37<>"","未読",IF(AND(D37<>"接続検討回答",D37<>"再接続検討",D37<>"契約申込回答"),"",TRIM(IF(O37="","負担金なし ","")&IF(U37="","工期なし ","")&IF(AND(O37<>"",OR(P37="",P37="不明")),"税区分不明 ","")&IF(AC37="low","信頼度low","")))) | AJ37: 未確認 | AM37: 開く | AN37: 発電者名の変更について（お知らせ） | AO37: 発電者名の変更について（お知らせ）
A38: 37 | B38: 1412 | C38: 1412_秦野案件(セブンシーズアドバイザーズ) | D38: その他 | E38: 東京 | F38: 2026-08-28 | H38: セブンシーズアドバイザーズ株式会社 | O38: 143000000 | P38: 税込 | Q38: =IF(O38="","",IF(P38="税抜",O38*1.1,O38)/10000) -> 14300 | R38: =IF(Q38="","不明",IF(Q38<=500,"〜500万",IF(Q38<=1000,"500〜1,000万",IF(Q38<=3000,"1,000〜3,000万","3,000万〜")))) -> 3,000万〜 | S38: ①アクセス線新設（新設電源線増強） 概算負担金 143百万円（税込） | U38: 27 | V38: =IF(U38="","不明",IF(U38<=6,"〜6ヶ月",IF(U38<=12,"7〜12ヶ月",IF(U38<=24,"13〜24ヶ月","25ヶ月〜")))) -> 25ヶ月〜 | W38: 概算工期 2年3ケ月（起点の記載なし） | X38: 上位系統である変電所の設備対策が必要。この対策工事には少なくとも10年以上を要する可能性が高く、貴社蓄電所連系はその工事完了後 | Y38: アクセス線新設（新設電源線増強） | Z38: 有：順潮流時の送電容量確保のため上位系統変電所の設備対策が必要、少なくとも10年以上を要する可能性が高い | AA38: 最大受電電力に対する連系可否の確認であり接続供給契約の契約電力等を考慮した設備対策ではない。概算負担金は発電側最大受電電力が需要側契約電力を超過する想定で算出。送電線距離・架空/地中・周辺環境・周辺電源申込状況・電源線共用・制度変更による変動は未考慮 | AC38: high | AE38: 東京電力PGの『概算負担金・概算工期のお知らせ』（接続検討前の簡易回答。正式な接続検討回答ではない）。容量・電圧・変電所の記載なし。同フォルダ07.接続検討申込書一式に『秦野特高蓄電所』（66kV GIS仕様あり）の接続検討申込書xlsxがあるが回答書は未格納。概算工期2年3ヶ月とは別に上位系統対策10年以上が律速。 | AF38: － | AG38: 工期と別にバンク/上位系対策待ち | AH38: =IF(AD38<>"","未読",IF(AND(D38<>"接続検討回答",D38<>"再接続検討",D38<>"契約申込回答"),"",TRIM(IF(O38="","負担金なし ","")&IF(U38="","工期なし ","")&IF(AND(O38<>"",OR(P38="",P38="不明")),"税区分不明 ","")&IF(AC38="low","信頼度low","")))) | AJ38: 未確認 | AM38: 開く | AN38: 概算負担金・概算工期のお知らせ(（仮）セブンシーズ秦野グラウンド蓄電所) | AO38: 概算負担金・概算工期のお知らせ(（仮）セブンシーズ秦野グラウンド蓄電所)
A39: 38 | B39: 1437 | C39: 1437_大阪府大阪市平野区長吉長原４丁目１８−１０（タイヨー平野店） | D39: 接続検討回答 | E39: 関西 | F39: 2026-09-02 | G39: 2026-06-30 | H39: 株式会社リッチフィールド | I39: 大阪府大阪市平野区長吉長原4丁目18-19 | J39: 1994 | K39: 1999 | L39: 6.6kV | M39: 川辺変電所 | N39: F38 南川辺配電線（高圧引込線ACOCL120sq 3m） | O39: 6382300 | P39: 税込 | Q39: =IF(O39="","",IF(P39="税抜",O39*1.1,O39)/10000) -> 638.23 | R39: =IF(Q39="","不明",IF(Q39<=500,"〜500万",IF(Q39<=1000,"500〜1,000万",IF(Q39<=3000,"1,000〜3,000万","3,000万〜")))) -> 500〜1,000万 | S39: 工事費負担金の総額6,382.3千円（消費税等相当額を含む・額欄は空欄）／総額(消費税等相当額を除く)5,803.0千円。概算工事費総額6,599.5千円（税抜5,999.5千円）。主な項目: バンク逆潮流対策5,383.8千円。内訳列はテキスト抽出で崩れており要原本確認 | U39: 3 | V39: =IF(U39="","不明",IF(U39<=6,"〜6ヶ月",IF(U39<=12,"7〜12ヶ月",IF(U39<=24,"13〜24ヶ月","25ヶ月〜")))) -> 〜6ヶ月 | W39: バンク逆潮流対策工事：2031年4月以降連系可／架空線・計量装置工事：工事費負担金の入金後3ヶ月程度 | X39: バンク逆潮流対策工事完了後の2031年4月以降かつ工事費負担金入金から3ヶ月程度後 | Y39: バンク逆潮流対策1式、高圧引込線3m新設、引込用開閉器200A新設、計量器(受電・供給)・VCT・通信端局 | Z39: 上位系増強工事の記載なし（バンク逆潮流対策が律速、2031年4月以降） | AA39: ノンファーム型接続、再給電方式(一定の順序)、N-1電制本格適用、出力変化速度5秒以上、力率一定制御90%、早期連系追加対策(充電制限)は不要 | AB39: 接続検討回答日から1年を経過すると契約申込不可 | AC39: medium | AE39: 受付番号22-J0095。表紙に『＜第2案＞』とあり第1案はフォルダ内に無し。発電場所は回答書上18-19（フォルダ名は18-10）。工事費負担金の内訳列の対応がテキスト抽出で崩れているため内訳は要原本確認。税込判断は税抜総額5,803.0千円×1.1≒6,382.3千円による | AF39: ○ | AG39: 工期と別にバンク/上位系対策待ち | AH39: =IF(AD39<>"","未読",IF(AND(D39<>"接続検討回答",D39<>"再接続検討",D39<>"契約申込回答"),"",TRIM(IF(O39="","負担金なし ","")&IF(U39="","工期なし ","")&IF(AND(O39<>"",OR(P39="",P39="不明")),"税区分不明 ","")&IF(AC39="low","信頼度low","")))) | AJ39: 未確認 | AM39: 開く | AN39: 接続検討回答書 | AO39: 接続検討回答書
A40: 39 | C40: xxxx_熊本県阿蘇郡杖立（アークエル）設備変更_小嶋さん | D40: 接続検討回答 | E40: 九州 | Q40: =IF(O40="","",IF(P40="税抜",O40*1.1,O40)/10000) | R40: =IF(Q40="","不明",IF(Q40<=500,"〜500万",IF(Q40<=1000,"500〜1,000万",IF(Q40<=3000,"1,000〜3,000万","3,000万〜")))) -> 不明 | V40: =IF(U40="","不明",IF(U40<=6,"〜6ヶ月",IF(U40<=12,"7〜12ヶ月",IF(U40<=24,"13〜24ヶ月","25ヶ月〜")))) -> 不明 | AC40: low | AD40: 画像のみPDF（read_file_contentでテキスト空）かつ10.6MBでdownload_file_contentの10MB上限超過のためダウンロード不可 | AE40: ファイル名から2025-09-11付の接続検討回答書と推定（未読）。参考：同フォルダ『20260519_工事負担金請求書.pdf』(id 1TAxIersnPI0NGEzzlDPtXSDPtZfJJQ8g)は読取可で、九州電力送配電 日田配電事業所→アークエル株式会社、2026-05-19発行、使用場所 熊本県阿蘇郡小国町大字下城三俣263（杖立第一蓄電所）、工事件名『発電所新設申込に伴う系統連系工事』、請求金額34,251,663円（10%対象、うち消費税等3,113,787円）、支払期日2026-06-18、単独申込。概算工事金額34,516,663円（税込）=配電設備工事(電柱新設2本・高圧線585m・高圧引込線90m等)+バンク逆潮流対策 杖立変電所 1,320円/kW(税込)×1,999kW=2,638,680円。フォルダには接続検討申込書・接続供給/発電量調整供給申込書xlsxもあり。サブフォルダ『イノスタ提出済み/02.接続検討』には大阪府池田市桃園案件の申込書類が混在 | AF40: － | AH40: =IF(AD40<>"","未読",IF(AND(D40<>"接続検討回答",D40<>"再接続検討",D40<>"契約申込回答"),"",TRIM(IF(O40="","負担金なし ","")&IF(U40="","工期なし ","")&IF(AND(O40<>"",OR(P40="",P40="不明")),"税区分不明 ","")&IF(AC40="low","信頼度low","")))) -> 未読 | AJ40: 未確認 | AM40: 開く | AN40: 20250911_接続検討回答書_杖立_(1)_1.pdf | AO40: 20250911_接続検討回答書_杖立_(1)_1.pdf
...

Sheet 凡例
A1: 接続検討回答 検証一覧
A2: 作成日 | B2: 2026-10-01（2026-10-05 追記）
A3: 出典 | B3: Googleドライブ「10_案件別資料」(フォルダID 1EPmWUK4lLBGkOlqCMv0b9XRxa3kipsIt) 配下の回答書をAIで読取（No1〜45）。2026-10-05追記: 「02_案件資料（PowerX様）」(フォルダID 1HR5tWnhE-0XOhtQnFoUVPtwMLtKMTdw-) 配下の案件別フォルダ（進行中36・【保留】61・【中止】115の計212フォルダ）にある接続検討回答書・再接続検討回答書をAIで読取（No46〜124、79件）
A4: 未取得 | B4: なし（フォルダID 1HR5tWnhE-0XOhtQnFoUVPtwMLtKMTdw- は2026-10-05に読取済。Googleドライブ連携では読めないため、Chromeで開いているアカウント経由で読取）。本文を読めなかったPDFは0件。中国電力NWの回答書のうち15件は画像のみのPDF（テキスト層なし、原本はパスワード付き）で文字を機械抽出できないため、ページ画像を画面に表示して目視で読み取り、読取信頼度をmediumとした（備考に明記、要確認シートにも掲載）
A6: シート | B6: 内容
A7: 回答一覧 | B7: 回答書1件=1行。青字=AI読取値（原本と照合する対象）。黄色セル=検証者が入力
A8: 要確認 | B8: 未読・読取信頼度low・負担金/工期の欠落・7月メモとの差異がある行の抜粋
A9: 集計 | B9: 負担金帯・工期帯・電力会社別の件数（回答一覧から数式で自動集計）
A10: 7月メモ比較 | B10: 2026-07-24分析メモの値と今回読取値の突合
A11: 案件フォルダ | B11: 10_案件別資料の48案件フォルダ＋02_案件資料（PowerX様）の212案件フォルダの回答書有無（追記分は 進行中→保留→中止 の順）
A13: 列の見方
A14: 負担金(税込・万円) | B14: 税抜の記載は×1.1で税込換算（数式）。税区分不明はそのまま
A15: 負担金帯 | B15: 〜500万 / 500〜1,000万 / 1,000〜3,000万 / 3,000万〜 / 不明
A16: 工期帯 | B16: 〜6ヶ月 / 7〜12ヶ月 / 13〜24ヶ月 / 25ヶ月〜 / 不明（起点は「工期の原文」列で確認）
A17: 集計対象 | B17: ○=案件(サイト)ごとの最新の回答（接続検討/再接続検討/契約申込で負担金あり）。集計シートは○のみを数える
A18: 律速・可否メモ | B18: 連系不可・運開希望日に間に合わず・工期と別にバンク逆潮流/上位系対策の待ち がある回答を自動表示
A19: 自動チェック | B19: 負担金なし・工期なし・税区分不明・信頼度low・未読 を自動表示
A20: 検証ステータス | B20: 黄色セルに 未確認 / 確認済 / 要修正 をプルダウンで入力
A21: 注意 | B21: AI読取値はスクリーニング用。社外提出や判断の前に必ず原本PDFで確認すること
A23: 追記分（No46以降）の書き方
A24: 案件名 | B24: フォルダ名のまま。【保留】【中止】フォルダ内の案件は「【保留】/…」「【中止】/…」と表記し、備考の先頭にも「状態: 進行中／保留／中止」を記載
A25: 重複ファイルの扱い | B25: 同じ回答書が複数の名前で保存されている場合は、受付番号つきの「【接続検討回答書】No…（受付番号）.pdf」「【再接続検討回答書】No…」を正として1行にした。「4.」「4-1.」などで始まる写し、原本の「PX…_【秘】…」、[OLD]の差替前は行にしていない
A26: 放電kW／充電kW | B26: 放電kW＝最大受電電力、充電kW＝最大自家消費電力（回答書の記載）
A27: 工期(月) | B27: 東北電力は配電設備(工事)の所要工期を記載。上位系統増強工事・バンク逆潮流対策・変電設備工事の工期や完了予定は「工期の原文」「上位系統増強」に記載し、配電設備より長い／遅い場合は律速・可否メモに「工期と別にバンク/上位系対策待ち」を表示
A28: 運開見込み（東北・中部） | B28: 回答書に希望日への可否の記載がないため、回答日＋工期(月)の単純計算（契約手続き期間は含まず）が運用開始希望日の月を超える場合に「運開希望日に間に合わず」とした
A29: 主な対策工事（東北） | B29: 対象設備表の項目と数量を転記。数量が「／」で2つ並ぶものは表の左→右（新設／建替・張替・取替／改造・改修・撤去）の順で、列の別は原本の表で確認すること
A30: 負担金(円)（東北） | B30: 別紙「概算工事費及び工事費負担金の総額」の工事費負担金の総額（百万円単位・税込）を円に換算。上位系統増強が必要な案件は一般負担の上限超過分を含むため数十億円になるものがある
A31: 読取信頼度（追記分） | B31: high＝PDFのテキストを機械抽出して読取。medium＝画像のみのPDFをページ画像の目視で読取（数字の読み違いの可能性があるため優先して原本照合）。low＝本文を読めなかったもの
A32: 集計対象（追記分） | B32: 案件フォルダごとに、負担金の記載がある最新の接続検討回答／再接続検討を○とした（保留・中止の案件も含む。連系否の回答は記載の負担金概算で集計）。フォルダ名に「※無効」とある回答は○にしていない

Sheet 要確認
A1: 回答一覧No | B1: 案件名 | C1: ファイル名 | D1: 理由 | E1: 原本リンク
A2: 6 | B2: 0916_島根県浜田市宇野町1819-1他3筆（エクスパワー） | C2: 【秘】接続検討回答書 （G松江320）.pdf | D2: 運開希望日に間に合わず | E2: 開く
A3: 7 | B3: 0916_島根県浜田市宇野町1819-1他3筆（エクスパワー） | C3: 916（エクスパワー）_発電設備等に関する契約申込みお回答について（承諾）_中国電力NW_20260707.pdf | D3: 工期(月)が読めていない | E3: 開く
A4: 10 | B4: 0919_山口県周防大島町久賀2086-4（エクスパワー） | C4: 接続検討回答_#0919_山口県大島郡周防大島町久賀2086-4.pdf | D4: 未読: スキャン画像PDF（約7MB）: read_file_contentでは本文テキスト化されず（グラフ断片のみ）、download_file_contentはMCPセッション切断で2回失敗 / 読取信頼度low | E4: 開く
A5: 11 | B5: 1092_三重県伊勢市特高 | C5: 接続検討回答書【株式会社パワーエックスさま（三重伊勢蓄電所）】.pdf | D5: 運開希望日に間に合わず | E5: 開く
A6: 13 | B6: 1113_茨城県行方市浜1985-1,1985-3,1986-3（合同会社高塚） | C6: 接続検討回答.pdf | D6: 未読: スキャン画像PDF（約7MB）: read_file_contentでは本文テキスト化されず（グラフ断片のみ）、download_file_contentはMCPセッション切断で2回失敗 / 読取信頼度low | E6: 開く
A7: 14 | B7: 00_取り下げ、進行不可/1123_北海道道厚岸郡浜中町姉別南三線(エクスパワー）) | C7: 03_接続検討回答書（約款改訂に係る更新）_【託2024_1167】_1.pdf | D7: 運開希望日に間に合わず | E7: 開く
A8: 16 | B8: 1129_崇徳学園入野グラウンド(大柿産業) | C8: 【秘】接続検討回答書(G東広島654).pdf | D8: 運開希望日に間に合わず | E8: 開く
A9: 18 | B9: 1136_兵庫県高砂市中筋3丁目780番（藤栄建設） | C9: 接続検討申込みに対する回答について.pdf | D9: 運開希望日に間に合わず | E9: 開く
A10: 19 | B10: 1147_愛知県岡崎市板田町東流石（中部産業） | C10: 接続検討回答書（株式会社パワーエックス PX愛知県岡崎市蓄電所）.pdf | D10: 工期と別にバンク/上位系対策待ち | E10: 開く
A11: 21 | B11: 1168_兵庫県高砂市伊保四丁目５１６番 | C11: 接続検討申込に対する回答_兵庫高砂伊保四丁目蓄電所.pdf | D11: 運開希望日に間に合わず | E11: 開く
A12: 22 | B12: 確認要_1169_島根県邑智郡梁瀬（石見簗瀬駅）（JR西日本） | C12: 【秘】接続検討回答書（G松江691） | D12: 運開希望日に間に合わず | E12: 開く
A13: 24 | B13: 確認要_1186_島根県邑智郡石原（沢谷駅）（JR西日本） | C13: 【秘】接続検討回答書（G松江670） | D13: 運開希望日に間に合わず | E13: 開く
... A96: 124 | B96: 【保留】/166_小山町上野277-2（静岡県）_高圧蓄電所 | C96: 概算工期回答書_JK26GHZ057572.pdf | D96: 工期と別にバンク/上位系対策待ち | E96: 開く

Sheet 集計
A1: 負担金帯（税込） | B1: 件数 | C1: 平均工期(月)
A2: 〜500万 | B2: =COUNTIFS('回答一覧'!$R$2:$R$125,A2,'回答一覧'!$AF$2:$AF$125,"○") -> 5 | C2: =IFERROR(AVERAGEIFS('回答一覧'!$U$2:$U$125,'回答一覧'!$R$2:$R$125,A2,'回答一覧'!$AF$2:$AF$125,"○"),"-") -> 11
A3: 500〜1,000万 | B3: =COUNTIFS('回答一覧'!$R$2:$R$125,A3,'回答一覧'!$AF$2:$AF$125,"○") -> 5 | C3: =IFERROR(AVERAGEIFS('回答一覧'!$U$2:$U$125,'回答一覧'!$R$2:$R$125,A3,'回答一覧'!$AF$2:$AF$125,"○"),"-") -> 6.4
A4: 1,000〜3,000万 | B4: =COUNTIFS('回答一覧'!$R$2:$R$125,A4,'回答一覧'!$AF$2:$AF$125,"○") -> 8 | C4: =IFERROR(AVERAGEIFS('回答一覧'!$U$2:$U$125,'回答一覧'!$R$2:$R$125,A4,'回答一覧'!$AF$2:$AF$125,"○"),"-") -> 21.625
A5: 3,000万〜 | B5: =COUNTIFS('回答一覧'!$R$2:$R$125,A5,'回答一覧'!$AF$2:$AF$125,"○") -> 71 | C5: =IFERROR(AVERAGEIFS('回答一覧'!$U$2:$U$125,'回答一覧'!$R$2:$R$125,A5,'回答一覧'!$AF$2:$AF$125,"○"),"-") -> 33.151515
A6: 不明 | B6: =COUNTIFS('回答一覧'!$R$2:$R$125,A6,'回答一覧'!$AF$2:$AF$125,"○") -> 0 | C6: =IFERROR(AVERAGEIFS('回答一覧'!$U$2:$U$125,'回答一覧'!$R$2:$R$125,A6,'回答一覧'!$AF$2:$AF$125,"○"),"-") -> -
A7: 合計 | B7: =SUM(B2:B6) -> 89
A9: 工期帯 | B9: 件数 | C9: 平均負担金(税込・万円)
A10: 〜6ヶ月 | B10: =COUNTIFS('回答一覧'!$V$2:$V$125,A10,'回答一覧'!$AF$2:$AF$125,"○") -> 8 | C10: =IFERROR(AVERAGEIFS('回答一覧'!$Q$2:$Q$125,'回答一覧'!$V$2:$V$125,A10,'回答一覧'!$AF$2:$AF$125,"○"),"-") -> 240790.36
A11: 7〜12ヶ月 | B11: =COUNTIFS('回答一覧'!$V$2:$V$125,A11,'回答一覧'!$AF$2:$AF$125,"○") -> 13 | C11: =IFERROR(AVERAGEIFS('回答一覧'!$Q$2:$Q$125,'回答一覧'!$V$2:$V$125,A11,'回答一覧'!$AF$2:$AF$125,"○"),"-") -> 261140.61
A12: 13〜24ヶ月 | B12: =COUNTIFS('回答一覧'!$V$2:$V$125,A12,'回答一覧'!$AF$2:$AF$125,"○") -> 21 | C12: =IFERROR(AVERAGEIFS('回答一覧'!$Q$2:$Q$125,'回答一覧'!$V$2:$V$125,A12,'回答一覧'!$AF$2:$AF$125,"○"),"-") -> 33185.856
A13: 25ヶ月〜 | B13: =COUNTIFS('回答一覧'!$V$2:$V$125,A13,'回答一覧'!$AF$2:$AF$125,"○") -> 42 | C13: =IFERROR(AVERAGEIFS('回答一覧'!$Q$2:$Q$125,'回答一覧'!$V$2:$V$125,A13,'回答一覧'!$AF$2:$AF$125,"○"),"-") -> 35496.861
A14: 不明 | B14: =COUNTIFS('回答一覧'!$V$2:$V$125,A14,'回答一覧'!$AF$2:$AF$125,"○") -> 5 | C14: =IFERROR(AVERAGEIFS('回答一覧'!$Q$2:$Q$125,'回答一覧'!$V$2:$V$125,A14,'回答一覧'!$AF$2:$AF$125,"○"),"-") -> 260980.14
A16: 電力会社 | B16: 件数 | C16: 平均負担金(税込・万円) | D16: 平均工期(月) | E16: 最大負担金(税込・万円) | F16: 最長工期(月)
