Workbook

Sheet スコアリング
A1: 全国変電所スコアリング（高圧2MW BESS） 黄色=ランクS/A ／ 橙=ゲート該当（上位系0かつN-1不可の警告。ランクは通常算出）
A2: No. | B2: エリア | C2: 変電所名 | D2: 都道府県 | E2: 最大電圧kV | F2: 二次電圧kV | G2: 緯度 | H2: 経度 | I2: 座標精度 | J2: 設備容量MW | K2: 運用容量MW | L2: 予想潮流MW | M2: 空容量_当該MW | N2: 空容量_上位系MW | O2: N-1電制 | P2: 出力制御 | Q2: 所在地(参考) | R2: ゲート | S2: S1空容量(35) | T2: S2 N-1(10) | U2: S3潮流(15) | V2: S4出制(5) | W2: S5配変(10) | X2: S6エリア(5) | Y2: 系統スコア(80) | Z2: ランク | AA2: 実績メモ
A3: 1 | B3: 北海道 | C3: 今別変換所 | D3: 青森県 | E3: 275 | G3: 41.133403 | H3: 140.5138 | I3: OSM実測 | R3: =IF(COUNT($M3:$N3)=0,"",IF(AND(IF($N3<>"",$N3,$M3)<=0,$O3<>"可"),"警告","")) | S3: =IF(COUNT($M3:$N3)=0,0,IF(IF($N3<>"",$N3,$M3)>=スコアリング基準!$B$20,スコアリング基準!$C$20,IF(IF($N3<>"",$N3,$M3)>=スコアリング基準!$B$21,スコアリング基準!$C$21,IF(IF($N3<>"",$N3,$M3)>0,スコアリング基準!$C$22,0)))) | T3: =IF($O3="可",スコアリング基準!$C$23,0) | U3: =IF(OR(COUNT($K3:$L3)<2,$K3=0),0,IF(ABS($L3)/$K3<=スコアリング基準!$B$24,スコアリング基準!$C$24,IF(ABS($L3)/$K3<=スコアリング基準!$B$25,スコアリング基準!$C$25,IF(ABS($L3)/$K3<=スコアリング基準!$B$26,スコアリング基準!$C$26,0)))) | V3: =IF($P3="なし",スコアリング基準!$C$27,0) | W3: =IF($F3="",0,IF(ISNUMBER($F3),IF($F3<=スコアリング基準!$B$28,スコアリング基準!$C$28,スコアリング基準!$C$29),0)) | X3: =IFERROR(VLOOKUP($B3,スコアリング基準!$A$36:$B$46,2,FALSE),0) | Y3: =SUM($S3:$X3) | Z3: =IF(COUNT($M3:$N3)=0,"データ無",IF($Y3>=スコアリング基準!$B$30,"S",IF($Y3>=スコアリング基準!$B$31,"A",IF($Y3>=スコアリング基準!$B$32,"B","C")))) | AA3: =IFERROR(INDEX(実績DB!$I$3:$I$104,MATCH($B3&$C3,実績DB!$J$3:$J$104,0)),"")
A4: 2 | B4: 北海道 | C4: 北斗変換所 | D4: 北海道 | E4: 275 | G4: 41.916295 | H4: 140.58525 | I4: OSM実測 | R4: =IF(COUNT($M4:$N4)=0,"",IF(AND(IF($N4<>"",$N4,$M4)<=0,$O4<>"可"),"警告","")) | S4: =IF(COUNT($M4:$N4)=0,0,IF(IF($N4<>"",$N4,$M4)>=スコアリング基準!$B$20,スコアリング基準!$C$20,IF(IF($N4<>"",$N4,$M4)>=スコアリング基準!$B$21,スコアリング基準!$C$21,IF(IF($N4<>"",$N4,$M4)>0,スコアリング基準!$C$22,0)))) | T4: =IF($O4="可",スコアリング基準!$C$23,0) | U4: =IF(OR(COUNT($K4:$L4)<2,$K4=0),0,IF(ABS($L4)/$K4<=スコアリング基準!$B$24,スコアリング基準!$C$24,IF(ABS($L4)/$K4<=スコアリング基準!$B$25,スコアリング基準!$C$25,IF(ABS($L4)/$K4<=スコアリング基準!$B$26,スコアリング基準!$C$26,0)))) | V4: =IF($P4="なし",スコアリング基準!$C$27,0) | W4: =IF($F4="",0,IF(ISNUMBER($F4),IF($F4<=スコアリング基準!$B$28,スコアリング基準!$C$28,スコアリング基準!$C$29),0)) | X4: =IFERROR(VLOOKUP($B4,スコアリング基準!$A$36:$B$46,2,FALSE),0) | Y4: =SUM($S4:$X4) | Z4: =IF(COUNT($M4:$N4)=0,"データ無",IF($Y4>=スコアリング基準!$B$30,"S",IF($Y4>=スコアリング基準!$B$31,"A",IF($Y4>=スコアリング基準!$B$32,"B","C")))) | AA4: =IFERROR(INDEX(実績DB!$I$3:$I$104,MATCH($B4&$C4,実績DB!$J$3:$J$104,0)),"")
A5: 3 | B5: 北海道 | C5: 北新得変電所 | D5: 北海道 | E5: 275 | F5: 187 | G5: 43.164147 | H5: 142.90436 | I5: OSM実測 | J5: 900 | K5: 450 | L5: -503 | O5: 不可 #1 | P5: 有り | Q5: 北海道新得町 | R5: =IF(COUNT($M5:$N5)=0,"",IF(AND(IF($N5<>"",$N5,$M5)<=0,$O5<>"可"),"警告","")) | S5: =IF(COUNT($M5:$N5)=0,0,IF(IF($N5<>"",$N5,$M5)>=スコアリング基準!$B$20,スコアリング基準!$C$20,IF(IF($N5<>"",$N5,$M5)>=スコアリング基準!$B$21,スコアリング基準!$C$21,IF(IF($N5<>"",$N5,$M5)>0,スコアリング基準!$C$22,0)))) | T5: =IF($O5="可",スコアリング基準!$C$23,0) | U5: =IF(OR(COUNT($K5:$L5)<2,$K5=0),0,IF(ABS($L5)/$K5<=スコアリング基準!$B$24,スコアリング基準!$C$24,IF(ABS($L5)/$K5<=スコアリング基準!$B$25,スコアリング基準!$C$25,IF(ABS($L5)/$K5<=スコアリング基準!$B$26,スコアリング基準!$C$26,0)))) | V5: =IF($P5="なし",スコアリング基準!$C$27,0) | W5: =IF($F5="",0,IF(ISNUMBER($F5),IF($F5<=スコアリング基準!$B$28,スコアリング基準!$C$28,スコアリング基準!$C$29),0)) | X5: =IFERROR(VLOOKUP($B5,スコアリング基準!$A$36:$B$46,2,FALSE),0) | Y5: =SUM($S5:$X5) | Z5: =IF(COUNT($M5:$N5)=0,"データ無",IF($Y5>=スコアリング基準!$B$30,"S",IF($Y5>=スコアリング基準!$B$31,"A",IF($Y5>=スコアリング基準!$B$32,"B","C")))) | AA5: =IFERROR(INDEX(実績DB!$I$3:$I$104,MATCH($B5&$C5,実績DB!$J$3:$J$104,0)),"")
A6: 4 | B6: 北海道 | C6: 北海道電力(株) 大野変電所 | D6: 北海道 | E6: 275 | G6: 41.888382 | H6: 140.60735 | I6: OSM実測 | J6: 900 | K6: 450 | L6: -536 | O6: 不可 #1 | P6: 有り | R6: =IF(COUNT($M6:$N6)=0,"",IF(AND(IF($N6<>"",$N6,$M6)<=0,$O6<>"可"),"警告","")) | S6: =IF(COUNT($M6:$N6)=0,0,IF(IF($N6<>"",$N6,$M6)>=スコアリング基準!$B$20,スコアリング基準!$C$20,IF(IF($N6<>"",$N6,$M6)>=スコアリング基準!$B$21,スコアリング基準!$C$21,IF(IF($N6<>"",$N6,$M6)>0,スコアリング基準!$C$22,0)))) | T6: =IF($O6="可",スコアリング基準!$C$23,0) | U6: =IF(OR(COUNT($K6:$L6)<2,$K6=0),0,IF(ABS($L6)/$K6<=スコアリング基準!$B$24,スコアリング基準!$C$24,IF(ABS($L6)/$K6<=スコアリング基準!$B$25,スコアリング基準!$C$25,IF(ABS($L6)/$K6<=スコアリング基準!$B$26,スコアリング基準!$C$26,0)))) | V6: =IF($P6="なし",スコアリング基準!$C$27,0) | W6: =IF($F6="",0,IF(ISNUMBER($F6),IF($F6<=スコアリング基準!$B$28,スコアリング基準!$C$28,スコアリング基準!$C$29),0)) | X6: =IFERROR(VLOOKUP($B6,スコアリング基準!$A$36:$B$46,2,FALSE),0) | Y6: =SUM($S6:$X6) | Z6: =IF(COUNT($M6:$N6)=0,"データ無",IF($Y6>=スコアリング基準!$B$30,"S",IF($Y6>=スコアリング基準!$B$31,"A",IF($Y6>=スコアリング基準!$B$32,"B","C")))) | AA6: =IFERROR(INDEX(実績DB!$I$3:$I$104,MATCH($B6&$C6,実績DB!$J$3:$J$104,0)),"")
A7: 5 | B7: 北海道 | C7: 南早来変電所① | D7: 北海道 | E7: 275 | F7: 187 | G7: 42.714326 | H7: 141.78053 | I7: OSM実測(名称一致) | J7: 1200 | K7: 600 | L7: 638 | O7: 不可 #1 | P7: 有り | Q7: 北海道安平町 | R7: =IF(COUNT($M7:$N7)=0,"",IF(AND(IF($N7<>"",$N7,$M7)<=0,$O7<>"可"),"警告","")) | S7: =IF(COUNT($M7:$N7)=0,0,IF(IF($N7<>"",$N7,$M7)>=スコアリング基準!$B$20,スコアリング基準!$C$20,IF(IF($N7<>"",$N7,$M7)>=スコアリング基準!$B$21,スコアリング基準!$C$21,IF(IF($N7<>"",$N7,$M7)>0,スコアリング基準!$C$22,0)))) | T7: =IF($O7="可",スコアリング基準!$C$23,0) | U7: =IF(OR(COUNT($K7:$L7)<2,$K7=0),0,IF(ABS($L7)/$K7<=スコアリング基準!$B$24,スコアリング基準!$C$24,IF(ABS($L7)/$K7<=スコアリング基準!$B$25,スコアリング基準!$C$25,IF(ABS($L7)/$K7<=スコアリング基準!$B$26,スコアリング基準!$C$26,0)))) | V7: =IF($P7="なし",スコアリング基準!$C$27,0) | W7: =IF($F7="",0,IF(ISNUMBER($F7),IF($F7<=スコアリング基準!$B$28,スコアリング基準!$C$28,スコアリング基準!$C$29),0)) | X7: =IFERROR(VLOOKUP($B7,スコアリング基準!$A$36:$B$46,2,FALSE),0) | Y7: =SUM($S7:$X7) | Z7: =IF(COUNT($M7:$N7)=0,"データ無",IF($Y7>=スコアリング基準!$B$30,"S",IF($Y7>=スコアリング基準!$B$31,"A",IF($Y7>=スコアリング基準!$B$32,"B","C")))) | AA7: =IFERROR(INDEX(実績DB!$I$3:$I$104,MATCH($B7&$C7,実績DB!$J$3:$J$104,0)),"")
A8: 6 | B8: 北海道 | C8: 大野変電所① | D8: 北海道 | E8: 275 | F8: 187 | G8: 41.888382 | H8: 140.60735 | I8: OSM実測(名称一致) | J8: 900 | K8: 450 | L8: -536 | O8: 不可 #1 | P8: 有り | Q8: 北海道北斗市 | R8: =IF(COUNT($M8:$N8)=0,"",IF(AND(IF($N8<>"",$N8,$M8)<=0,$O8<>"可"),"警告","")) | S8: =IF(COUNT($M8:$N8)=0,0,IF(IF($N8<>"",$N8,$M8)>=スコアリング基準!$B$20,スコアリング基準!$C$20,IF(IF($N8<>"",$N8,$M8)>=スコアリング基準!$B$21,スコアリング基準!$C$21,IF(IF($N8<>"",$N8,$M8)>0,スコアリング基準!$C$22,0)))) | T8: =IF($O8="可",スコアリング基準!$C$23,0) | U8: =IF(OR(COUNT($K8:$L8)<2,$K8=0),0,IF(ABS($L8)/$K8<=スコアリング基準!$B$24,スコアリング基準!$C$24,IF(ABS($L8)/$K8<=スコアリング基準!$B$25,スコアリング基準!$C$25,IF(ABS($L8)/$K8<=スコアリング基準!$B$26,スコアリング基準!$C$26,0)))) | V8: =IF($P8="なし",スコアリング基準!$C$27,0) | W8: =IF($F8="",0,IF(ISNUMBER($F8),IF($F8<=スコアリング基準!$B$28,スコアリング基準!$C$28,スコアリング基準!$C$29),0)) | X8: =IFERROR(VLOOKUP($B8,スコアリング基準!$A$36:$B$46,2,FALSE),0) | Y8: =SUM($S8:$X8) | Z8: =IF(COUNT($M8:$N8)=0,"データ無",IF($Y8>=スコアリング基準!$B$30,"S",IF($Y8>=スコアリング基準!$B$31,"A",IF($Y8>=スコアリング基準!$B$32,"B","C")))) | AA8: =IFERROR(INDEX(実績DB!$I$3:$I$104,MATCH($B8&$C8,実績DB!$J$3:$J$104,0)),"")
A9: 7 | B9: 北海道 | C9: 泊変電所 | D9: 北海道 | E9: 275 | G9: 43.039555 | H9: 140.51623 | I9: OSM実測 | R9: =IF(COUNT($M9:$N9)=0,"",IF(AND(IF($N9<>"",$N9,$M9)<=0,$O9<>"可"),"警告","")) | S9: =IF(COUNT($M9:$N9)=0,0,IF(IF($N9<>"",$N9,$M9)>=スコアリング基準!$B$20,スコアリング基準!$C$20,IF(IF($N9<>"",$N9,$M9)>=スコアリング基準!$B$21,スコアリング基準!$C$21,IF(IF($N9<>"",$N9,$M9)>0,スコアリング基準!$C$22,0)))) | T9: =IF($O9="可",スコアリング基準!$C$23,0) | U9: =IF(OR(COUNT($K9:$L9)<2,$K9=0),0,IF(ABS($L9)/$K9<=スコアリング基準!$B$24,スコアリング基準!$C$24,IF(ABS($L9)/$K9<=スコアリング基準!$B$25,スコアリング基準!$C$25,IF(ABS($L9)/$K9<=スコアリング基準!$B$26,スコアリング基準!$C$26,0)))) | V9: =IF($P9="なし",スコアリング基準!$C$27,0) | W9: =IF($F9="",0,IF(ISNUMBER($F9),IF($F9<=スコアリング基準!$B$28,スコアリング基準!$C$28,スコアリング基準!$C$29),0)) | X9: =IFERROR(VLOOKUP($B9,スコアリング基準!$A$36:$B$46,2,FALSE),0) | Y9: =SUM($S9:$X9) | Z9: =IF(COUNT($M9:$N9)=0,"データ無",IF($Y9>=スコアリング基準!$B$30,"S",IF($Y9>=スコアリング基準!$B$31,"A",IF($Y9>=スコアリング基準!$B$32,"B","C")))) | AA9: =IFERROR(INDEX(実績DB!$I$3:$I$104,MATCH($B9&$C9,実績DB!$J$3:$J$104,0)),"")
A10: 8 | B10: 北海道 | C10: 石狩湾新港発電所 | D10: 北海道 | E10: 275 | G10: 43.191869 | H10: 141.27664 | I10: OSM実測 | R10: =IF(COUNT($M10:$N10)=0,"",IF(AND(IF($N10<>"",$N10,$M10)<=0,$O10<>"可"),"警告","")) | S10: =IF(COUNT($M10:$N10)=0,0,IF(IF($N10<>"",$N10,$M10)>=スコアリング基準!$B$20,スコアリング基準!$C$20,IF(IF($N10<>"",$N10,$M10)>=スコアリング基準!$B$21,スコアリング基準!$C$21,IF(IF($N10<>"",$N10,$M10)>0,スコアリング基準!$C$22,0)))) | T10: =IF($O10="可",スコアリング基準!$C$23,0) | U10: =IF(OR(COUNT($K10:$L10)<2,$K10=0),0,IF(ABS($L10)/$K10<=スコアリング基準!$B$24,スコアリング基準!$C$24,IF(ABS($L10)/$K10<=スコアリング基準!$B$25,スコアリング基準!$C$25,IF(ABS($L10)/$K10<=スコアリング基準!$B$26,スコアリング基準!$C$26,0)))) | V10: =IF($P10="なし",スコアリング基準!$C$27,0) | W10: =IF($F10="",0,IF(ISNUMBER($F10),IF($F10<=スコアリング基準!$B$28,スコアリング基準!$C$28,スコアリング基準!$C$29),0)) | X10: =IFERROR(VLOOKUP($B10,スコアリング基準!$A$36:$B$46,2,FALSE),0) | Y10: =SUM($S10:$X10) | Z10: =IF(COUNT($M10:$N10)=0,"データ無",IF($Y10>=スコアリング基準!$B$30,"S",IF($Y10>=スコアリング基準!$B$31,"A",IF($Y10>=スコアリング基準!$B$32,"B","C")))) | AA10: =IFERROR(INDEX(実績DB!$I$3:$I$104,MATCH($B10&$C10,実績DB!$J$3:$J$104,0)),"")
A11: 9 | B11: 北海道 | C11: 西双葉開閉所 | D11: 北海道 | E11: 275 | G11: 42.749341 | H11: 141.03533 | I11: OSM実測 | R11: =IF(COUNT($M11:$N11)=0,"",IF(AND(IF($N11<>"",$N11,$M11)<=0,$O11<>"可"),"警告","")) | S11: =IF(COUNT($M11:$N11)=0,0,IF(IF($N11<>"",$N11,$M11)>=スコアリング基準!$B$20,スコアリング基準!$C$20,IF(IF($N11<>"",$N11,$M11)>=スコアリング基準!$B$21,スコアリング基準!$C$21,IF(IF($N11<>"",$N11,$M11)>0,スコアリング基準!$C$22,0)))) | T11: =IF($O11="可",スコアリング基準!$C$23,0) | U11: =IF(OR(COUNT($K11:$L11)<2,$K11=0),0,IF(ABS($L11)/$K11<=スコアリング基準!$B$24,スコアリング基準!$C$24,IF(ABS($L11)/$K11<=スコアリング基準!$B$25,スコアリング基準!$C$25,IF(ABS($L11)/$K11<=スコアリング基準!$B$26,スコアリング基準!$C$26,0)))) | V11: =IF($P11="なし",スコアリング基準!$C$27,0) | W11: =IF($F11="",0,IF(ISNUMBER($F11),IF($F11<=スコアリング基準!$B$28,スコアリング基準!$C$28,スコアリング基準!$C$29),0)) | X11: =IFERROR(VLOOKUP($B11,スコアリング基準!$A$36:$B$46,2,FALSE),0) | Y11: =SUM($S11:$X11) | Z11: =IF(COUNT($M11:$N11)=0,"データ無",IF($Y11>=スコアリング基準!$B$30,"S",IF($Y11>=スコアリング基準!$B$31,"A",IF($Y11>=スコアリング基準!$B$32,"B","C")))) | AA11: =IFERROR(INDEX(実績DB!$I$3:$I$104,MATCH($B11&$C11,実績DB!$J$3:$J$104,0)),"")
A12: 10 | B12: 北海道 | C12: 西当別変電所 | D12: 北海道 | E12: 275 | F12: 187 | G12: 43.234251 | H12: 141.45127 | I12: OSM実測 | J12: 1800 | K12: 1200 | L12: 1177 | O12: 不可 #1 | P12: なし | Q12: 北海道当別町 | R12: =IF(COUNT($M12:$N12)=0,"",IF(AND(IF($N12<>"",$N12,$M12)<=0,$O12<>"可"),"警告","")) | S12: =IF(COUNT($M12:$N12)=0,0,IF(IF($N12<>"",$N12,$M12)>=スコアリング基準!$B$20,スコアリング基準!$C$20,IF(IF($N12<>"",$N12,$M12)>=スコアリング基準!$B$21,スコアリング基準!$C$21,IF(IF($N12<>"",$N12,$M12)>0,スコアリング基準!$C$22,0)))) | T12: =IF($O12="可",スコアリング基準!$C$23,0) | U12: =IF(OR(COUNT($K12:$L12)<2,$K12=0),0,IF(ABS($L12)/$K12<=スコアリング基準!$B$24,スコアリング基準!$C$24,IF(ABS($L12)/$K12<=スコアリング基準!$B$25,スコアリング基準!$C$25,IF(ABS($L12)/$K12<=スコアリング基準!$B$26,スコアリング基準!$C$26,0)))) | V12: =IF($P12="なし",スコアリング基準!$C$27,0) | W12: =IF($F12="",0,IF(ISNUMBER($F12),IF($F12<=スコアリング基準!$B$28,スコアリング基準!$C$28,スコアリング基準!$C$29),0)) | X12: =IFERROR(VLOOKUP($B12,スコアリング基準!$A$36:$B$46,2,FALSE),0) | Y12: =SUM($S12:$X12) | Z12: =IF(COUNT($M12:$N12)=0,"データ無",IF($Y12>=スコアリング基準!$B$30,"S",IF($Y12>=スコアリング基準!$B$31,"A",IF($Y12>=スコアリング基準!$B$32,"B","C")))) | AA12: =IFERROR(INDEX(実績DB!$I$3:$I$104,MATCH($B12&$C12,実績DB!$J$3:$J$104,0)),"")
A13: 11 | B13: 北海道 | C13: 西野変電所 | D13: 北海道 | E13: 275 | F13: 187 | G13: 43.05722 | H13: 141.22255 | I13: OSM実測 | J13: 1800 | K13: 1200 | L13: 1022 | O13: 不可 #1 | P13: なし | Q13: 北海道札幌市西区 | R13: =IF(COUNT($M13:$N13)=0,"",IF(AND(IF($N13<>"",$N13,$M13)<=0,$O13<>"可"),"警告","")) | S13: =IF(COUNT($M13:$N13)=0,0,IF(IF($N13<>"",$N13,$M13)>=スコアリング基準!$B$20,スコアリング基準!$C$20,IF(IF($N13<>"",$N13,$M13)>=スコアリング基準!$B$21,スコアリング基準!$C$21,IF(IF($N13<>"",$N13,$M13)>0,スコアリング基準!$C$22,0)))) | T13: =IF($O13="可",スコアリング基準!$C$23,0) | U13: =IF(OR(COUNT($K13:$L13)<2,$K13=0),0,IF(ABS($L13)/$K13<=スコアリング基準!$B$24,スコアリング基準!$C$24,IF(ABS($L13)/$K13<=スコアリング基準!$B$25,スコアリング基準!$C$25,IF(ABS($L13)/$K13<=スコアリング基準!$B$26,スコアリング基準!$C$26,0)))) | V13: =IF($P13="なし",スコアリング基準!$C$27,0) | W13: =IF($F13="",0,IF(ISNUMBER($F13),IF($F13<=スコアリング基準!$B$28,スコアリング基準!$C$28,スコアリング基準!$C$29),0)) | X13: =IFERROR(VLOOKUP($B13,スコアリング基準!$A$36:$B$46,2,FALSE),0) | Y13: =SUM($S13:$X13) | Z13: =IF(COUNT($M13:$N13)=0,"データ無",IF($Y13>=スコアリング基準!$B$30,"S",IF($Y13>=スコアリング基準!$B$31,"A",IF($Y13>=スコアリング基準!$B$32,"B","C")))) | AA13: =IFERROR(INDEX(実績DB!$I$3:$I$104,MATCH($B13&$C13,実績DB!$J$3:$J$104,0)),"")
A14: 12 | B14: 北海道 | C14: 吉岡ケーブルヘッド | D14: 北海道 | E14: 250 | G14: 41.441719 | H14: 140.23466 | I14: OSM実測 | R14: =IF(COUNT($M14:$N14)=0,"",IF(AND(IF($N14<>"",$N14,$M14)<=0,$O14<>"可"),"警告","")) | S14: =IF(COUNT($M14:$N14)=0,0,IF(IF($N14<>"",$N14,$M14)>=スコアリング基準!$B$20,スコアリング基準!$C$20,IF(IF($N14<>"",$N14,$M14)>=スコアリング基準!$B$21,スコアリング基準!$C$21,IF(IF($N14<>"",$N14,$M14)>0,スコアリング基準!$C$22,0)))) | T14: =IF($O14="可",スコアリング基準!$C$23,0) | U14: =IF(OR(COUNT($K14:$L14)<2,$K14=0),0,IF(ABS($L14)/$K14<=スコアリング基準!$B$24,スコアリング基準!$C$24,IF(ABS($L14)/$K14<=スコアリング基準!$B$25,スコアリング基準!$C$25,IF(ABS($L14)/$K14<=スコアリング基準!$B$26,スコアリング基準!$C$26,0)))) | V14: =IF($P14="なし",スコアリング基準!$C$27,0) | W14: =IF($F14="",0,IF(ISNUMBER($F14),IF($F14<=スコアリング基準!$B$28,スコアリング基準!$C$28,スコアリング基準!$C$29),0)) | X14: =IFERROR(VLOOKUP($B14,スコアリング基準!$A$36:$B$46,2,FALSE),0) | Y14: =SUM($S14:$X14) | Z14: =IF(COUNT($M14:$N14)=0,"データ無",IF($Y14>=スコアリング基準!$B$30,"S",IF($Y14>=スコアリング基準!$B$31,"A",IF($Y14>=スコアリング基準!$B$32,"B","C")))) | AA14: =IFERROR(INDEX(実績DB!$I$3:$I$104,MATCH($B14&$C14,実績DB!$J$3:$J$104,0)),"")
A15: 13 | B15: 北海道 | C15: 竜飛ケーブルヘッド | D15: 青森県 | E15: 250 | G15: 41.252366 | H15: 140.34658 | I15: OSM実測 | R15: =IF(COUNT($M15:$N15)=0,"",IF(AND(IF($N15<>"",$N15,$M15)<=0,$O15<>"可"),"警告","")) | S15: =IF(COUNT($M15:$N15)=0,0,IF(IF($N15<>"",$N15,$M15)>=スコアリング基準!$B$20,スコアリング基準!$C$20,IF(IF($N15<>"",$N15,$M15)>=スコアリング基準!$B$21,スコアリング基準!$C$21,IF(IF($N15<>"",$N15,$M15)>0,スコアリング基準!$C$22,0)))) | T15: =IF($O15="可",スコアリング基準!$C$23,0) | U15: =IF(OR(COUNT($K15:$L15)<2,$K15=0),0,IF(ABS($L15)/$K15<=スコアリング基準!$B$24,スコアリング基準!$C$24,IF(ABS($L15)/$K15<=スコアリング基準!$B$25,スコアリング基準!$C$25,IF(ABS($L15)/$K15<=スコアリング基準!$B$26,スコアリング基準!$C$26,0)))) | V15: =IF($P15="なし",スコアリング基準!$C$27,0) | W15: =IF($F15="",0,IF(ISNUMBER($F15),IF($F15<=スコアリング基準!$B$28,スコアリング基準!$C$28,スコアリング基準!$C$29),0)) | X15: =IFERROR(VLOOKUP($B15,スコアリング基準!$A$36:$B$46,2,FALSE),0) | Y15: =SUM($S15:$X15) | Z15: =IF(COUNT($M15:$N15)=0,"データ無",IF($Y15>=スコアリング基準!$B$30,"S",IF($Y15>=スコアリング基準!$B$31,"A",IF($Y15>=スコアリング基準!$B$32,"B","C")))) | AA15: =IFERROR(INDEX(実績DB!$I$3:$I$104,MATCH($B15&$C15,実績DB!$J$3:$J$104,0)),"")
A16: 14 | B16: 北海道 | C16: 七飯発電所 | D16: 北海道 | E16: 187 | G16: 41.931997 | H16: 140.65452 | I16: OSM実測 | R16: =IF(COUNT($M16:$N16)=0,"",IF(AND(IF($N16<>"",$N16,$M16)<=0,$O16<>"可"),"警告","")) | S16: =IF(COUNT($M16:$N16)=0,0,IF(IF($N16<>"",$N16,$M16)>=スコアリング基準!$B$20,スコアリング基準!$C$20,IF(IF($N16<>"",$N16,$M16)>=スコアリング基準!$B$21,スコアリング基準!$C$21,IF(IF($N16<>"",$N16,$M16)>0,スコアリング基準!$C$22,0)))) | T16: =IF($O16="可",スコアリング基準!$C$23,0) | U16: =IF(OR(COUNT($K16:$L16)<2,$K16=0),0,IF(ABS($L16)/$K16<=スコアリング基準!$B$24,スコアリング基準!$C$24,IF(ABS($L16)/$K16<=スコアリング基準!$B$25,スコアリング基準!$C$25,IF(ABS($L16)/$K16<=スコアリング基準!$B$26,スコアリング基準!$C$26,0)))) | V16: =IF($P16="なし",スコアリング基準!$C$27,0) | W16: =IF($F16="",0,IF(ISNUMBER($F16),IF($F16<=スコアリング基準!$B$28,スコアリング基準!$C$28,スコアリング基準!$C$29),0)) | X16: =IFERROR(VLOOKUP($B16,スコアリング基準!$A$36:$B$46,2,FALSE),0) | Y16: =SUM($S16:$X16) | Z16: =IF(COUNT($M16:$N16)=0,"データ無",IF($Y16>=スコアリング基準!$B$30,"S",IF($Y16>=スコアリング基準!$B$31,"A",IF($Y16>=スコアリング基準!$B$32,"B","C")))) | AA16: =IFERROR(INDEX(実績DB!$I$3:$I$104,MATCH($B16&$C16,実績DB!$J$3:$J$104,0)),"")
A17: 15 | B17: 北海道 | C17: 北七飯変電所 | D17: 北海道 | E17: 187 | F17: 66 | G17: 41.932291 | H17: 140.65711 | I17: OSM実測(名称一致) | J17: 300 | K17: 195 | L17: -184 | O17: 不可 #1 | P17: 有り | Q17: 北海道七飯町 | R17: =IF(COUNT($M17:$N17)=0,"",IF(AND(IF($N17<>"",$N17,$M17)<=0,$O17<>"可"),"警告","")) | S17: =IF(COUNT($M17:$N17)=0,0,IF(IF($N17<>"",$N17,$M17)>=スコアリング基準!$B$20,スコアリング基準!$C$20,IF(IF($N17<>"",$N17,$M17)>=スコアリング基準!$B$21,スコアリング基準!$C$21,IF(IF($N17<>"",$N17,$M17)>0,スコアリング基準!$C$22,0)))) | T17: =IF($O17="可",スコアリング基準!$C$23,0) | U17: =IF(OR(COUNT($K17:$L17)<2,$K17=0),0,IF(ABS($L17)/$K17<=スコアリング基準!$B$24,スコアリング基準!$C$24,IF(ABS($L17)/$K17<=スコアリング基準!$B$25,スコアリング基準!$C$25,IF(ABS($L17)/$K17<=スコアリング基準!$B$26,スコアリング基準!$C$26,0)))) | V17: =IF($P17="なし",スコアリング基準!$C$27,0) | W17: =IF($F17="",0,IF(ISNUMBER($F17),IF($F17<=スコアリング基準!$B$28,スコアリング基準!$C$28,スコアリング基準!$C$29),0)) | X17: =IFERROR(VLOOKUP($B17,スコアリング基準!$A$36:$B$46,2,FALSE),0) | Y17: =SUM($S17:$X17) | Z17: =IF(COUNT($M17:$N17)=0,"データ無",IF($Y17>=スコアリング基準!$B$30,"S",IF($Y17>=スコアリング基準!$B$31,"A",IF($Y17>=スコアリング基準!$B$32,"B","C")))) | AA17: =IFERROR(INDEX(実績DB!$I$3:$I$104,MATCH($B17&$C17,実績DB!$J$3:$J$104,0)),"")
A18: 16 | B18: 北海道 | C18: 北江別変電所 | D18: 北海道 | E18: 187 | F18: 66 | G18: 43.120728 | H18: 141.53453 | I18: OSM実測 | J18: 350 | K18: 197 | L18: -263 | O18: 可 | P18: 有り | Q18: 北海道江別市 | R18: =IF(COUNT($M18:$N18)=0,"",IF(AND(IF($N18<>"",$N18,$M18)<=0,$O18<>"可"),"警告","")) | S18: =IF(COUNT($M18:$N18)=0,0,IF(IF($N18<>"",$N18,$M18)>=スコアリング基準!$B$20,スコアリング基準!$C$20,IF(IF($N18<>"",$N18,$M18)>=スコアリング基準!$B$21,スコアリング基準!$C$21,IF(IF($N18<>"",$N18,$M18)>0,スコアリング基準!$C$22,0)))) | T18: =IF($O18="可",スコアリング基準!$C$23,0) | U18: =IF(OR(COUNT($K18:$L18)<2,$K18=0),0,IF(ABS($L18)/$K18<=スコアリング基準!$B$24,スコアリング基準!$C$24,IF(ABS($L18)/$K18<=スコアリング基準!$B$25,スコアリング基準!$C$25,IF(ABS($L18)/$K18<=スコアリング基準!$B$26,スコアリング基準!$C$26,0)))) | V18: =IF($P18="なし",スコアリング基準!$C$27,0) | W18: =IF($F18="",0,IF(ISNUMBER($F18),IF($F18<=スコアリング基準!$B$28,スコアリング基準!$C$28,スコアリング基準!$C$29),0)) | X18: =IFERROR(VLOOKUP($B18,スコアリング基準!$A$36:$B$46,2,FALSE),0) | Y18: =SUM($S18:$X18) | Z18: =IF(COUNT($M18:$N18)=0,"データ無",IF($Y18>=スコアリング基準!$B$30,"S",IF($Y18>=スコアリング基準!$B$31,"A",IF($Y18>=スコアリング基準!$B$32,"B","C")))) | AA18: =IFERROR(INDEX(実績DB!$I$3:$I$104,MATCH($B18&$C18,実績DB!$J$3:$J$104,0)),"")
A19: 17 | B19: 北海道 | C19: 北海道北部風力送電㈱ 北豊富変電所 | D19: 北海道 | E19: 187 | G19: 45.196211 | H19: 141.79538 | I19: OSM実測 | R19: =IF(COUNT($M19:$N19)=0,"",IF(AND(IF($N19<>"",$N19,$M19)<=0,$O19<>"可"),"警告","")) | S19: =IF(COUNT($M19:$N19)=0,0,IF(IF($N19<>"",$N19,$M19)>=スコアリング基準!$B$20,スコアリング基準!$C$20,IF(IF($N19<>"",$N19,$M19)>=スコアリング基準!$B$21,スコアリング基準!$C$21,IF(IF($N19<>"",$N19,$M19)>0,スコアリング基準!$C$22,0)))) | T19: =IF($O19="可",スコアリング基準!$C$23,0) | U19: =IF(OR(COUNT($K19:$L19)<2,$K19=0),0,IF(ABS($L19)/$K19<=スコアリング基準!$B$24,スコアリング基準!$C$24,IF(ABS($L19)/$K19<=スコアリング基準!$B$25,スコアリング基準!$C$25,IF(ABS($L19)/$K19<=スコアリング基準!$B$26,スコアリング基準!$C$26,0)))) | V19: =IF($P19="なし",スコアリング基準!$C$27,0) | W19: =IF($F19="",0,IF(ISNUMBER($F19),IF($F19<=スコアリング基準!$B$28,スコアリング基準!$C$28,スコアリング基準!$C$29),0)) | X19: =IFERROR(VLOOKUP($B19,スコアリング基準!$A$36:$B$46,2,FALSE),0) | Y19: =SUM($S19:$X19) | Z19: =IF(COUNT($M19:$N19)=0,"データ無",IF($Y19>=スコアリング基準!$B$30,"S",IF($Y19>=スコアリング基準!$B$31,"A",IF($Y19>=スコアリング基準!$B$32,"B","C")))) | AA19: =IFERROR(INDEX(実績DB!$I$3:$I$104,MATCH($B19&$C19,実績DB!$J$3:$J$104,0)),"")
A20: 18 | B20: 北海道 | C20: 北海道電力 総合研究所 | D20: 北海道 | E20: 187 | G20: 43.120027 | H20: 141.5375 | I20: OSM実測 | R20: =IF(COUNT($M20:$N20)=0,"",IF(AND(IF($N20<>"",$N20,$M20)<=0,$O20<>"可"),"警告","")) | S20: =IF(COUNT($M20:$N20)=0,0,IF(IF($N20<>"",$N20,$M20)>=スコアリング基準!$B$20,スコアリング基準!$C$20,IF(IF($N20<>"",$N20,$M20)>=スコアリング基準!$B$21,スコアリング基準!$C$21,IF(IF($N20<>"",$N20,$M20)>0,スコアリング基準!$C$22,0)))) | T20: =IF($O20="可",スコアリング基準!$C$23,0) | U20: =IF(OR(COUNT($K20:$L20)<2,$K20=0),0,IF(ABS($L20)/$K20<=スコアリング基準!$B$24,スコアリング基準!$C$24,IF(ABS($L20)/$K20<=スコアリング基準!$B$25,スコアリング基準!$C$25,IF(ABS($L20)/$K20<=スコアリング基準!$B$26,スコアリング基準!$C$26,0)))) | V20: =IF($P20="なし",スコアリング基準!$C$27,0) | W20: =IF($F20="",0,IF(ISNUMBER($F20),IF($F20<=スコアリング基準!$B$28,スコアリング基準!$C$28,スコアリング基準!$C$29),0)) | X20: =IFERROR(VLOOKUP($B20,スコアリング基準!$A$36:$B$46,2,FALSE),0) | Y20: =SUM($S20:$X20) | Z20: =IF(COUNT($M20:$N20)=0,"データ無",IF($Y20>=スコアリング基準!$B$30,"S",IF($Y20>=スコアリング基準!$B$31,"A",IF($Y20>=スコアリング基準!$B$32,"B","C")))) | AA20: =IFERROR(INDEX(実績DB!$I$3:$I$104,MATCH($B20&$C20,実績DB!$J$3:$J$104,0)),"")
A21: 19 | B21: 北海道 | C21: 北芽室変電所 | D21: 北海道 | E21: 187 | F21: 66 | G21: 42.92133 | H21: 143.03358 | I21: OSM実測 | J21: 310 | K21: 158 | L21: -185 | O21: 可 | P21: 有り | Q21: 北海道芽室町 | R21: =IF(COUNT($M21:$N21)=0,"",IF(AND(IF($N21<>"",$N21,$M21)<=0,$O21<>"可"),"警告","")) | S21: =IF(COUNT($M21:$N21)=0,0,IF(IF($N21<>"",$N21,$M21)>=スコアリング基準!$B$20,スコアリング基準!$C$20,IF(IF($N21<>"",$N21,$M21)>=スコアリング基準!$B$21,スコアリング基準!$C$21,IF(IF($N21<>"",$N21,$M21)>0,スコアリング基準!$C$22,0)))) | T21: =IF($O21="可",スコアリング基準!$C$23,0) | U21: =IF(OR(COUNT($K21:$L21)<2,$K21=0),0,IF(ABS($L21)/$K21<=スコアリング基準!$B$24,スコアリング基準!$C$24,IF(ABS($L21)/$K21<=スコアリング基準!$B$25,スコアリング基準!$C$25,IF(ABS($L21)/$K21<=スコアリング基準!$B$26,スコアリング基準!$C$26,0)))) | V21: =IF($P21="なし",スコアリング基準!$C$27,0) | W21: =IF($F21="",0,IF(ISNUMBER($F21),IF($F21<=スコアリング基準!$B$28,スコアリング基準!$C$28,スコアリング基準!$C$29),0)) | X21: =IFERROR(VLOOKUP($B21,スコアリング基準!$A$36:$B$46,2,FALSE),0) | Y21: =SUM($S21:$X21) | Z21: =IF(COUNT($M21:$N21)=0,"データ無",IF($Y21>=スコアリング基準!$B$30,"S",IF($Y21>=スコアリング基準!$B$31,"A",IF($Y21>=スコアリング基準!$B$32,"B","C")))) | AA21: =IFERROR(INDEX(実績DB!$I$3:$I$104,MATCH($B21&$C21,実績DB!$J$3:$J$104,0)),"")
A22: 20 | B22: 北海道 | C22: 北静内変電所 | D22: 北海道 | E22: 187 | F22: 66 | G22: 42.35 | H22: 142.37 | I22: 推定 | J22: 120 | K22: 60 | L22: -152 | O22: 不可 #5 | P22: 有り | Q22: 北海道新ひだか町静内 | R22: =IF(COUNT($M22:$N22)=0,"",IF(AND(IF($N22<>"",$N22,$M22)<=0,$O22<>"可"),"警告","")) | S22: =IF(COUNT($M22:$N22)=0,0,IF(IF($N22<>"",$N22,$M22)>=スコアリング基準!$B$20,スコアリング基準!$C$20,IF(IF($N22<>"",$N22,$M22)>=スコアリング基準!$B$21,スコアリング基準!$C$21,IF(IF($N22<>"",$N22,$M22)>0,スコアリング基準!$C$22,0)))) | T22: =IF($O22="可",スコアリング基準!$C$23,0) | U22: =IF(OR(COUNT($K22:$L22)<2,$K22=0),0,IF(ABS($L22)/$K22<=スコアリング基準!$B$24,スコアリング基準!$C$24,IF(ABS($L22)/$K22<=スコアリング基準!$B$25,スコアリング基準!$C$25,IF(ABS($L22)/$K22<=スコアリング基準!$B$26,スコアリング基準!$C$26,0)))) | V22: =IF($P22="なし",スコアリング基準!$C$27,0) | W22: =IF($F22="",0,IF(ISNUMBER($F22),IF($F22<=スコアリング基準!$B$28,スコアリング基準!$C$28,スコアリング基準!$C$29),0)) | X22: =IFERROR(VLOOKUP($B22,スコアリング基準!$A$36:$B$46,2,FALSE),0) | Y22: =SUM($S22:$X22) | Z22: =IF(COUNT($M22:$N22)=0,"データ無",IF($Y22>=スコアリング基準!$B$30,"S",IF($Y22>=スコアリング基準!$B$31,"A",IF($Y22>=スコアリング基準!$B$32,"B","C")))) | AA22: =IFERROR(INDEX(実績DB!$I$3:$I$104,MATCH($B22&$C22,実績DB!$J$3:$J$104,0)),"")
A23: 21 | B23: 北海道 | C23: 南九条変電所 | D23: 北海道 | E23: 187 | F23: 66 | G23: 43.046 | H23: 141.37 | I23: 推定 | J23: 450 | K23: 299 | L23: 121 | O23: 可 | P23: なし | Q23: 北海道札幌市豊平区 | R23: =IF(COUNT($M23:$N23)=0,"",IF(AND(IF($N23<>"",$N23,$M23)<=0,$O23<>"可"),"警告","")) | S23: =IF(COUNT($M23:$N23)=0,0,IF(IF($N23<>"",$N23,$M23)>=スコアリング基準!$B$20,スコアリング基準!$C$20,IF(IF($N23<>"",$N23,$M23)>=スコアリング基準!$B$21,スコアリング基準!$C$21,IF(IF($N23<>"",$N23,$M23)>0,スコアリング基準!$C$22,0)))) | T23: =IF($O23="可",スコアリング基準!$C$23,0) | U23: =IF(OR(COUNT($K23:$L23)<2,$K23=0),0,IF(ABS($L23)/$K23<=スコアリング基準!$B$24,スコアリング基準!$C$24,IF(ABS($L23)/$K23<=スコアリング基準!$B$25,スコアリング基準!$C$25,IF(ABS($L23)/$K23<=スコアリング基準!$B$26,スコアリング基準!$C$26,0)))) | V23: =IF($P23="なし",スコアリング基準!$C$27,0) | W23: =IF($F23="",0,IF(ISNUMBER($F23),IF($F23<=スコアリング基準!$B$28,スコアリング基準!$C$28,スコアリング基準!$C$29),0)) | X23: =IFERROR(VLOOKUP($B23,スコアリング基準!$A$36:$B$46,2,FALSE),0) | Y23: =SUM($S23:$X23) | Z23: =IF(COUNT($M23:$N23)=0,"データ無",IF($Y23>=スコアリング基準!$B$30,"S",IF($Y23>=スコアリング基準!$B$31,"A",IF($Y23>=スコアリング基準!$B$32,"B","C")))) | AA23: =IFERROR(INDEX(実績DB!$I$3:$I$104,MATCH($B23&$C23,実績DB!$J$3:$J$104,0)),"")
A24: 22 | B24: 北海道 | C24: 南札幌変電所 | D24: 北海道 | E24: 187 | F24: 66 | G24: 43.022335 | H24: 141.41853 | I24: OSM実測(名称一致) | J24: 600 | K24: 389 | L24: 10 | O24: 可 | P24: なし | Q24: 北海道札幌市南区 | R24: =IF(COUNT($M24:$N24)=0,"",IF(AND(IF($N24<>"",$N24,$M24)<=0,$O24<>"可"),"警告","")) | S24: =IF(COUNT($M24:$N24)=0,0,IF(IF($N24<>"",$N24,$M24)>=スコアリング基準!$B$20,スコアリング基準!$C$20,IF(IF($N24<>"",$N24,$M24)>=スコアリング基準!$B$21,スコアリング基準!$C$21,IF(IF($N24<>"",$N24,$M24)>0,スコアリング基準!$C$22,0)))) | T24: =IF($O24="可",スコアリング基準!$C$23,0) | U24: =IF(OR(COUNT($K24:$L24)<2,$K24=0),0,IF(ABS($L24)/$K24<=スコアリング基準!$B$24,スコアリング基準!$C$24,IF(ABS($L24)/$K24<=スコアリング基準!$B$25,スコアリング基準!$C$25,IF(ABS($L24)/$K24<=スコアリング基準!$B$26,スコアリング基準!$C$26,0)))) | V24: =IF($P24="なし",スコアリング基準!$C$27,0) | W24: =IF($F24="",0,IF(ISNUMBER($F24),IF($F24<=スコアリング基準!$B$28,スコアリング基準!$C$28,スコアリング基準!$C$29),0)) | X24: =IFERROR(VLOOKUP($B24,スコアリング基準!$A$36:$B$46,2,FALSE),0) | Y24: =SUM($S24:$X24) | Z24: =IF(COUNT($M24:$N24)=0,"データ無",IF($Y24>=スコアリング基準!$B$30,"S",IF($Y24>=スコアリング基準!$B$31,"A",IF($Y24>=スコアリング基準!$B$32,"B","C")))) | AA24: =IFERROR(INDEX(実績DB!$I$3:$I$104,MATCH($B24&$C24,実績DB!$J$3:$J$104,0)),"")
A25: 23 | B25: 北海道 | C25: 双葉開閉所 | D25: 北海道 | E25: 187 | G25: 42.743148 | H25: 141.03404 | I25: OSM実測 | R25: =IF(COUNT($M25:$N25)=0,"",IF(AND(IF($N25<>"",$N25,$M25)<=0,$O25<>"可"),"警告","")) | S25: =IF(COUNT($M25:$N25)=0,0,IF(IF($N25<>"",$N25,$M25)>=スコアリング基準!$B$20,スコアリング基準!$C$20,IF(IF($N25<>"",$N25,$M25)>=スコアリング基準!$B$21,スコアリング基準!$C$21,IF(IF($N25<>"",$N25,$M25)>0,スコアリング基準!$C$22,0)))) | T25: =IF($O25="可",スコアリング基準!$C$23,0) | U25: =IF(OR(COUNT($K25:$L25)<2,$K25=0),0,IF(ABS($L25)/$K25<=スコアリング基準!$B$24,スコアリング基準!$C$24,IF(ABS($L25)/$K25<=スコアリング基準!$B$25,スコアリング基準!$C$25,IF(ABS($L25)/$K25<=スコアリング基準!$B$26,スコアリング基準!$C$26,0)))) | V25: =IF($P25="なし",スコアリング基準!$C$27,0) | W25: =IF($F25="",0,IF(ISNUMBER($F25),IF($F25<=スコアリング基準!$B$28,スコアリング基準!$C$28,スコアリング基準!$C$29),0)) | X25: =IFERROR(VLOOKUP($B25,スコアリング基準!$A$36:$B$46,2,FALSE),0) | Y25: =SUM($S25:$X25) | Z25: =IF(COUNT($M25:$N25)=0,"データ無",IF($Y25>=スコアリング基準!$B$30,"S",IF($Y25>=スコアリング基準!$B$31,"A",IF($Y25>=スコアリング基準!$B$32,"B","C")))) | AA25: =IFERROR(INDEX(実績DB!$I$3:$I$104,MATCH($B25&$C25,実績DB!$J$3:$J$104,0)),"")
A26: 24 | B26: 北海道 | C26: 女満別変電所 | D26: 北海道 | E26: 187 | F26: 66 | G26: 43.832103 | H26: 144.21691 | I26: OSM実測(名称一致) | J26: 200 | K26: 100 | L26: -179 | O26: 可 | P26: 有り | Q26: 北海道大空町女満別 | R26: =IF(COUNT($M26:$N26)=0,"",IF(AND(IF($N26<>"",$N26,$M26)<=0,$O26<>"可"),"警告","")) | S26: =IF(COUNT($M26:$N26)=0,0,IF(IF($N26<>"",$N26,$M26)>=スコアリング基準!$B$20,スコアリング基準!$C$20,IF(IF($N26<>"",$N26,$M26)>=スコアリング基準!$B$21,スコアリング基準!$C$21,IF(IF($N26<>"",$N26,$M26)>0,スコアリング基準!$C$22,0)))) | T26: =IF($O26="可",スコアリング基準!$C$23,0) | U26: =IF(OR(COUNT($K26:$L26)<2,$K26=0),0,IF(ABS($L26)/$K26<=スコアリング基準!$B$24,スコアリング基準!$C$24,IF(ABS($L26)/$K26<=スコアリング基準!$B$25,スコアリング基準!$C$25,IF(ABS($L26)/$K26<=スコアリング基準!$B$26,スコアリング基準!$C$26,0)))) | V26: =IF($P26="なし",スコアリング基準!$C$27,0) | W26: =IF($F26="",0,IF(ISNUMBER($F26),IF($F26<=スコアリング基準!$B$28,スコアリング基準!$C$28,スコアリング基準!$C$29),0)) | X26: =IFERROR(VLOOKUP($B26,スコアリング基準!$A$36:$B$46,2,FALSE),0) | Y26: =SUM($S26:$X26) | Z26: =IF(COUNT($M26:$N26)=0,"データ無",IF($Y26>=スコアリング基準!$B$30,"S",IF($Y26>=スコアリング基準!$B$31,"A",IF($Y26>=スコアリング基準!$B$32,"B","C")))) | AA26: =IFERROR(INDEX(実績DB!$I$3:$I$104,MATCH($B26&$C26,実績DB!$J$3:$J$104,0)),"")
A27: 25 | B27: 北海道 | C27: 宇円別変電所 | D27: 北海道 | E27: 187 | F27: 66 | G27: 43.077642 | H27: 144.15521 | I27: OSM実測 | J27: 275 | K27: 153 | L27: -418 | O27: 可 | P27: 有り | Q27: 北海道釧路市（標茶近郊） | R27: =IF(COUNT($M27:$N27)=0,"",IF(AND(IF($N27<>"",$N27,$M27)<=0,$O27<>"可"),"警告","")) | S27: =IF(COUNT($M27:$N27)=0,0,IF(IF($N27<>"",$N27,$M27)>=スコアリング基準!$B$20,スコアリング基準!$C$20,IF(IF($N27<>"",$N27,$M27)>=スコアリング基準!$B$21,スコアリング基準!$C$21,IF(IF($N27<>"",$N27,$M27)>0,スコアリング基準!$C$22,0)))) | T27: =IF($O27="可",スコアリング基準!$C$23,0) | U27: =IF(OR(COUNT($K27:$L27)<2,$K27=0),0,IF(ABS($L27)/$K27<=スコアリング基準!$B$24,スコアリング基準!$C$24,IF(ABS($L27)/$K27<=スコアリング基準!$B$25,スコアリング基準!$C$25,IF(ABS($L27)/$K27<=スコアリング基準!$B$26,スコアリング基準!$C$26,0)))) | V27: =IF($P27="なし",スコアリング基準!$C$27,0) | W27: =IF($F27="",0,IF(ISNUMBER($F27),IF($F27<=スコアリング基準!$B$28,スコアリング基準!$C$28,スコアリング基準!$C$29),0)) | X27: =IFERROR(VLOOKUP($B27,スコアリング基準!$A$36:$B$46,2,FALSE),0) | Y27: =SUM($S27:$X27) | Z27: =IF(COUNT($M27:$N27)=0,"データ無",IF($Y27>=スコアリング基準!$B$30,"S",IF($Y27>=スコアリング基準!$B$31,"A",IF($Y27>=スコアリング基準!$B$32,"B","C")))) | AA27: =IFERROR(INDEX(実績DB!$I$3:$I$104,MATCH($B27&$C27,実績DB!$J$3:$J$104,0)),"")
A28: 26 | B28: 北海道 | C28: 室蘭変電所 | D28: 北海道 | E28: 187 | F28: 66 | G28: 42.372421 | H28: 141.03307 | I28: OSM実測 | J28: 300 | K28: 150 | L28: -268 | O28: 可 | P28: 有り | Q28: 北海道室蘭市 | R28: =IF(COUNT($M28:$N28)=0,"",IF(AND(IF($N28<>"",$N28,$M28)<=0,$O28<>"可"),"警告","")) | S28: =IF(COUNT($M28:$N28)=0,0,IF(IF($N28<>"",$N28,$M28)>=スコアリング基準!$B$20,スコアリング基準!$C$20,IF(IF($N28<>"",$N28,$M28)>=スコアリング基準!$B$21,スコアリング基準!$C$21,IF(IF($N28<>"",$N28,$M28)>0,スコアリング基準!$C$22,0)))) | T28: =IF($O28="可",スコアリング基準!$C$23,0) | U28: =IF(OR(COUNT($K28:$L28)<2,$K28=0),0,IF(ABS($L28)/$K28<=スコアリング基準!$B$24,スコアリング基準!$C$24,IF(ABS($L28)/$K28<=スコアリング基準!$B$25,スコアリング基準!$C$25,IF(ABS($L28)/$K28<=スコアリング基準!$B$26,スコアリング基準!$C$26,0)))) | V28: =IF($P28="なし",スコアリング基準!$C$27,0) | W28: =IF($F28="",0,IF(ISNUMBER($F28),IF($F28<=スコアリング基準!$B$28,スコアリング基準!$C$28,スコアリング基準!$C$29),0)) | X28: =IFERROR(VLOOKUP($B28,スコアリング基準!$A$36:$B$46,2,FALSE),0) | Y28: =SUM($S28:$X28) | Z28: =IF(COUNT($M28:$N28)=0,"データ無",IF($Y28>=スコアリング基準!$B$30,"S",IF($Y28>=スコアリング基準!$B$31,"A",IF($Y28>=スコアリング基準!$B$32,"B","C")))) | AA28: =IFERROR(INDEX(実績DB!$I$3:$I$104,MATCH($B28&$C28,実績DB!$J$3:$J$104,0)),"")
A29: 27 | B29: 北海道 | C29: 岩清水開閉所 | D29: 北海道 | E29: 187 | G29: 42.510487 | H29: 142.51781 | I29: OSM実測 | R29: =IF(COUNT($M29:$N29)=0,"",IF(AND(IF($N29<>"",$N29,$M29)<=0,$O29<>"可"),"警告","")) | S29: =IF(COUNT($M29:$N29)=0,0,IF(IF($N29<>"",$N29,$M29)>=スコアリング基準!$B$20,スコアリング基準!$C$20,IF(IF($N29<>"",$N29,$M29)>=スコアリング基準!$B$21,スコアリング基準!$C$21,IF(IF($N29<>"",$N29,$M29)>0,スコアリング基準!$C$22,0)))) | T29: =IF($O29="可",スコアリング基準!$C$23,0) | U29: =IF(OR(COUNT($K29:$L29)<2,$K29=0),0,IF(ABS($L29)/$K29<=スコアリング基準!$B$24,スコアリング基準!$C$24,IF(ABS($L29)/$K29<=スコアリング基準!$B$25,スコアリング基準!$C$25,IF(ABS($L29)/$K29<=スコアリング基準!$B$26,スコアリング基準!$C$26,0)))) | V29: =IF($P29="なし",スコアリング基準!$C$27,0) | W29: =IF($F29="",0,IF(ISNUMBER($F29),IF($F29<=スコアリング基準!$B$28,スコアリング基準!$C$28,スコアリング基準!$C$29),0)) | X29: =IFERROR(VLOOKUP($B29,スコアリング基準!$A$36:$B$46,2,FALSE),0) | Y29: =SUM($S29:$X29) | Z29: =IF(COUNT($M29:$N29)=0,"データ無",IF($Y29>=スコアリング基準!$B$30,"S",IF($Y29>=スコアリング基準!$B$31,"A",IF($Y29>=スコアリング基準!$B$32,"B","C")))) | AA29: =IFERROR(INDEX(実績DB!$I$3:$I$104,MATCH($B29&$C29,実績DB!$J$3:$J$104,0)),"")
A30: 28 | B30: 北海道 | C30: 恵庭変電所 | D30: 北海道 | E30: 187 | F30: 66 | G30: 42.931477 | H30: 141.60195 | I30: OSM実測(名称一致) | J30: 500 | K30: 299 | L30: -249 | O30: 可 | P30: なし | Q30: 北海道恵庭市 | R30: =IF(COUNT($M30:$N30)=0,"",IF(AND(IF($N30<>"",$N30,$M30)<=0,$O30<>"可"),"警告","")) | S30: =IF(COUNT($M30:$N30)=0,0,IF(IF($N30<>"",$N30,$M30)>=スコアリング基準!$B$20,スコアリング基準!$C$20,IF(IF($N30<>"",$N30,$M30)>=スコアリング基準!$B$21,スコアリング基準!$C$21,IF(IF($N30<>"",$N30,$M30)>0,スコアリング基準!$C$22,0)))) | T30: =IF($O30="可",スコアリング基準!$C$23,0) | U30: =IF(OR(COUNT($K30:$L30)<2,$K30=0),0,IF(ABS($L30)/$K30<=スコアリング基準!$B$24,スコアリング基準!$C$24,IF(ABS($L30)/$K30<=スコアリング基準!$B$25,スコアリング基準!$C$25,IF(ABS($L30)/$K30<=スコアリング基準!$B$26,スコアリング基準!$C$26,0)))) | V30: =IF($P30="なし",スコアリング基準!$C$27,0) | W30: =IF($F30="",0,IF(ISNUMBER($F30),IF($F30<=スコアリング基準!$B$28,スコアリング基準!$C$28,スコアリング基準!$C$29),0)) | X30: =IFERROR(VLOOKUP($B30,スコアリング基準!$A$36:$B$46,2,FALSE),0) | Y30: =SUM($S30:$X30) | Z30: =IF(COUNT($M30:$N30)=0,"データ無",IF($Y30>=スコアリング基準!$B$30,"S",IF($Y30>=スコアリング基準!$B$31,"A",IF($Y30>=スコアリング基準!$B$32,"B","C")))) | AA30: =IFERROR(INDEX(実績DB!$I$3:$I$104,MATCH($B30&$C30,実績DB!$J$3:$J$104,0)),"")
A31: 29 | B31: 北海道 | C31: 新冠開閉所 | D31: 北海道 | E31: 187 | G31: 42.599765 | H31: 142.54786 | I31: OSM実測 | R31: =IF(COUNT($M31:$N31)=0,"",IF(AND(IF($N31<>"",$N31,$M31)<=0,$O31<>"可"),"警告","")) | S31: =IF(COUNT($M31:$N31)=0,0,IF(IF($N31<>"",$N31,$M31)>=スコアリング基準!$B$20,スコアリング基準!$C$20,IF(IF($N31<>"",$N31,$M31)>=スコアリング基準!$B$21,スコアリング基準!$C$21,IF(IF($N31<>"",$N31,$M31)>0,スコアリング基準!$C$22,0)))) | T31: =IF($O31="可",スコアリング基準!$C$23,0) | U31: =IF(OR(COUNT($K31:$L31)<2,$K31=0),0,IF(ABS($L31)/$K31<=スコアリング基準!$B$24,スコアリング基準!$C$24,IF(ABS($L31)/$K31<=スコアリング基準!$B$25,スコアリング基準!$C$25,IF(ABS($L31)/$K31<=スコアリング基準!$B$26,スコアリング基準!$C$26,0)))) | V31: =IF($P31="なし",スコアリング基準!$C$27,0) | W31: =IF($F31="",0,IF(ISNUMBER($F31),IF($F31<=スコアリング基準!$B$28,スコアリング基準!$C$28,スコアリング基準!$C$29),0)) | X31: =IFERROR(VLOOKUP($B31,スコアリング基準!$A$36:$B$46,2,FALSE),0) | Y31: =SUM($S31:$X31) | Z31: =IF(COUNT($M31:$N31)=0,"データ無",IF($Y31>=スコアリング基準!$B$30,"S",IF($Y31>=スコアリング基準!$B$31,"A",IF($Y31>=スコアリング基準!$B$32,"B","C")))) | AA31: =IFERROR(INDEX(実績DB!$I$3:$I$104,MATCH($B31&$C31,実績DB!$J$3:$J$104,0)),"")
A32: 30 | B32: 北海道 | C32: 旭川変電所 | D32: 北海道 | E32: 187 | F32: 66 | G32: 43.753355 | H32: 142.38782 | I32: OSM実測(名称一致) | J32: 300 | K32: 150 | L32: -60 | O32: 可 | P32: 有り | Q32: 北海道旭川市 | R32: =IF(COUNT($M32:$N32)=0,"",IF(AND(IF($N32<>"",$N32,$M32)<=0,$O32<>"可"),"警告","")) | S32: =IF(COUNT($M32:$N32)=0,0,IF(IF($N32<>"",$N32,$M32)>=スコアリング基準!$B$20,スコアリング基準!$C$20,IF(IF($N32<>"",$N32,$M32)>=スコアリング基準!$B$21,スコアリング基準!$C$21,IF(IF($N32<>"",$N32,$M32)>0,スコアリング基準!$C$22,0)))) | T32: =IF($O32="可",スコアリング基準!$C$23,0) | U32: =IF(OR(COUNT($K32:$L32)<2,$K32=0),0,IF(ABS($L32)/$K32<=スコアリング基準!$B$24,スコアリング基準!$C$24,IF(ABS($L32)/$K32<=スコアリング基準!$B$25,スコアリング基準!$C$25,IF(ABS($L32)/$K32<=スコアリング基準!$B$26,スコアリング基準!$C$26,0)))) | V32: =IF($P32="なし",スコアリング基準!$C$27,0) | W32: =IF($F32="",0,IF(ISNUMBER($F32),IF($F32<=スコアリング基準!$B$28,スコアリング基準!$C$28,スコアリング基準!$C$29),0)) | X32: =IFERROR(VLOOKUP($B32,スコアリング基準!$A$36:$B$46,2,FALSE),0) | Y32: =SUM($S32:$X32) | Z32: =IF(COUNT($M32:$N32)=0,"データ無",IF($Y32>=スコアリング基準!$B$30,"S",IF($Y32>=スコアリング基準!$B$31,"A",IF($Y32>=スコアリング基準!$B$32,"B","C")))) | AA32: =IFERROR(INDEX(実績DB!$I$3:$I$104,MATCH($B32&$C32,実績DB!$J$3:$J$104,0)),"")
A33: 31 | B33: 北海道 | C33: 旭川嵐山開閉所 | D33: 北海道 | E33: 187 | G33: 43.815396 | H33: 142.28055 | I33: OSM実測 | R33: =IF(COUNT($M33:$N33)=0,"",IF(AND(IF($N33<>"",$N33,$M33)<=0,$O33<>"可"),"警告","")) | S33: =IF(COUNT($M33:$N33)=0,0,IF(IF($N33<>"",$N33,$M33)>=スコアリング基準!$B$20,スコアリング基準!$C$20,IF(IF($N33<>"",$N33,$M33)>=スコアリング基準!$B$21,スコアリング基準!$C$21,IF(IF($N33<>"",$N33,$M33)>0,スコアリング基準!$C$22,0)))) | T33: =IF($O33="可",スコアリング基準!$C$23,0) | U33: =IF(OR(COUNT($K33:$L33)<2,$K33=0),0,IF(ABS($L33)/$K33<=スコアリング基準!$B$24,スコアリング基準!$C$24,IF(ABS($L33)/$K33<=スコアリング基準!$B$25,スコアリング基準!$C$25,IF(ABS($L33)/$K33<=スコアリング基準!$B$26,スコアリング基準!$C$26,0)))) | V33: =IF($P33="なし",スコアリング基準!$C$27,0) | W33: =IF($F33="",0,IF(ISNUMBER($F33),IF($F33<=スコアリング基準!$B$28,スコアリング基準!$C$28,スコアリング基準!$C$29),0)) | X33: =IFERROR(VLOOKUP($B33,スコアリング基準!$A$36:$B$46,2,FALSE),0) | Y33: =SUM($S33:$X33) | Z33: =IF(COUNT($M33:$N33)=0,"データ無",IF($Y33>=スコアリング基準!$B$30,"S",IF($Y33>=スコアリング基準!$B$31,"A",IF($Y33>=スコアリング基準!$B$32,"B","C")))) | AA33: =IFERROR(INDEX(実績DB!$I$3:$I$104,MATCH($B33&$C33,実績DB!$J$3:$J$104,0)),"")
A34: 32 | B34: 北海道 | C34: 東苫小牧変電所 | D34: 北海道 | E34: 187 | F34: 66 | G34: 42.65 | H34: 141.62 | I34: 推定 | J34: 200 | K34: 100 | L34: -108 | O34: 不可 #1 | P34: 有り | Q34: 北海道苫小牧市東部 | R34: =IF(COUNT($M34:$N34)=0,"",IF(AND(IF($N34<>"",$N34,$M34)<=0,$O34<>"可"),"警告","")) | S34: =IF(COUNT($M34:$N34)=0,0,IF(IF($N34<>"",$N34,$M34)>=スコアリング基準!$B$20,スコアリング基準!$C$20,IF(IF($N34<>"",$N34,$M34)>=スコアリング基準!$B$21,スコアリング基準!$C$21,IF(IF($N34<>"",$N34,$M34)>0,スコアリング基準!$C$22,0)))) | T34: =IF($O34="可",スコアリング基準!$C$23,0) | U34: =IF(OR(COUNT($K34:$L34)<2,$K34=0),0,IF(ABS($L34)/$K34<=スコアリング基準!$B$24,スコアリング基準!$C$24,IF(ABS($L34)/$K34<=スコアリング基準!$B$25,スコアリング基準!$C$25,IF(ABS($L34)/$K34<=スコアリング基準!$B$26,スコアリング基準!$C$26,0)))) | V34: =IF($P34="なし",スコアリング基準!$C$27,0) | W34: =IF($F34="",0,IF(ISNUMBER($F34),IF($F34<=スコアリング基準!$B$28,スコアリング基準!$C$28,スコアリング基準!$C$29),0)) | X34: =IFERROR(VLOOKUP($B34,スコアリング基準!$A$36:$B$46,2,FALSE),0) | Y34: =SUM($S34:$X34) | Z34: =IF(COUNT($M34:$N34)=0,"データ無",IF($Y34>=スコアリング基準!$B$30,"S",IF($Y34>=スコアリング基準!$B$31,"A",IF($Y34>=スコアリング基準!$B$32,"B","C")))) | AA34: =IFERROR(INDEX(実績DB!$I$3:$I$104,MATCH($B34&$C34,実績DB!$J$3:$J$104,0)),"")
A35: 33 | B35: 北海道 | C35: 東釧路変電所 | D35: 北海道 | E35: 187 | F35: 66 | G35: 43.010707 | H35: 144.44655 | I35: OSM実測 | J35: 300 | K35: 198 | L35: -474 | O35: 可 | P35: 有り | Q35: 北海道釧路市東部 | R35: =IF(COUNT($M35:$N35)=0,"",IF(AND(IF($N35<>"",$N35,$M35)<=0,$O35<>"可"),"警告","")) | S35: =IF(COUNT($M35:$N35)=0,0,IF(IF($N35<>"",$N35,$M35)>=スコアリング基準!$B$20,スコアリング基準!$C$20,IF(IF($N35<>"",$N35,$M35)>=スコアリング基準!$B$21,スコアリング基準!$C$21,IF(IF($N35<>"",$N35,$M35)>0,スコアリング基準!$C$22,0)))) | T35: =IF($O35="可",スコアリング基準!$C$23,0) | U35: =IF(OR(COUNT($K35:$L35)<2,$K35=0),0,IF(ABS($L35)/$K35<=スコアリング基準!$B$24,スコアリング基準!$C$24,IF(ABS($L35)/$K35<=スコアリング基準!$B$25,スコアリング基準!$C$25,IF(ABS($L35)/$K35<=スコアリング基準!$B$26,スコアリング基準!$C$26,0)))) | V35: =IF($P35="なし",スコアリング基準!$C$27,0) | W35: =IF($F35="",0,IF(ISNUMBER($F35),IF($F35<=スコアリング基準!$B$28,スコアリング基準!$C$28,スコアリング基準!$C$29),0)) | X35: =IFERROR(VLOOKUP($B35,スコアリング基準!$A$36:$B$46,2,FALSE),0) | Y35: =SUM($S35:$X35) | Z35: =IF(COUNT($M35:$N35)=0,"データ無",IF($Y35>=スコアリング基準!$B$30,"S",IF($Y35>=スコアリング基準!$B$31,"A",IF($Y35>=スコアリング基準!$B$32,"B","C")))) | AA35: =IFERROR(INDEX(実績DB!$I$3:$I$104,MATCH($B35&$C35,実績DB!$J$3:$J$104,0)),"")
A36: 34 | B36: 北海道 | C36: 留辺蘂変電所 | D36: 北海道 | E36: 187 | F36: 66 | G36: 43.77543 | H36: 143.60053 | I36: OSM実測 | J36: 300 | K36: 198 | L36: -331 | O36: 可 | P36: 有り | Q36: 北海道北見市留辺蘂 | R36: =IF(COUNT($M36:$N36)=0,"",IF(AND(IF($N36<>"",$N36,$M36)<=0,$O36<>"可"),"警告","")) | S36: =IF(COUNT($M36:$N36)=0,0,IF(IF($N36<>"",$N36,$M36)>=スコアリング基準!$B$20,スコアリング基準!$C$20,IF(IF($N36<>"",$N36,$M36)>=スコアリング基準!$B$21,スコアリング基準!$C$21,IF(IF($N36<>"",$N36,$M36)>0,スコアリング基準!$C$22,0)))) | T36: =IF($O36="可",スコアリング基準!$C$23,0) | U36: =IF(OR(COUNT($K36:$L36)<2,$K36=0),0,IF(ABS($L36)/$K36<=スコアリング基準!$B$24,スコアリング基準!$C$24,IF(ABS($L36)/$K36<=スコアリング基準!$B$25,スコアリング基準!$C$25,IF(ABS($L36)/$K36<=スコアリング基準!$B$26,スコアリング基準!$C$26,0)))) | V36: =IF($P36="なし",スコアリング基準!$C$27,0) | W36: =IF($F36="",0,IF(ISNUMBER($F36),IF($F36<=スコアリング基準!$B$28,スコアリング基準!$C$28,スコアリング基準!$C$29),0)) | X36: =IFERROR(VLOOKUP($B36,スコアリング基準!$A$36:$B$46,2,FALSE),0) | Y36: =SUM($S36:$X36) | Z36: =IF(COUNT($M36:$N36)=0,"データ無",IF($Y36>=スコアリング基準!$B$30,"S",IF($Y36>=スコアリング基準!$B$31,"A",IF($Y36>=スコアリング基準!$B$32,"B","C")))) | AA36: =IFERROR(INDEX(実績DB!$I$3:$I$104,MATCH($B36&$C36,実績DB!$J$3:$J$104,0)),"")
A37: 35 | B37: 北海道 | C37: 篠路変電所 | D37: 北海道 | E37: 187 | F37: 66 | G37: 43.138575 | H37: 141.37443 | I37: OSM実測(名称一致) | J37: 400 | K37: 200 | L37: 82 | O37: 可 | P37: なし | Q37: 北海道札幌市北区 | R37: =IF(COUNT($M37:$N37)=0,"",IF(AND(IF($N37<>"",$N37,$M37)<=0,$O37<>"可"),"警告","")) | S37: =IF(COUNT($M37:$N37)=0,0,IF(IF($N37<>"",$N37,$M37)>=スコアリング基準!$B$20,スコアリング基準!$C$20,IF(IF($N37<>"",$N37,$M37)>=スコアリング基準!$B$21,スコアリング基準!$C$21,IF(IF($N37<>"",$N37,$M37)>0,スコアリング基準!$C$22,0)))) | T37: =IF($O37="可",スコアリング基準!$C$23,0) | U37: =IF(OR(COUNT($K37:$L37)<2,$K37=0),0,IF(ABS($L37)/$K37<=スコアリング基準!$B$24,スコアリング基準!$C$24,IF(ABS($L37)/$K37<=スコアリング基準!$B$25,スコアリング基準!$C$25,IF(ABS($L37)/$K37<=スコアリング基準!$B$26,スコアリング基準!$C$26,0)))) | V37: =IF($P37="なし",スコアリング基準!$C$27,0) | W37: =IF($F37="",0,IF(ISNUMBER($F37),IF($F37<=スコアリング基準!$B$28,スコアリング基準!$C$28,スコアリング基準!$C$29),0)) | X37: =IFERROR(VLOOKUP($B37,スコアリング基準!$A$36:$B$46,2,FALSE),0) | Y37: =SUM($S37:$X37) | Z37: =IF(COUNT($M37:$N37)=0,"データ無",IF($Y37>=スコアリング基準!$B$30,"S",IF($Y37>=スコアリング基準!$B$31,"A",IF($Y37>=スコアリング基準!$B$32,"B","C")))) | AA37: =IFERROR(INDEX(実績DB!$I$3:$I$104,MATCH($B37&$C37,実績DB!$J$3:$J$104,0)),"")
A38: 36 | B38: 北海道 | C38: 苗穂変電所 | D38: 北海道 | E38: 187 | F38: 66 | G38: 43.092594 | H38: 141.40321 | I38: OSM実測 | J38: 600 | K38: 398 | L38: 81 | O38: 可 | P38: なし | Q38: 北海道札幌市東区 | R38: =IF(COUNT($M38:$N38)=0,"",IF(AND(IF($N38<>"",$N38,$M38)<=0,$O38<>"可"),"警告","")) | S38: =IF(COUNT($M38:$N38)=0,0,IF(IF($N38<>"",$N38,$M38)>=スコアリング基準!$B$20,スコアリング基準!$C$20,IF(IF($N38<>"",$N38,$M38)>=スコアリング基準!$B$21,スコアリング基準!$C$21,IF(IF($N38<>"",$N38,$M38)>0,スコアリング基準!$C$22,0)))) | T38: =IF($O38="可",スコアリング基準!$C$23,0) | U38: =IF(OR(COUNT($K38:$L38)<2,$K38=0),0,IF(ABS($L38)/$K38<=スコアリング基準!$B$24,スコアリング基準!$C$24,IF(ABS($L38)/$K38<=スコアリング基準!$B$25,スコアリング基準!$C$25,IF(ABS($L38)/$K38<=スコアリング基準!$B$26,スコアリング基準!$C$26,0)))) | V38: =IF($P38="なし",スコアリング基準!$C$27,0) | W38: =IF($F38="",0,IF(ISNUMBER($F38),IF($F38<=スコアリング基準!$B$28,スコアリング基準!$C$28,スコアリング基準!$C$29),0)) | X38: =IFERROR(VLOOKUP($B38,スコアリング基準!$A$36:$B$46,2,FALSE),0) | Y38: =SUM($S38:$X38) | Z38: =IF(COUNT($M38:$N38)=0,"データ無",IF($Y38>=スコアリング基準!$B$30,"S",IF($Y38>=スコアリング基準!$B$31,"A",IF($Y38>=スコアリング基準!$B$32,"B","C")))) | AA38: =IFERROR(INDEX(実績DB!$I$3:$I$104,MATCH($B38&$C38,実績DB!$J$3:$J$104,0)),"")
A39: 37 | B39: 北海道 | C39: 苫小牧変電所 | D39: 北海道 | E39: 187 | F39: 66 | G39: 42.634946 | H39: 141.55665 | I39: OSM実測 | J39: 350 | K39: 199 | L39: -305 | O39: 可 | P39: 有り | Q39: 北海道苫小牧市 | R39: =IF(COUNT($M39:$N39)=0,"",IF(AND(IF($N39<>"",$N39,$M39)<=0,$O39<>"可"),"警告","")) | S39: =IF(COUNT($M39:$N39)=0,0,IF(IF($N39<>"",$N39,$M39)>=スコアリング基準!$B$20,スコアリング基準!$C$20,IF(IF($N39<>"",$N39,$M39)>=スコアリング基準!$B$21,スコアリング基準!$C$21,IF(IF($N39<>"",$N39,$M39)>0,スコアリング基準!$C$22,0)))) | T39: =IF($O39="可",スコアリング基準!$C$23,0) | U39: =IF(OR(COUNT($K39:$L39)<2,$K39=0),0,IF(ABS($L39)/$K39<=スコアリング基準!$B$24,スコアリング基準!$C$24,IF(ABS($L39)/$K39<=スコアリング基準!$B$25,スコアリング基準!$C$25,IF(ABS($L39)/$K39<=スコアリング基準!$B$26,スコアリング基準!$C$26,0)))) | V39: =IF($P39="なし",スコアリング基準!$C$27,0) | W39: =IF($F39="",0,IF(ISNUMBER($F39),IF($F39<=スコアリング基準!$B$28,スコアリング基準!$C$28,スコアリング基準!$C$29),0)) | X39: =IFERROR(VLOOKUP($B39,スコアリング基準!$A$36:$B$46,2,FALSE),0) | Y39: =SUM($S39:$X39) | Z39: =IF(COUNT($M39:$N39)=0,"データ無",IF($Y39>=スコアリング基準!$B$30,"S",IF($Y39>=スコアリング基準!$B$31,"A",IF($Y39>=スコアリング基準!$B$32,"B","C")))) | AA39: =IFERROR(INDEX(実績DB!$I$3:$I$104,MATCH($B39&$C39,実績DB!$J$3:$J$104,0)),"")
A40: 38 | B40: 北海道 | C40: 西中川変電所 | D40: 北海道 | E40: 187 | F40: 100 | G40: 44.831234 | H40: 142.03421 | I40: OSM実測(名称一致) | J40: 200 | K40: 100 | L40: -160 | O40: 不可 #3、#5 | P40: 有り | Q40: 北海道中川町 | R40: =IF(COUNT($M40:$N40)=0,"",IF(AND(IF($N40<>"",$N40,$M40)<=0,$O40<>"可"),"警告","")) | S40: =IF(COUNT($M40:$N40)=0,0,IF(IF($N40<>"",$N40,$M40)>=スコアリング基準!$B$20,スコアリング基準!$C$20,IF(IF($N40<>"",$N40,$M40)>=スコアリング基準!$B$21,スコアリング基準!$C$21,IF(IF($N40<>"",$N40,$M40)>0,スコアリング基準!$C$22,0)))) | T40: =IF($O40="可",スコアリング基準!$C$23,0) | U40: =IF(OR(COUNT($K40:$L40)<2,$K40=0),0,IF(ABS($L40)/$K40<=スコアリング基準!$B$24,スコアリング基準!$C$24,IF(ABS($L40)/$K40<=スコアリング基準!$B$25,スコアリング基準!$C$25,IF(ABS($L40)/$K40<=スコアリング基準!$B$26,スコアリング基準!$C$26,0)))) | V40: =IF($P40="なし",スコアリング基準!$C$27,0) | W40: =IF($F40="",0,IF(ISNUMBER($F40),IF($F40<=スコアリング基準!$B$28,スコアリング基準!$C$28,スコアリング基準!$C$29),0)) | X40: =IFERROR(VLOOKUP($B40,スコアリング基準!$A$36:$B$46,2,FALSE),0) | Y40: =SUM($S40:$X40) | Z40: =IF(COUNT($M40:$N40)=0,"データ無",IF($Y40>=スコアリング基準!$B$30,"S",IF($Y40>=スコアリング基準!$B$31,"A",IF($Y40>=スコアリング基準!$B$32,"B","C")))) | AA40: =IFERROR(INDEX(実績DB!$I$3:$I$104,MATCH($B40&$C40,実績DB!$J$3:$J$104,0)),"")
...

Sheet スコアリング基準
A1: 変電所スコアリング基準（系統用蓄電池・高圧2MW前提）v1
A2: 作成: 2026-07-28 ｜ 接続検討の実回答12件の分析から逆算した配点で「接続検討を申し込む価値」を点数化する（実績DBは19件・2026-08-06更新。配点は19件ベースの分析でも変更なしを確認）
A4: 変数・配点定義（実績12件で校正）
A5: 記号 | B5: 変数 | C5: 配点 | D5: 閾値・ルール | E5: 根拠(実績)
A6: G1 | B6: ゲート: 上位系0（警告） | C6: 警告 | D6: 空容量(上位系考慮)≦0 かつ N-1電制≠可 → ⚠警告（ランクは通常算出。S1=0でB以下） | E6: 喜多方: 上位系増強で工期10年2ヶ月／由仁: 上位系0でも410万・6ヶ月で連系（2026-10-20に除外→警告）
A7: G2 | B7: ゲート: 募集プロセス/増強エリア | C7: 除外(手動) | D7: 各社公表資料で該当時に手動除外 | E7: 高額・長納期化リスク
A8: S1 | B8: 空容量(上位系考慮) | C8: 35 | D8: ≧20MW(2MWの10倍):35 / ≧6MW:28 / >0:15 / ≦0:0 | E8: 最重要。上位系増強の回避確率
A9: S2 | B9: N-1電制 可否 | C9: 10 | D9: 可:10 / それ以外:0 | E9: 空容量ゼロでも接続余地
A10: S3 | B10: 予想潮流の余裕(|潮流|/運用容量) | C10: 15 | D10: ≦30%:15 / ≦60%:9 / ≦90%:4 / >90%:0 | E10: 混雑度=出力制御・増強リスク
A11: S4 | B11: 出力制御可能性 | C11: 5 | D11: なし:5 / 有り:0 | E11: 収益影響(九州で頻発)
A12: S5 | B12: 配電用変電所か(二次電圧) | C12: 10 | D12: 二次≦7kV(6.6/6.0):10 / その他数値:5 / 不明:0 | E12: 高圧2MW連系の受け皿
A13: S6 | B13: エリア | C13: 5 | D13: エリア点表参照 | E13: 実績工期のエリア差(九州3ヶ月〜中部24ヶ月)
A14: 合計 | B14: 系統スコア | C14: 80 | D14: S1+S2+S3+S4+S5+S6
A15: S7 | B15: (土地確定後)変電所・既設配電線への近接 | C15: 20 | D15: ≦500m:20 / ≦1km:15 / ≦2km:10 / ≦5km:4 / 超:0 | E15: 負担金≒400万+0.8〜1.0万円/m×新設延長
B16: 実績補正 | C16: ± | D16: 実績DBに同一変電所があれば優先参照(実績メモ列) | E16: 王子SS(バンク対策済み)=神崎920万/3ヶ月 等
A18: 配点パラメータ（黄色セルを変更するとスコアが自動再計算されます）
A19: 項目 | B19: 閾値 | C19: 点数
A20: S1: 空容量 ≧(MW) で35点 | B20: 20 | C20: 35
A21: S1: 空容量 ≧(MW) で28点 | B21: 6 | C21: 28
A22: S1: 空容量 >0 で15点 | C22: 15
A23: S2: N-1電制「可」 | C23: 10
A24: S3: |潮流|/運用容量 ≦ で15点 | B24: 0.3 | C24: 15
A25: S3: |潮流|/運用容量 ≦ で9点 | B25: 0.6 | C25: 9
A26: S3: |潮流|/運用容量 ≦ で4点 | B26: 0.9 | C26: 4
A27: S4: 出力制御「なし」 | C27: 5
A28: S5: 二次電圧 ≦(kV) で10点 | B28: 7 | C28: 10
A29: S5: 二次電圧 その他数値 | C29: 5
A30: ランクS: 系統スコア ≧ | B30: 60
A31: ランクA: 系統スコア ≧ | B31: 48
A32: ランクB: 系統スコア ≧ | B32: 36
A34: S6 エリア点（実績工期・出力制御環境からの仮置き。実績追加で更新）
A35: エリア | B35: 点数 | C35: 根拠(実績)
A36: 北海道 | B36: 5 | C36: 由仁町: 計量のみ410万・6ヶ月
A37: 東北 | B37: 4 | C37: 喜多方: 配電のみなら7ヶ月
A38: 東京 | B38: 4 | C38: 需要地・配変多い(実績は特高のみ)
A39: 中部 | B39: 2 | C39: 関市18ヶ月・野尻24ヶ月と増強系が遅い
A40: 北陸 | B40: 3 | C40: 実績なし・中位仮置き
A41: 関西 | B41: 3 | C41: 白浜: 12ヶ月
A42: 中国 | B42: 3 | C42: 実績未読(PW付)・中位仮置き
A43: 四国 | B43: 3 | C43: 実績なし・中位仮置き
...

Sheet 実績DB
A1: 接続検討回答 実績102件（手入力18件: 2026-08-06更新／残り84件: 接続検討回答 検証一覧から取込・AI読取値のため要原本確認）
A2: エリア | B2: 変電所名(リスト表記) | C2: 案件 | D2: 出力 | E2: 負担金 | F2: 連系工期 | G2: 主な対策工事 | H2: 教訓・律速 | I2: 要約(スコア表参照用・同じ変電所の回答はまとめて表示) | J2: キー(自動)
A3: 九州 | B3: 笠之原変電所 | C3: 鹿屋市上小原 | D3: 1,999kW | E3: 約6,140万円(付箋値・要確認) | F3: 入金後1年4ヶ月 | G3: 張替1,405m+SVC | H3: 細線・SVC発動で高額長期 | I3: 負担金約6,140万・1年4ヶ月(張替1.4km+SVC) | J3: =A3&TRIM(B3)
A4: 北海道 | B4: 由仁変電所 | C4: 由仁町川端(1135) | D4: 1,999kW | E4: 410万円 | F4: 入金後6ヶ月 | G4: 計量設備のみ | H4: 空容量潤沢なら最安最速 | I4: 負担金410万・6ヶ月(計量のみ) | J4: =A4&TRIM(B4)
A5: 九州 | B5: 王子変電所 | C5: 大分市神崎(東盛) | D5: 高圧 | E5: 920万円 | F5: 入金後3ヶ月 | G5: 張替1,006m+PGB | H5: バンク逆潮流対策済みは別格 | I5: 負担金920万・3ヶ月(バンク対策済み) | J5: =A5&TRIM(B5)
A6: 九州 | B6: 久山変電所 | C6: 福岡県久山町(KMP) | D6: 高圧 | E6: 1,630万円(税抜) | F6: 入金後1年5ヶ月 | G6: SVC300kvar+張替16m | H6: 細線(177A)でSVC発動 | I6: 負担金1,630万・1年5ヶ月(SVC) | J6: =A6&TRIM(B6)
A7: 東北 | B7: －(須賀川上位系) | C7: 喜多方市松山(PX No071) | D7: 高圧 | E7: 特定負担は僅少 | F7: 配電7ヶ月/上位系10年2ヶ月 | G7: SVR5000kVA+須賀川MT取替 | H7: 上位系増強=時間で死ぬ | I7: 上位系増強で10年2ヶ月(ゲート根拠) | J7: =A7&TRIM(B7)
A8: 中部 | B8: 小屋名変電所 | C8: 関市小屋名(B646G) | D8: 高圧 | E8: 620万円+保証金31万 | F8: 入金後18ヶ月 | G8: 配電線増強 | H8: 中部の増強系は遅い | I8: 負担金620万・18ヶ月(増強) | J8: =A8&TRIM(B8)
A9: 中部 | B9: 柏原変電所 | C9: 信濃町柏原2390-1 | D9: 高圧 | E9: 850万円+保証金42.5万 | F9: 入金後6ヶ月 | G9: 新設48m+引込105m | H9: 軽微工事なら中部でも速い | I9: 850万・6ヶ月(新設48m)/同F21野尻は1,782万・24ヶ月 ／ (同上メモ参照) | J9: =A9&TRIM(B9)
A10: 中部 | B10: 柏原変電所 | C10: 信濃町野尻(契約申込=確定) | D10: 1,998kW | E10: 1,782万円(税抜) | F10: 入金後24ヶ月 | G10: 電柱5本+新設1,842m+SVR取替 | H10: 新設km級は高額長期 | I10: 850万・6ヶ月(新設48m)/同F21野尻は1,782万・24ヶ月 ／ (同上メモ参照) | J10: =A10&TRIM(B10)
A11: 東京 | B11: －(西毛線) | C11: 高崎市吉井町(特高参考) | D11: 特高 | E11: 4.64億円+保証金2,551万 | F11: 入金後26ヶ月(受付後73ヶ月) | G11: 送電線新設+2回線張替 | H11: 特高は桁違い | I11: 特高参考: 4.64億・6年 | J11: =A11&TRIM(B11)
A12: 関西 | B12: －(田辺管内) | C12: 白浜町才野1339-1 | D12: 1,999kW | E12: 約3,700〜3,900万円 | F12: 入金後12ヶ月 | G12: 高圧線新設4,701m+SVR2台 | H12: 遠距離新設の典型NG | I12: 3,700万・12ヶ月(新設4.7km) | J12: =A12&TRIM(B12)
A13: 九州 | B13: －(野原宇佐線) | C13: 宇佐市蜷木(1486) | D13: 高圧 | E13: 2.465億円→契約時点2.704億円(税抜) | F13: 入金後2年3ヶ月→2年10ヶ月(契約時No24595) | G13: 66kV鉄塔・アクセス送電線新設 | H13: 66kV側対策で億超え | I13: 2.5億・2年3ヶ月(66kV側対策) | J13: =A13&TRIM(B13)
A14: 九州 | B14: －(西佐世保相浦線) | C14: 伊万里市東山代町東大久保(特高参考) | D14: 特高40,232kW | E14: 2.68億円(税込・税抜2.43億) | F14: 入金後3年2ヶ月 | G14: アクセス線新設0.1km+鉄塔建替2基+張替0.9km×2回線+転送遮断装置3面 | H14: 特高40MW級は短距離でも2.5億・3年級 | I14: 特高参考: 2.68億・3年2ヶ月(九電回答2026/7/14) | J14: =A14&TRIM(B14)
... A104: 中国 | B104: －(大崎変電所（配電用）) | C104: 大崎上島町中野3462-1他（広島県）_高圧蓄電所 | D104: 1,998kW | E104: 760万円(税込) | F104: 入金後11ヶ月 | G104: 電柱新設4本・建替8本、高圧線新設247m・張替等568m、高圧引込線33m(SN-ACSR-OC200mm2 送電容量455A)、計測機能付開閉器1台、計量… | H104: 運開希望日に間に合わず / 工期と別にバンク/上位系対策待ち／上位系: あり: 110kV竹原火力・竹原呉線のN-1充電停止装置（過負荷保護装置）設置（工事費の一部を負担）、110kV竹原火…（AI読取・信頼度medium・要原本確認） | I104: 接続検討回答: 760万円・11ヶ月(2026-09-17) 運開希望日に間に合わず / 工期と別にバンク/上位系対策待ち | J104: =A104&TRIM(B104)
A106: ■分析メモ(2026-08-06追記・19件ベース)
A107: ①工期は「エリア×工事種別」で決まる: 九州は張替のみなら3〜6ヶ月(神崎3ヶ月・上鏡6ヶ月)。中部は最軽微(新設150mだけ)でも18ヶ月と標準工程が長い。S6エリア点(九州5・中部2)は実績と整合しており変更不要
A108: ②負担金は工事量に比例: 198万(新設150m)→1,170万(張替1.2km)→2,536万(新設373m+張替735m+SVR+バンク対策)→3,246万(新設617m+張替1km+SVR2台)。推定式は「固定費200〜400万+延長(m)×0.7〜1.0万+SVR/SVC×500万+バンク対策500〜1,000万」に更新余地
A109: ③契約段階の増額リスク: 宇佐蜷木は接続検討→契約申込で負担金+2,400万(+10%)・工期+7ヶ月。接続検討回答値には+10〜15%・+半年のバッファを見る
A110: ④特高は4件(吉井4.64億/伊万里2.68億/南関1.69億/伊勢9.23億)で負担金・工期(26〜73ヶ月)とも桁違い。高圧2MW戦略の正しさを再確認。ただし南関のように共同按分が効くと1.7億まで下がる例あり
A111: ⑤上位系統対策の有無が時間の分水嶺: 上鏡は「上位系統対策なし」で6ヶ月。喜多方(上位系10年)との対比でゲート足切りの妥当性を再確認
A112: ⑥バンク逆潮流対策は2例目(藤枝2,536万)。対策済み変電所(神崎920万)との差≒約1,000万強=対策費。対策済みバンクの再利用価値大。残課題: 東電JK2件・PW付PDF2件(東広島・山口)・鹿屋原本確認
